Workbook

Sheet 사용법
B2: AI 파이프라인 통합 리소스/스케줄 관리 시트 v11
B3: 한 소재 = 직군별 줄(최대 3줄, 기획/이미지/영상) - 각 줄이 자기 날짜에 MD를 직접 입력
B5: 색 표시
B6: 파랑 | C6: 해당 직군 정원(TO)의 80~100% 채워진 상태
B7: 보라 | C7: 정원(TO) 초과 - 조율 필요
B8: 회색 | C8: 주말(토/일) 또는 대한민국 공휴일 - 실제 워킹데이 아님
B9: 빨강 | C9: 같은 담당자가 같은 날 여러 소재에 걸쳐 하루 8시간(1.0MD)을 초과 - 배정 조율 필요
B10: 1. 한 소재 = 직군별 줄
B11: 구조 | C11: 소재명 하나에 관여하는 직군(기획/이미지/영상)마다 별도의 줄이 있습니다. 3직군 다 관여하면 3줄, 영상만 있으면 1줄. 소재명은 같은 텍스트로 반복 입력해서 같은 소재임을 표시합니다.
B12: 각 줄이 독립적 | C12: 기획 줄은 기획대로, 영상 줄은 영상대로 자기만의 담당자·날짜·MD를 가집니다. 기획은 8/5 하루만, 영상은 8/6~8/7 이틀만 - 이렇게 서로 다른 기간이 자연스럽게 표현됩니다.
B13: 수량 | C13: 영상 수/사이즈베리/다국어베리는 소재당 한 번만 입력(아무 줄에나, 중복 입력 금지 - 안 그러면 집계가 중복됩니다).
B15: 2. MD 입력 - 날짜 칸에 직접
B16: 직접 입력 | C16: 오른쪽 날짜 칸에 그날 실제 투입 MD를 직접 입력합니다(예: 8/6에 1.0, 8/7에 1.0). 균등분산이 아니라 실제 값 그대로.
B17: 자동 계산 | C17: 시작일·완료일은 입력한 날짜 중 가장 이른 날/늦은 날로 자동 계산됩니다. 합계MD도 그 줄에 입력한 숫자를 모두 더한 값입니다.
B18: 최종완료일(고객전달) | C18: 이 소재를 실제로 고객사에 전달하는 확정일입니다. 기획이 결정해서 입력합니다 - 자동계산이 아니라 사람이 정하는 값입니다. 같은 소재의 기획/이미지/영상 3줄에 전부 동일하게 입력하세요(복사/붙여넣기). 기획 작업 자체가 하루뿐이어도, 최종완료일은 영상까지 다 끝난 뒤의 진짜 고객 전달일이어야 합니다 - 착각하지 않도록 이름을 명확히 구분했습니다.
B19: 여유 | C19: 각 줄의 여유 = 최종완료일(고객전달) − 그 줄의 실제 완료일(자동). 3줄 모두 같은 최종완료일을 기준으로 계산되므로, 어느 직군이 고객 마감에 걸리는지 줄별로 바로 보입니다.
B20: 담당자 8시간 초과 | C20: 같은 담당자 이름으로 같은 날짜에 여러 소재에 걸쳐 입력한 MD를 다 더해서 마스터의 '담당자 1일 캐파(기본 1.0=8시간)'를 넘으면 그 날짜 칸이 빨간색으로 경고됩니다.
B22: 3. 팀별 색상 구간
B23: 30행 구간 | C23: 각 월 탭 안에서 마케팅1~4팀 + 기타, 팀마다 30행씩 고정 구간. 한 소재가 여러 줄을 쓰므로 팀당 소재는 대략 10~30개 정도 들어갑니다. 넘으면 행 삽입.
B24: 고객팀 자동 | C24: 구간 안 행의 고객팀 칸은 자동 고정.
B26: 4. 워킹데이 (주말 + 대한민국 공휴일)
B27: 회색 처리 | C27: 간트와 상단 TO 상태 모두 토/일 + 마스터의 대한민국 공휴일 목록에 해당하는 날짜는 회색 처리.
B28: 공휴일 수정 | C28: 마스터 시트 공휴일 목록(설날/추석 등 음력 기반 포함)은 참고용 - 정부 발표 기준 확인 후 수정.
B30: 5. 연간요약
B31: 월별/누적 | C31: 12개 월 탭에서 직접 집계. 매월 누적, 상반기/하반기/연간 합계, 월별 가동률, 팀x유형, 타이틀별.

Sheet 마스터
A1: 마스터 / 기준정보
A2: 게임 타이틀 (25) | C2: 고객팀 | E2: 직군 | G2: 상태 | I2: 운영 파라미터
A3: 뱀피르 | C3: 마케팅1팀 | E3: 기획 | G3: 대기 | I3: 연도 | J3: 2026
A4: RF 글로벌 | C4: 마케팅2팀 | E4: 이미지 | G4: 진행 | I4: 월 가동일수 | J4: 20
A5: SOL 인챈트 | C5: 마케팅3팀 | E5: 영상 | G5: 검수 | I5: 담당자 1일 캐파(MD) | J5: 1
A6: 스톤에이지펫월드 | C6: 마케팅4팀 | G6: 완료
A7: 칠대죄오리진 | C7: 기타 | I7: 직군 일 TO 정원
A8: 세나리버스 | I8: 영상 | J8: 6
A9: 몬길 | I9: 이미지 | J9: 8
A10: 왕겜(GOT) | I10: 기획 | J10: 3
A11: 몬스터길들이기
A12: 라이즈오브 | I12: 대한민국 공휴일 (참고 - 연도별 확인/수정 필요)
I13: 신정 | J13: =DATE(2026,1,1)
I14: 설날연휴 | J14: =DATE(2026,2,16)
I15: 설날 | J15: =DATE(2026,2,17)
I16: 설날연휴 | J16: =DATE(2026,2,18)
I17: 삼일절(대체) | J17: =DATE(2026,3,2)
I18: 어린이날 | J18: =DATE(2026,5,5)
I19: 부처님오신날(음력,확인필요) | J19: =DATE(2026,5,24)
I20: 현충일 | J20: =DATE(2026,6,6)
I21: 광복절 | J21: =DATE(2026,8,15)
I22: 추석연휴(음력,확인필요) | J22: =DATE(2026,9,24)
I23: 추석(음력,확인필요) | J23: =DATE(2026,9,25)
I24: 추석연휴(음력,확인필요) | J24: =DATE(2026,9,26)
I25: 개천절 | J25: =DATE(2026,10,3)
I26: 한글날 | J26: =DATE(2026,10,9)
I27: 성탄절 | J27: =DATE(2026,12,25)
A30: 비나(VINA) 운영 시나리오 (참고)
A31: 방안 1 | C31: 기획+내부디자인+비나영상 - 비나 영상공수는 영상실 매출 귀속
A32: 방안 2 | C32: 비나=사이즈베리만 - 영상 베리는 디자인 흡수
A33: 방안 3 | C33: 비나 이미지TO 추가발주+추가비용
A34: 방안 4 | C34: 본사 프로세스 통합(이미지TO 추가X)

Sheet 연간요약
B2: 연간요약 - 월별 / 상하반기 / 매월 누적
B3: 각 월 탭에서 직접 집계. 입력은 해당 월 탭에서.
B5: 월 | C5: 영상MD | D5: 이미지MD | E5: 기획MD | F5: 합계MD | G5: 누적MD | H5: 영상수 | I5: 사이즈베리 | J5: 다국어베리 | K5: 가동률
B6: 1월 | C6: =SUMIF('1월'!$E$8:$E$162,"영상",'1월'!$K$8:$K$162) | D6: =SUMIF('1월'!$E$8:$E$162,"이미지",'1월'!$K$8:$K$162) | E6: =SUMIF('1월'!$E$8:$E$162,"기획",'1월'!$K$8:$K$162) | F6: =SUM(C6:E6) | G6: =SUM($F$6:F6) | H6: =SUM('1월'!H8:H162) | I6: =SUM('1월'!I8:I162) | J6: =SUM('1월'!J8:J162) | K6: =IFERROR(F6/(SUM('마스터'!$J$8:$J$10)*'마스터'!$J$4),0)
B7: 2월 | C7: =SUMIF('2월'!$E$8:$E$162,"영상",'2월'!$K$8:$K$162) | D7: =SUMIF('2월'!$E$8:$E$162,"이미지",'2월'!$K$8:$K$162) | E7: =SUMIF('2월'!$E$8:$E$162,"기획",'2월'!$K$8:$K$162) | F7: =SUM(C7:E7) | G7: =SUM($F$6:F7) | H7: =SUM('2월'!H8:H162) | I7: =SUM('2월'!I8:I162) | J7: =SUM('2월'!J8:J162) | K7: =IFERROR(F7/(SUM('마스터'!$J$8:$J$10)*'마스터'!$J$4),0)
B8: 3월 | C8: =SUMIF('3월'!$E$8:$E$162,"영상",'3월'!$K$8:$K$162) | D8: =SUMIF('3월'!$E$8:$E$162,"이미지",'3월'!$K$8:$K$162) | E8: =SUMIF('3월'!$E$8:$E$162,"기획",'3월'!$K$8:$K$162) | F8: =SUM(C8:E8) | G8: =SUM($F$6:F8) | H8: =SUM('3월'!H8:H162) | I8: =SUM('3월'!I8:I162) | J8: =SUM('3월'!J8:J162) | K8: =IFERROR(F8/(SUM('마스터'!$J$8:$J$10)*'마스터'!$J$4),0)
B9: 4월 | C9: =SUMIF('4월'!$E$8:$E$162,"영상",'4월'!$K$8:$K$162) | D9: =SUMIF('4월'!$E$8:$E$162,"이미지",'4월'!$K$8:$K$162) | E9: =SUMIF('4월'!$E$8:$E$162,"기획",'4월'!$K$8:$K$162) | F9: =SUM(C9:E9) | G9: =SUM($F$6:F9) | H9: =SUM('4월'!H8:H162) | I9: =SUM('4월'!I8:I162) | J9: =SUM('4월'!J8:J162) | K9: =IFERROR(F9/(SUM('마스터'!$J$8:$J$10)*'마스터'!$J$4),0)
B10: 5월 | C10: =SUMIF('5월'!$E$8:$E$162,"영상",'5월'!$K$8:$K$162) | D10: =SUMIF('5월'!$E$8:$E$162,"이미지",'5월'!$K$8:$K$162) | E10: =SUMIF('5월'!$E$8:$E$162,"기획",'5월'!$K$8:$K$162) | F10: =SUM(C10:E10) | G10: =SUM($F$6:F10) | H10: =SUM('5월'!H8:H162) | I10: =SUM('5월'!I8:I162) | J10: =SUM('5월'!J8:J162) | K10: =IFERROR(F10/(SUM('마스터'!$J$8:$J$10)*'마스터'!$J$4),0)
B11: 6월 | C11: =SUMIF('6월'!$E$8:$E$162,"영상",'6월'!$K$8:$K$162) | D11: =SUMIF('6월'!$E$8:$E$162,"이미지",'6월'!$K$8:$K$162) | E11: =SUMIF('6월'!$E$8:$E$162,"기획",'6월'!$K$8:$K$162) | F11: =SUM(C11:E11) | G11: =SUM($F$6:F11) | H11: =SUM('6월'!H8:H162) | I11: =SUM('6월'!I8:I162) | J11: =SUM('6월'!J8:J162) | K11: =IFERROR(F11/(SUM('마스터'!$J$8:$J$10)*'마스터'!$J$4),0)
B12: 7월 | C12: =SUMIF('7월'!$E$8:$E$162,"영상",'7월'!$K$8:$K$162) | D12: =SUMIF('7월'!$E$8:$E$162,"이미지",'7월'!$K$8:$K$162) | E12: =SUMIF('7월'!$E$8:$E$162,"기획",'7월'!$K$8:$K$162) | F12: =SUM(C12:E12) | G12: =SUM($F$6:F12) | H12: =SUM('7월'!H8:H162) | I12: =SUM('7월'!I8:I162) | J12: =SUM('7월'!J8:J162) | K12: =IFERROR(F12/(SUM('마스터'!$J$8:$J$10)*'마스터'!$J$4),0)
B13: 8월 | C13: =SUMIF('8월'!$E$8:$E$162,"영상",'8월'!$K$8:$K$162) | D13: =SUMIF('8월'!$E$8:$E$162,"이미지",'8월'!$K$8:$K$162) | E13: =SUMIF('8월'!$E$8:$E$162,"기획",'8월'!$K$8:$K$162) | F13: =SUM(C13:E13) | G13: =SUM($F$6:F13) | H13: =SUM('8월'!H8:H162) | I13: =SUM('8월'!I8:I162) | J13: =SUM('8월'!J8:J162) | K13: =IFERROR(F13/(SUM('마스터'!$J$8:$J$10)*'마스터'!$J$4),0)
B14: 9월 | C14: =SUMIF('9월'!$E$8:$E$162,"영상",'9월'!$K$8:$K$162) | D14: =SUMIF('9월'!$E$8:$E$162,"이미지",'9월'!$K$8:$K$162) | E14: =SUMIF('9월'!$E$8:$E$162,"기획",'9월'!$K$8:$K$162) | F14: =SUM(C14:E14) | G14: =SUM($F$6:F14) | H14: =SUM('9월'!H8:H162) | I14: =SUM('9월'!I8:I162) | J14: =SUM('9월'!J8:J162) | K14: =IFERROR(F14/(SUM('마스터'!$J$8:$J$10)*'마스터'!$J$4),0)
B15: 10월 | C15: =SUMIF('10월'!$E$8:$E$162,"영상",'10월'!$K$8:$K$162) | D15: =SUMIF('10월'!$E$8:$E$162,"이미지",'10월'!$K$8:$K$162) | E15: =SUMIF('10월'!$E$8:$E$162,"기획",'10월'!$K$8:$K$162) | F15: =SUM(C15:E15) | G15: =SUM($F$6:F15) | H15: =SUM('10월'!H8:H162) | I15: =SUM('10월'!I8:I162) | J15: =SUM('10월'!J8:J162) | K15: =IFERROR(F15/(SUM('마스터'!$J$8:$J$10)*'마스터'!$J$4),0)
B16: 11월 | C16: =SUMIF('11월'!$E$8:$E$162,"영상",'11월'!$K$8:$K$162) | D16: =SUMIF('11월'!$E$8:$E$162,"이미지",'11월'!$K$8:$K$162) | E16: =SUMIF('11월'!$E$8:$E$162,"기획",'11월'!$K$8:$K$162) | F16: =SUM(C16:E16) | G16: =SUM($F$6:F16) | H16: =SUM('11월'!H8:H162) | I16: =SUM('11월'!I8:I162) | J16: =SUM('11월'!J8:J162) | K16: =IFERROR(F16/(SUM('마스터'!$J$8:$J$10)*'마스터'!$J$4),0)
B17: 12월 | C17: =SUMIF('12월'!$E$8:$E$162,"영상",'12월'!$K$8:$K$162) | D17: =SUMIF('12월'!$E$8:$E$162,"이미지",'12월'!$K$8:$K$162) | E17: =SUMIF('12월'!$E$8:$E$162,"기획",'12월'!$K$8:$K$162) | F17: =SUM(C17:E17) | G17: =SUM($F$6:F17) | H17: =SUM('12월'!H8:H162) | I17: =SUM('12월'!I8:I162) | J17: =SUM('12월'!J8:J162) | K17: =IFERROR(F17/(SUM('마스터'!$J$8:$J$10)*'마스터'!$J$4),0)
B18: 상반기(1-6) | C18: =SUM(C6:C11) | D18: =SUM(D6:D11) | E18: =SUM(E6:E11) | F18: =SUM(F6:F11) | H18: =SUM(H6:H11) | I18: =SUM(I6:I11) | J18: =SUM(J6:J11) | K18: =IFERROR(F18/(SUM('마스터'!$J$8:$J$10)*'마스터'!$J$4*(11-6+1)),0)
B19: 하반기(7-12) | C19: =SUM(C12:C17) | D19: =SUM(D12:D17) | E19: =SUM(E12:E17) | F19: =SUM(F12:F17) | H19: =SUM(H12:H17) | I19: =SUM(I12:I17) | J19: =SUM(J12:J17) | K19: =IFERROR(F19/(SUM('마스터'!$J$8:$J$10)*'마스터'!$J$4*(17-12+1)),0)
B20: 연간 합계 | C20: =SUM(C6:C17) | D20: =SUM(D6:D17) | E20: =SUM(E6:E17) | F20: =SUM(F6:F17) | H20: =SUM(H6:H17) | I20: =SUM(I6:I17) | J20: =SUM(J6:J17) | K20: =IFERROR(F20/(SUM('마스터'!$J$8:$J$10)*'마스터'!$J$4*(17-6+1)),0)
B23: 고객팀 x 직군 (연간 건수) | H23: 게임타이틀별 (연간 MD)
B24: 팀\직군 | C24: 기획 | D24: 이미지 | E24: 영상 | H24: 타이틀 | I24: 건수 | J24: MD
B25: 마케팅1팀 | C25: =COUNTIFS('1월'!$C$8:$C$162,$B25,'1월'!$E$8:$E$162,C$24)+COUNTIFS('2월'!$C$8:$C$162,$B25,'2월'!$E$8:$E$162,C$24)+COUNTIFS('3월'!$C$8:$C$162,$B25,'3월'!$E$8:$E$162,C$24)+COUNTIFS('4월'!$C$8:$C$162,$B25,'4월'!$E$8:$E$162,C$24)+COUNTIFS('5월'!$C$8:$C$162,$B25,'5월'!$E$8:$E$162,C$24)+COUNTIFS('6월'!$C$8:$C$162,$B25,'6월'!$E$8:$E$162,C$24)+COUNTIFS('7월'!$C$8:$C$162,$B25,'7월'!$E$8:$E$162,C$24)+COUNTIFS('8월'!$C$8:$C$162,$B25,'8월'!$E$8:$E$162,C$24)+COUNTIFS('9월'!$C$8:$C$162,$B25,'9월'!$E$8:$E$162,C$24)+COUNTIFS('10월'!$C$8:$C$162,$B25,'10월'!$E$8:$E$162,C$24)+COUNTIFS('11월'!$C$8:$C$162,$B25,'11월'!$E$8:$E$162,C$24)+COUNTIFS('12월'!$C$8:$C$162,$B25,'12월'!$E$8:$E$162,C$24) | D25: =COUNTIFS('1월'!$C$8:$C$162,$B25,'1월'!$E$8:$E$162,D$24)+COUNTIFS('2월'!$C$8:$C$162,$B25,'2월'!$E$8:$E$162,D$24)+COUNTIFS('3월'!$C$8:$C$162,$B25,'3월'!$E$8:$E$162,D$24)+COUNTIFS('4월'!$C$8:$C$162,$B25,'4월'!$E$8:$E$162,D$24)+COUNTIFS('5월'!$C$8:$C$162,$B25,'5월'!$E$8:$E$162,D$24)+COUNTIFS('6월'!$C$8:$C$162,$B25,'6월'!$E$8:$E$162,D$24)+COUNTIFS('7월'!$C$8:$C$162,$B25,'7월'!$E$8:$E$162,D$24)+COUNTIFS('8월'!$C$8:$C$162,$B25,'8월'!$E$8:$E$162,D$24)+COUNTIFS('9월'!$C$8:$C$162,$B25,'9월'!$E$8:$E$162,D$24)+COUNTIFS('10월'!$C$8:$C$162,$B25,'10월'!$E$8:$E$162,D$24)+COUNTIFS('11월'!$C$8:$C$162,$B25,'11월'!$E$8:$E$162,D$24)+COUNTIFS('12월'!$C$8:$C$162,$B25,'12월'!$E$8:$E$162,D$24) | E25: =COUNTIFS('1월'!$C$8:$C$162,$B25,'1월'!$E$8:$E$162,E$24)+COUNTIFS('2월'!$C$8:$C$162,$B25,'2월'!$E$8:$E$162,E$24)+COUNTIFS('3월'!$C$8:$C$162,$B25,'3월'!$E$8:$E$162,E$24)+COUNTIFS('4월'!$C$8:$C$162,$B25,'4월'!$E$8:$E$162,E$24)+COUNTIFS('5월'!$C$8:$C$162,$B25,'5월'!$E$8:$E$162,E$24)+COUNTIFS('6월'!$C$8:$C$162,$B25,'6월'!$E$8:$E$162,E$24)+COUNTIFS('7월'!$C$8:$C$162,$B25,'7월'!$E$8:$E$162,E$24)+COUNTIFS('8월'!$C$8:$C$162,$B25,'8월'!$E$8:$E$162,E$24)+COUNTIFS('9월'!$C$8:$C$162,$B25,'9월'!$E$8:$E$162,E$24)+COUNTIFS('10월'!$C$8:$C$162,$B25,'10월'!$E$8:$E$162,E$24)+COUNTIFS('11월'!$C$8:$C$162,$B25,'11월'!$E$8:$E$162,E$24)+COUNTIFS('12월'!$C$8:$C$162,$B25,'12월'!$E$8:$E$162,E$24) | H25: 뱀피르 | I25: =COUNTIF('1월'!$B$8:$B$162,$H25)+COUNTIF('2월'!$B$8:$B$162,$H25)+COUNTIF('3월'!$B$8:$B$162,$H25)+COUNTIF('4월'!$B$8:$B$162,$H25)+COUNTIF('5월'!$B$8:$B$162,$H25)+COUNTIF('6월'!$B$8:$B$162,$H25)+COUNTIF('7월'!$B$8:$B$162,$H25)+COUNTIF('8월'!$B$8:$B$162,$H25)+COUNTIF('9월'!$B$8:$B$162,$H25)+COUNTIF('10월'!$B$8:$B$162,$H25)+COUNTIF('11월'!$B$8:$B$162,$H25)+COUNTIF('12월'!$B$8:$B$162,$H25) | J25: =SUMIF('1월'!$B$8:$B$162,$H25,'1월'!$K$8:$K$162)+SUMIF('2월'!$B$8:$B$162,$H25,'2월'!$K$8:$K$162)+SUMIF('3월'!$B$8:$B$162,$H25,'3월'!$K$8:$K$162)+SUMIF('4월'!$B$8:$B$162,$H25,'4월'!$K$8:$K$162)+SUMIF('5월'!$B$8:$B$162,$H25,'5월'!$K$8:$K$162)+SUMIF('6월'!$B$8:$B$162,$H25,'6월'!$K$8:$K$162)+SUMIF('7월'!$B$8:$B$162,$H25,'7월'!$K$8:$K$162)+SUMIF('8월'!$B$8:$B$162,$H25,'8월'!$K$8:$K$162)+SUMIF('9월'!$B$8:$B$162,$H25,'9월'!$K$8:$K$162)+SUMIF('10월'!$B$8:$B$162,$H25,'10월'!$K$8:$K$162)+SUMIF('11월'!$B$8:$B$162,$H25,'11월'!$K$8:$K$162)+SUMIF('12월'!$B$8:$B$162,$H25,'12월'!$K$8:$K$162)
B26: 마케팅2팀 | C26: =COUNTIFS('1월'!$C$8:$C$162,$B26,'1월'!$E$8:$E$162,C$24)+COUNTIFS('2월'!$C$8:$C$162,$B26,'2월'!$E$8:$E$162,C$24)+COUNTIFS('3월'!$C$8:$C$162,$B26,'3월'!$E$8:$E$162,C$24)+COUNTIFS('4월'!$C$8:$C$162,$B26,'4월'!$E$8:$E$162,C$24)+COUNTIFS('5월'!$C$8:$C$162,$B26,'5월'!$E$8:$E$162,C$24)+COUNTIFS('6월'!$C$8:$C$162,$B26,'6월'!$E$8:$E$162,C$24)+COUNTIFS('7월'!$C$8:$C$162,$B26,'7월'!$E$8:$E$162,C$24)+COUNTIFS('8월'!$C$8:$C$162,$B26,'8월'!$E$8:$E$162,C$24)+COUNTIFS('9월'!$C$8:$C$162,$B26,'9월'!$E$8:$E$162,C$24)+COUNTIFS('10월'!$C$8:$C$162,$B26,'10월'!$E$8:$E$162,C$24)+COUNTIFS('11월'!$C$8:$C$162,$B26,'11월'!$E$8:$E$162,C$24)+COUNTIFS('12월'!$C$8:$C$162,$B26,'12월'!$E$8:$E$162,C$24) | D26: =COUNTIFS('1월'!$C$8:$C$162,$B26,'1월'!$E$8:$E$162,D$24)+COUNTIFS('2월'!$C$8:$C$162,$B26,'2월'!$E$8:$E$162,D$24)+COUNTIFS('3월'!$C$8:$C$162,$B26,'3월'!$E$8:$E$162,D$24)+COUNTIFS('4월'!$C$8:$C$162,$B26,'4월'!$E$8:$E$162,D$24)+COUNTIFS('5월'!$C$8:$C$162,$B26,'5월'!$E$8:$E$162,D$24)+COUNTIFS('6월'!$C$8:$C$162,$B26,'6월'!$E$8:$E$162,D$24)+COUNTIFS('7월'!$C$8:$C$162,$B26,'7월'!$E$8:$E$162,D$24)+COUNTIFS('8월'!$C$8:$C$162,$B26,'8월'!$E$8:$E$162,D$24)+COUNTIFS('9월'!$C$8:$C$162,$B26,'9월'!$E$8:$E$162,D$24)+COUNTIFS('10월'!$C$8:$C$162,$B26,'10월'!$E$8:$E$162,D$24)+COUNTIFS('11월'!$C$8:$C$162,$B26,'11월'!$E$8:$E$162,D$24)+COUNTIFS('12월'!$C$8:$C$162,$B26,'12월'!$E$8:$E$162,D$24) | E26: =COUNTIFS('1월'!$C$8:$C$162,$B26,'1월'!$E$8:$E$162,E$24)+COUNTIFS('2월'!$C$8:$C$162,$B26,'2월'!$E$8:$E$162,E$24)+COUNTIFS('3월'!$C$8:$C$162,$B26,'3월'!$E$8:$E$162,E$24)+COUNTIFS('4월'!$C$8:$C$162,$B26,'4월'!$E$8:$E$162,E$24)+COUNTIFS('5월'!$C$8:$C$162,$B26,'5월'!$E$8:$E$162,E$24)+COUNTIFS('6월'!$C$8:$C$162,$B26,'6월'!$E$8:$E$162,E$24)+COUNTIFS('7월'!$C$8:$C$162,$B26,'7월'!$E$8:$E$162,E$24)+COUNTIFS('8월'!$C$8:$C$162,$B26,'8월'!$E$8:$E$162,E$24)+COUNTIFS('9월'!$C$8:$C$162,$B26,'9월'!$E$8:$E$162,E$24)+COUNTIFS('10월'!$C$8:$C$162,$B26,'10월'!$E$8:$E$162,E$24)+COUNTIFS('11월'!$C$8:$C$162,$B26,'11월'!$E$8:$E$162,E$24)+COUNTIFS('12월'!$C$8:$C$162,$B26,'12월'!$E$8:$E$162,E$24) | H26: RF 글로벌 | I26: =COUNTIF('1월'!$B$8:$B$162,$H26)+COUNTIF('2월'!$B$8:$B$162,$H26)+COUNTIF('3월'!$B$8:$B$162,$H26)+COUNTIF('4월'!$B$8:$B$162,$H26)+COUNTIF('5월'!$B$8:$B$162,$H26)+COUNTIF('6월'!$B$8:$B$162,$H26)+COUNTIF('7월'!$B$8:$B$162,$H26)+COUNTIF('8월'!$B$8:$B$162,$H26)+COUNTIF('9월'!$B$8:$B$162,$H26)+COUNTIF('10월'!$B$8:$B$162,$H26)+COUNTIF('11월'!$B$8:$B$162,$H26)+COUNTIF('12월'!$B$8:$B$162,$H26) | J26: =SUMIF('1월'!$B$8:$B$162,$H26,'1월'!$K$8:$K$162)+SUMIF('2월'!$B$8:$B$162,$H26,'2월'!$K$8:$K$162)+SUMIF('3월'!$B$8:$B$162,$H26,'3월'!$K$8:$K$162)+SUMIF('4월'!$B$8:$B$162,$H26,'4월'!$K$8:$K$162)+SUMIF('5월'!$B$8:$B$162,$H26,'5월'!$K$8:$K$162)+SUMIF('6월'!$B$8:$B$162,$H26,'6월'!$K$8:$K$162)+SUMIF('7월'!$B$8:$B$162,$H26,'7월'!$K$8:$K$162)+SUMIF('8월'!$B$8:$B$162,$H26,'8월'!$K$8:$K$162)+SUMIF('9월'!$B$8:$B$162,$H26,'9월'!$K$8:$K$162)+SUMIF('10월'!$B$8:$B$162,$H26,'10월'!$K$8:$K$162)+SUMIF('11월'!$B$8:$B$162,$H26,'11월'!$K$8:$K$162)+SUMIF('12월'!$B$8:$B$162,$H26,'12월'!$K$8:$K$162)
B27: 마케팅3팀 | C27: =COUNTIFS('1월'!$C$8:$C$162,$B27,'1월'!$E$8:$E$162,C$24)+COUNTIFS('2월'!$C$8:$C$162,$B27,'2월'!$E$8:$E$162,C$24)+COUNTIFS('3월'!$C$8:$C$162,$B27,'3월'!$E$8:$E$162,C$24)+COUNTIFS('4월'!$C$8:$C$162,$B27,'4월'!$E$8:$E$162,C$24)+COUNTIFS('5월'!$C$8:$C$162,$B27,'5월'!$E$8:$E$162,C$24)+COUNTIFS('6월'!$C$8:$C$162,$B27,'6월'!$E$8:$E$162,C$24)+COUNTIFS('7월'!$C$8:$C$162,$B27,'7월'!$E$8:$E$162,C$24)+COUNTIFS('8월'!$C$8:$C$162,$B27,'8월'!$E$8:$E$162,C$24)+COUNTIFS('9월'!$C$8:$C$162,$B27,'9월'!$E$8:$E$162,C$24)+COUNTIFS('10월'!$C$8:$C$162,$B27,'10월'!$E$8:$E$162,C$24)+COUNTIFS('11월'!$C$8:$C$162,$B27,'11월'!$E$8:$E$162,C$24)+COUNTIFS('12월'!$C$8:$C$162,$B27,'12월'!$E$8:$E$162,C$24) | D27: =COUNTIFS('1월'!$C$8:$C$162,$B27,'1월'!$E$8:$E$162,D$24)+COUNTIFS('2월'!$C$8:$C$162,$B27,'2월'!$E$8:$E$162,D$24)+COUNTIFS('3월'!$C$8:$C$162,$B27,'3월'!$E$8:$E$162,D$24)+COUNTIFS('4월'!$C$8:$C$162,$B27,'4월'!$E$8:$E$162,D$24)+COUNTIFS('5월'!$C$8:$C$162,$B27,'5월'!$E$8:$E$162,D$24)+COUNTIFS('6월'!$C$8:$C$162,$B27,'6월'!$E$8:$E$162,D$24)+COUNTIFS('7월'!$C$8:$C$162,$B27,'7월'!$E$8:$E$162,D$24)+COUNTIFS('8월'!$C$8:$C$162,$B27,'8월'!$E$8:$E$162,D$24)+COUNTIFS('9월'!$C$8:$C$162,$B27,'9월'!$E$8:$E$162,D$24)+COUNTIFS('10월'!$C$8:$C$162,$B27,'10월'!$E$8:$E$162,D$24)+COUNTIFS('11월'!$C$8:$C$162,$B27,'11월'!$E$8:$E$162,D$24)+COUNTIFS('12월'!$C$8:$C$162,$B27,'12월'!$E$8:$E$162,D$24) | E27: =COUNTIFS('1월'!$C$8:$C$162,$B27,'1월'!$E$8:$E$162,E$24)+COUNTIFS('2월'!$C$8:$C$162,$B27,'2월'!$E$8:$E$162,E$24)+COUNTIFS('3월'!$C$8:$C$162,$B27,'3월'!$E$8:$E$162,E$24)+COUNTIFS('4월'!$C$8:$C$162,$B27,'4월'!$E$8:$E$162,E$24)+COUNTIFS('5월'!$C$8:$C$162,$B27,'5월'!$E$8:$E$162,E$24)+COUNTIFS('6월'!$C$8:$C$162,$B27,'6월'!$E$8:$E$162,E$24)+COUNTIFS('7월'!$C$8:$C$162,$B27,'7월'!$E$8:$E$162,E$24)+COUNTIFS('8월'!$C$8:$C$162,$B27,'8월'!$E$8:$E$162,E$24)+COUNTIFS('9월'!$C$8:$C$162,$B27,'9월'!$E$8:$E$162,E$24)+COUNTIFS('10월'!$C$8:$C$162,$B27,'10월'!$E$8:$E$162,E$24)+COUNTIFS('11월'!$C$8:$C$162,$B27,'11월'!$E$8:$E$162,E$24)+COUNTIFS('12월'!$C$8:$C$162,$B27,'12월'!$E$8:$E$162,E$24) | H27: SOL 인챈트 | I27: =COUNTIF('1월'!$B$8:$B$162,$H27)+COUNTIF('2월'!$B$8:$B$162,$H27)+COUNTIF('3월'!$B$8:$B$162,$H27)+COUNTIF('4월'!$B$8:$B$162,$H27)+COUNTIF('5월'!$B$8:$B$162,$H27)+COUNTIF('6월'!$B$8:$B$162,$H27)+COUNTIF('7월'!$B$8:$B$162,$H27)+COUNTIF('8월'!$B$8:$B$162,$H27)+COUNTIF('9월'!$B$8:$B$162,$H27)+COUNTIF('10월'!$B$8:$B$162,$H27)+COUNTIF('11월'!$B$8:$B$162,$H27)+COUNTIF('12월'!$B$8:$B$162,$H27) | J27: =SUMIF('1월'!$B$8:$B$162,$H27,'1월'!$K$8:$K$162)+SUMIF('2월'!$B$8:$B$162,$H27,'2월'!$K$8:$K$162)+SUMIF('3월'!$B$8:$B$162,$H27,'3월'!$K$8:$K$162)+SUMIF('4월'!$B$8:$B$162,$H27,'4월'!$K$8:$K$162)+SUMIF('5월'!$B$8:$B$162,$H27,'5월'!$K$8:$K$162)+SUMIF('6월'!$B$8:$B$162,$H27,'6월'!$K$8:$K$162)+SUMIF('7월'!$B$8:$B$162,$H27,'7월'!$K$8:$K$162)+SUMIF('8월'!$B$8:$B$162,$H27,'8월'!$K$8:$K$162)+SUMIF('9월'!$B$8:$B$162,$H27,'9월'!$K$8:$K$162)+SUMIF('10월'!$B$8:$B$162,$H27,'10월'!$K$8:$K$162)+SUMIF('11월'!$B$8:$B$162,$H27,'11월'!$K$8:$K$162)+SUMIF('12월'!$B$8:$B$162,$H27,'12월'!$K$8:$K$162)
B28: 마케팅4팀 | C28: =COUNTIFS('1월'!$C$8:$C$162,$B28,'1월'!$E$8:$E$162,C$24)+COUNTIFS('2월'!$C$8:$C$162,$B28,'2월'!$E$8:$E$162,C$24)+COUNTIFS('3월'!$C$8:$C$162,$B28,'3월'!$E$8:$E$162,C$24)+COUNTIFS('4월'!$C$8:$C$162,$B28,'4월'!$E$8:$E$162,C$24)+COUNTIFS('5월'!$C$8:$C$162,$B28,'5월'!$E$8:$E$162,C$24)+COUNTIFS('6월'!$C$8:$C$162,$B28,'6월'!$E$8:$E$162,C$24)+COUNTIFS('7월'!$C$8:$C$162,$B28,'7월'!$E$8:$E$162,C$24)+COUNTIFS('8월'!$C$8:$C$162,$B28,'8월'!$E$8:$E$162,C$24)+COUNTIFS('9월'!$C$8:$C$162,$B28,'9월'!$E$8:$E$162,C$24)+COUNTIFS('10월'!$C$8:$C$162,$B28,'10월'!$E$8:$E$162,C$24)+COUNTIFS('11월'!$C$8:$C$162,$B28,'11월'!$E$8:$E$162,C$24)+COUNTIFS('12월'!$C$8:$C$162,$B28,'12월'!$E$8:$E$162,C$24) | D28: =COUNTIFS('1월'!$C$8:$C$162,$B28,'1월'!$E$8:$E$162,D$24)+COUNTIFS('2월'!$C$8:$C$162,$B28,'2월'!$E$8:$E$162,D$24)+COUNTIFS('3월'!$C$8:$C$162,$B28,'3월'!$E$8:$E$162,D$24)+COUNTIFS('4월'!$C$8:$C$162,$B28,'4월'!$E$8:$E$162,D$24)+COUNTIFS('5월'!$C$8:$C$162,$B28,'5월'!$E$8:$E$162,D$24)+COUNTIFS('6월'!$C$8:$C$162,$B28,'6월'!$E$8:$E$162,D$24)+COUNTIFS('7월'!$C$8:$C$162,$B28,'7월'!$E$8:$E$162,D$24)+COUNTIFS('8월'!$C$8:$C$162,$B28,'8월'!$E$8:$E$162,D$24)+COUNTIFS('9월'!$C$8:$C$162,$B28,'9월'!$E$8:$E$162,D$24)+COUNTIFS('10월'!$C$8:$C$162,$B28,'10월'!$E$8:$E$162,D$24)+COUNTIFS('11월'!$C$8:$C$162,$B28,'11월'!$E$8:$E$162,D$24)+COUNTIFS('12월'!$C$8:$C$162,$B28,'12월'!$E$8:$E$162,D$24) | E28: =COUNTIFS('1월'!$C$8:$C$162,$B28,'1월'!$E$8:$E$162,E$24)+COUNTIFS('2월'!$C$8:$C$162,$B28,'2월'!$E$8:$E$162,E$24)+COUNTIFS('3월'!$C$8:$C$162,$B28,'3월'!$E$8:$E$162,E$24)+COUNTIFS('4월'!$C$8:$C$162,$B28,'4월'!$E$8:$E$162,E$24)+COUNTIFS('5월'!$C$8:$C$162,$B28,'5월'!$E$8:$E$162,E$24)+COUNTIFS('6월'!$C$8:$C$162,$B28,'6월'!$E$8:$E$162,E$24)+COUNTIFS('7월'!$C$8:$C$162,$B28,'7월'!$E$8:$E$162,E$24)+COUNTIFS('8월'!$C$8:$C$162,$B28,'8월'!$E$8:$E$162,E$24)+COUNTIFS('9월'!$C$8:$C$162,$B28,'9월'!$E$8:$E$162,E$24)+COUNTIFS('10월'!$C$8:$C$162,$B28,'10월'!$E$8:$E$162,E$24)+COUNTIFS('11월'!$C$8:$C$162,$B28,'11월'!$E$8:$E$162,E$24)+COUNTIFS('12월'!$C$8:$C$162,$B28,'12월'!$E$8:$E$162,E$24) | H28: 스톤에이지펫월드 | I28: =COUNTIF('1월'!$B$8:$B$162,$H28)+COUNTIF('2월'!$B$8:$B$162,$H28)+COUNTIF('3월'!$B$8:$B$162,$H28)+COUNTIF('4월'!$B$8:$B$162,$H28)+COUNTIF('5월'!$B$8:$B$162,$H28)+COUNTIF('6월'!$B$8:$B$162,$H28)+COUNTIF('7월'!$B$8:$B$162,$H28)+COUNTIF('8월'!$B$8:$B$162,$H28)+COUNTIF('9월'!$B$8:$B$162,$H28)+COUNTIF('10월'!$B$8:$B$162,$H28)+COUNTIF('11월'!$B$8:$B$162,$H28)+COUNTIF('12월'!$B$8:$B$162,$H28) | J28: =SUMIF('1월'!$B$8:$B$162,$H28,'1월'!$K$8:$K$162)+SUMIF('2월'!$B$8:$B$162,$H28,'2월'!$K$8:$K$162)+SUMIF('3월'!$B$8:$B$162,$H28,'3월'!$K$8:$K$162)+SUMIF('4월'!$B$8:$B$162,$H28,'4월'!$K$8:$K$162)+SUMIF('5월'!$B$8:$B$162,$H28,'5월'!$K$8:$K$162)+SUMIF('6월'!$B$8:$B$162,$H28,'6월'!$K$8:$K$162)+SUMIF('7월'!$B$8:$B$162,$H28,'7월'!$K$8:$K$162)+SUMIF('8월'!$B$8:$B$162,$H28,'8월'!$K$8:$K$162)+SUMIF('9월'!$B$8:$B$162,$H28,'9월'!$K$8:$K$162)+SUMIF('10월'!$B$8:$B$162,$H28,'10월'!$K$8:$K$162)+SUMIF('11월'!$B$8:$B$162,$H28,'11월'!$K$8:$K$162)+SUMIF('12월'!$B$8:$B$162,$H28,'12월'!$K$8:$K$162)
B29: 기타 | C29: =COUNTIFS('1월'!$C$8:$C$162,$B29,'1월'!$E$8:$E$162,C$24)+COUNTIFS('2월'!$C$8:$C$162,$B29,'2월'!$E$8:$E$162,C$24)+COUNTIFS('3월'!$C$8:$C$162,$B29,'3월'!$E$8:$E$162,C$24)+COUNTIFS('4월'!$C$8:$C$162,$B29,'4월'!$E$8:$E$162,C$24)+COUNTIFS('5월'!$C$8:$C$162,$B29,'5월'!$E$8:$E$162,C$24)+COUNTIFS('6월'!$C$8:$C$162,$B29,'6월'!$E$8:$E$162,C$24)+COUNTIFS('7월'!$C$8:$C$162,$B29,'7월'!$E$8:$E$162,C$24)+COUNTIFS('8월'!$C$8:$C$162,$B29,'8월'!$E$8:$E$162,C$24)+COUNTIFS('9월'!$C$8:$C$162,$B29,'9월'!$E$8:$E$162,C$24)+COUNTIFS('10월'!$C$8:$C$162,$B29,'10월'!$E$8:$E$162,C$24)+COUNTIFS('11월'!$C$8:$C$162,$B29,'11월'!$E$8:$E$162,C$24)+COUNTIFS('12월'!$C$8:$C$162,$B29,'12월'!$E$8:$E$162,C$24) | D29: =COUNTIFS('1월'!$C$8:$C$162,$B29,'1월'!$E$8:$E$162,D$24)+COUNTIFS('2월'!$C$8:$C$162,$B29,'2월'!$E$8:$E$162,D$24)+COUNTIFS('3월'!$C$8:$C$162,$B29,'3월'!$E$8:$E$162,D$24)+COUNTIFS('4월'!$C$8:$C$162,$B29,'4월'!$E$8:$E$162,D$24)+COUNTIFS('5월'!$C$8:$C$162,$B29,'5월'!$E$8:$E$162,D$24)+COUNTIFS('6월'!$C$8:$C$162,$B29,'6월'!$E$8:$E$162,D$24)+COUNTIFS('7월'!$C$8:$C$162,$B29,'7월'!$E$8:$E$162,D$24)+COUNTIFS('8월'!$C$8:$C$162,$B29,'8월'!$E$8:$E$162,D$24)+COUNTIFS('9월'!$C$8:$C$162,$B29,'9월'!$E$8:$E$162,D$24)+COUNTIFS('10월'!$C$8:$C$162,$B29,'10월'!$E$8:$E$162,D$24)+COUNTIFS('11월'!$C$8:$C$162,$B29,'11월'!$E$8:$E$162,D$24)+COUNTIFS('12월'!$C$8:$C$162,$B29,'12월'!$E$8:$E$162,D$24) | E29: =COUNTIFS('1월'!$C$8:$C$162,$B29,'1월'!$E$8:$E$162,E$24)+COUNTIFS('2월'!$C$8:$C$162,$B29,'2월'!$E$8:$E$162,E$24)+COUNTIFS('3월'!$C$8:$C$162,$B29,'3월'!$E$8:$E$162,E$24)+COUNTIFS('4월'!$C$8:$C$162,$B29,'4월'!$E$8:$E$162,E$24)+COUNTIFS('5월'!$C$8:$C$162,$B29,'5월'!$E$8:$E$162,E$24)+COUNTIFS('6월'!$C$8:$C$162,$B29,'6월'!$E$8:$E$162,E$24)+COUNTIFS('7월'!$C$8:$C$162,$B29,'7월'!$E$8:$E$162,E$24)+COUNTIFS('8월'!$C$8:$C$162,$B29,'8월'!$E$8:$E$162,E$24)+COUNTIFS('9월'!$C$8:$C$162,$B29,'9월'!$E$8:$E$162,E$24)+COUNTIFS('10월'!$C$8:$C$162,$B29,'10월'!$E$8:$E$162,E$24)+COUNTIFS('11월'!$C$8:$C$162,$B29,'11월'!$E$8:$E$162,E$24)+COUNTIFS('12월'!$C$8:$C$162,$B29,'12월'!$E$8:$E$162,E$24) | H29: 칠대죄오리진 | I29: =COUNTIF('1월'!$B$8:$B$162,$H29)+COUNTIF('2월'!$B$8:$B$162,$H29)+COUNTIF('3월'!$B$8:$B$162,$H29)+COUNTIF('4월'!$B$8:$B$162,$H29)+COUNTIF('5월'!$B$8:$B$162,$H29)+COUNTIF('6월'!$B$8:$B$162,$H29)+COUNTIF('7월'!$B$8:$B$162,$H29)+COUNTIF('8월'!$B$8:$B$162,$H29)+COUNTIF('9월'!$B$8:$B$162,$H29)+COUNTIF('10월'!$B$8:$B$162,$H29)+COUNTIF('11월'!$B$8:$B$162,$H29)+COUNTIF('12월'!$B$8:$B$162,$H29) | J29: =SUMIF('1월'!$B$8:$B$162,$H29,'1월'!$K$8:$K$162)+SUMIF('2월'!$B$8:$B$162,$H29,'2월'!$K$8:$K$162)+SUMIF('3월'!$B$8:$B$162,$H29,'3월'!$K$8:$K$162)+SUMIF('4월'!$B$8:$B$162,$H29,'4월'!$K$8:$K$162)+SUMIF('5월'!$B$8:$B$162,$H29,'5월'!$K$8:$K$162)+SUMIF('6월'!$B$8:$B$162,$H29,'6월'!$K$8:$K$162)+SUMIF('7월'!$B$8:$B$162,$H29,'7월'!$K$8:$K$162)+SUMIF('8월'!$B$8:$B$162,$H29,'8월'!$K$8:$K$162)+SUMIF('9월'!$B$8:$B$162,$H29,'9월'!$K$8:$K$162)+SUMIF('10월'!$B$8:$B$162,$H29,'10월'!$K$8:$K$162)+SUMIF('11월'!$B$8:$B$162,$H29,'11월'!$K$8:$K$162)+SUMIF('12월'!$B$8:$B$162,$H29,'12월'!$K$8:$K$162)
H30: 세나리버스 | I30: =COUNTIF('1월'!$B$8:$B$162,$H30)+COUNTIF('2월'!$B$8:$B$162,$H30)+COUNTIF('3월'!$B$8:$B$162,$H30)+COUNTIF('4월'!$B$8:$B$162,$H30)+COUNTIF('5월'!$B$8:$B$162,$H30)+COUNTIF('6월'!$B$8:$B$162,$H30)+COUNTIF('7월'!$B$8:$B$162,$H30)+COUNTIF('8월'!$B$8:$B$162,$H30)+COUNTIF('9월'!$B$8:$B$162,$H30)+COUNTIF('10월'!$B$8:$B$162,$H30)+COUNTIF('11월'!$B$8:$B$162,$H30)+COUNTIF('12월'!$B$8:$B$162,$H30) | J30: =SUMIF('1월'!$B$8:$B$162,$H30,'1월'!$K$8:$K$162)+SUMIF('2월'!$B$8:$B$162,$H30,'2월'!$K$8:$K$162)+SUMIF('3월'!$B$8:$B$162,$H30,'3월'!$K$8:$K$162)+SUMIF('4월'!$B$8:$B$162,$H30,'4월'!$K$8:$K$162)+SUMIF('5월'!$B$8:$B$162,$H30,'5월'!$K$8:$K$162)+SUMIF('6월'!$B$8:$B$162,$H30,'6월'!$K$8:$K$162)+SUMIF('7월'!$B$8:$B$162,$H30,'7월'!$K$8:$K$162)+SUMIF('8월'!$B$8:$B$162,$H30,'8월'!$K$8:$K$162)+SUMIF('9월'!$B$8:$B$162,$H30,'9월'!$K$8:$K$162)+SUMIF('10월'!$B$8:$B$162,$H30,'10월'!$K$8:$K$162)+SUMIF('11월'!$B$8:$B$162,$H30,'11월'!$K$8:$K$162)+SUMIF('12월'!$B$8:$B$162,$H30,'12월'!$K$8:$K$162)
H31: 몬길 | I31: =COUNTIF('1월'!$B$8:$B$162,$H31)+COUNTIF('2월'!$B$8:$B$162,$H31)+COUNTIF('3월'!$B$8:$B$162,$H31)+COUNTIF('4월'!$B$8:$B$162,$H31)+COUNTIF('5월'!$B$8:$B$162,$H31)+COUNTIF('6월'!$B$8:$B$162,$H31)+COUNTIF('7월'!$B$8:$B$162,$H31)+COUNTIF('8월'!$B$8:$B$162,$H31)+COUNTIF('9월'!$B$8:$B$162,$H31)+COUNTIF('10월'!$B$8:$B$162,$H31)+COUNTIF('11월'!$B$8:$B$162,$H31)+COUNTIF('12월'!$B$8:$B$162,$H31) | J31: =SUMIF('1월'!$B$8:$B$162,$H31,'1월'!$K$8:$K$162)+SUMIF('2월'!$B$8:$B$162,$H31,'2월'!$K$8:$K$162)+SUMIF('3월'!$B$8:$B$162,$H31,'3월'!$K$8:$K$162)+SUMIF('4월'!$B$8:$B$162,$H31,'4월'!$K$8:$K$162)+SUMIF('5월'!$B$8:$B$162,$H31,'5월'!$K$8:$K$162)+SUMIF('6월'!$B$8:$B$162,$H31,'6월'!$K$8:$K$162)+SUMIF('7월'!$B$8:$B$162,$H31,'7월'!$K$8:$K$162)+SUMIF('8월'!$B$8:$B$162,$H31,'8월'!$K$8:$K$162)+SUMIF('9월'!$B$8:$B$162,$H31,'9월'!$K$8:$K$162)+SUMIF('10월'!$B$8:$B$162,$H31,'10월'!$K$8:$K$162)+SUMIF('11월'!$B$8:$B$162,$H31,'11월'!$K$8:$K$162)+SUMIF('12월'!$B$8:$B$162,$H31,'12월'!$K$8:$K$162)
H32: 왕겜(GOT) | I32: =COUNTIF('1월'!$B$8:$B$162,$H32)+COUNTIF('2월'!$B$8:$B$162,$H32)+COUNTIF('3월'!$B$8:$B$162,$H32)+COUNTIF('4월'!$B$8:$B$162,$H32)+COUNTIF('5월'!$B$8:$B$162,$H32)+COUNTIF('6월'!$B$8:$B$162,$H32)+COUNTIF('7월'!$B$8:$B$162,$H32)+COUNTIF('8월'!$B$8:$B$162,$H32)+COUNTIF('9월'!$B$8:$B$162,$H32)+COUNTIF('10월'!$B$8:$B$162,$H32)+COUNTIF('11월'!$B$8:$B$162,$H32)+COUNTIF('12월'!$B$8:$B$162,$H32) | J32: =SUMIF('1월'!$B$8:$B$162,$H32,'1월'!$K$8:$K$162)+SUMIF('2월'!$B$8:$B$162,$H32,'2월'!$K$8:$K$162)+SUMIF('3월'!$B$8:$B$162,$H32,'3월'!$K$8:$K$162)+SUMIF('4월'!$B$8:$B$162,$H32,'4월'!$K$8:$K$162)+SUMIF('5월'!$B$8:$B$162,$H32,'5월'!$K$8:$K$162)+SUMIF('6월'!$B$8:$B$162,$H32,'6월'!$K$8:$K$162)+SUMIF('7월'!$B$8:$B$162,$H32,'7월'!$K$8:$K$162)+SUMIF('8월'!$B$8:$B$162,$H32,'8월'!$K$8:$K$162)+SUMIF('9월'!$B$8:$B$162,$H32,'9월'!$K$8:$K$162)+SUMIF('10월'!$B$8:$B$162,$H32,'10월'!$K$8:$K$162)+SUMIF('11월'!$B$8:$B$162,$H32,'11월'!$K$8:$K$162)+SUMIF('12월'!$B$8:$B$162,$H32,'12월'!$K$8:$K$162)
H33: 몬스터길들이기 | I33: =COUNTIF('1월'!$B$8:$B$162,$H33)+COUNTIF('2월'!$B$8:$B$162,$H33)+COUNTIF('3월'!$B$8:$B$162,$H33)+COUNTIF('4월'!$B$8:$B$162,$H33)+COUNTIF('5월'!$B$8:$B$162,$H33)+COUNTIF('6월'!$B$8:$B$162,$H33)+COUNTIF('7월'!$B$8:$B$162,$H33)+COUNTIF('8월'!$B$8:$B$162,$H33)+COUNTIF('9월'!$B$8:$B$162,$H33)+COUNTIF('10월'!$B$8:$B$162,$H33)+COUNTIF('11월'!$B$8:$B$162,$H33)+COUNTIF('12월'!$B$8:$B$162,$H33) | J33: =SUMIF('1월'!$B$8:$B$162,$H33,'1월'!$K$8:$K$162)+SUMIF('2월'!$B$8:$B$162,$H33,'2월'!$K$8:$K$162)+SUMIF('3월'!$B$8:$B$162,$H33,'3월'!$K$8:$K$162)+SUMIF('4월'!$B$8:$B$162,$H33,'4월'!$K$8:$K$162)+SUMIF('5월'!$B$8:$B$162,$H33,'5월'!$K$8:$K$162)+SUMIF('6월'!$B$8:$B$162,$H33,'6월'!$K$8:$K$162)+SUMIF('7월'!$B$8:$B$162,$H33,'7월'!$K$8:$K$162)+SUMIF('8월'!$B$8:$B$162,$H33,'8월'!$K$8:$K$162)+SUMIF('9월'!$B$8:$B$162,$H33,'9월'!$K$8:$K$162)+SUMIF('10월'!$B$8:$B$162,$H33,'10월'!$K$8:$K$162)+SUMIF('11월'!$B$8:$B$162,$H33,'11월'!$K$8:$K$162)+SUMIF('12월'!$B$8:$B$162,$H33,'12월'!$K$8:$K$162)
H34: 라이즈오브 | I34: =COUNTIF('1월'!$B$8:$B$162,$H34)+COUNTIF('2월'!$B$8:$B$162,$H34)+COUNTIF('3월'!$B$8:$B$162,$H34)+COUNTIF('4월'!$B$8:$B$162,$H34)+COUNTIF('5월'!$B$8:$B$162,$H34)+COUNTIF('6월'!$B$8:$B$162,$H34)+COUNTIF('7월'!$B$8:$B$162,$H34)+COUNTIF('8월'!$B$8:$B$162,$H34)+COUNTIF('9월'!$B$8:$B$162,$H34)+COUNTIF('10월'!$B$8:$B$162,$H34)+COUNTIF('11월'!$B$8:$B$162,$H34)+COUNTIF('12월'!$B$8:$B$162,$H34) | J34: =SUMIF('1월'!$B$8:$B$162,$H34,'1월'!$K$8:$K$162)+SUMIF('2월'!$B$8:$B$162,$H34,'2월'!$K$8:$K$162)+SUMIF('3월'!$B$8:$B$162,$H34,'3월'!$K$8:$K$162)+SUMIF('4월'!$B$8:$B$162,$H34,'4월'!$K$8:$K$162)+SUMIF('5월'!$B$8:$B$162,$H34,'5월'!$K$8:$K$162)+SUMIF('6월'!$B$8:$B$162,$H34,'6월'!$K$8:$K$162)+SUMIF('7월'!$B$8:$B$162,$H34,'7월'!$K$8:$K$162)+SUMIF('8월'!$B$8:$B$162,$H34,'8월'!$K$8:$K$162)+SUMIF('9월'!$B$8:$B$162,$H34,'9월'!$K$8:$K$162)+SUMIF('10월'!$B$8:$B$162,$H34,'10월'!$K$8:$K$162)+SUMIF('11월'!$B$8:$B$162,$H34,'11월'!$K$8:$K$162)+SUMIF('12월'!$B$8:$B$162,$H34,'12월'!$K$8:$K$162)

Sheet 1월
A1: 1월 업무 정보 (소재명 = 직군별 줄) | H1: 수량 (소재당 1번만) | K1: 집계 / 일정 (자동) | U1: 1월 간트 - 날짜 칸에 MD 직접 입력 (주말+공휴일 회색) 상단 4줄=일자별 직군 TO 상태
A2: No | B2: 게임 타이틀명 | C2: 고객팀 | D2: 소재명(업무명) | E2: 직군 | F2: 담당자 | G2: 최종완료일 (고객전달) | H2: 영상 수 | I2: 사이즈 베리 | J2: 다국어 베리 | K2: 합계 MD | L2: 시작일 (자동) | M2: 완료일 (자동) | N2: 여유 | O2: 상태 | P2: 비고 | U2: =DATE('마스터'!$J$3,1,1) | V2: =U2+1 | W2: =V2+1 | X2: =W2+1 | Y2: =X2+1 | Z2: =Y2+1 | AA2: =Z2+1 | AB2: =AA2+1 | AC2: =AB2+1 | ... AY2: =AX2+1
A3: 전체 TO (일자별 부하) | G3: 정원 | H3: =SUM('마스터'!$J$8:$J$10) | U3: =SUM(U$8:U$162) | V3: =SUM(V$8:V$162) | W3: =SUM(W$8:W$162) | X3: =SUM(X$8:X$162) | Y3: =SUM(Y$8:Y$162) | Z3: =SUM(Z$8:Z$162) | AA3: =SUM(AA$8:AA$162) | AB3: =SUM(AB$8:AB$162) | ... AY3: =SUM(AY$8:AY$162)
A4: 영상 TO | G4: 정원 | H4: ='마스터'!$J$8 | U4: =SUMIF($E$8:$E$162,"영상",U$8:U$162) | V4: =SUMIF($E$8:$E$162,"영상",V$8:V$162) | W4: =SUMIF($E$8:$E$162,"영상",W$8:W$162) | X4: =SUMIF($E$8:$E$162,"영상",X$8:X$162) | Y4: =SUMIF($E$8:$E$162,"영상",Y$8:Y$162) | Z4: =SUMIF($E$8:$E$162,"영상",Z$8:Z$162) | AA4: =SUMIF($E$8:$E$162,"영상",AA$8:AA$162) | AB4: =SUMIF($E$8:$E$162,"영상",AB$8:AB$162) | ... AY4: =SUMIF($E$8:$E$162,"영상",AY$8:AY$162)
A5: 이미지 TO | G5: 정원 | H5: ='마스터'!$J$9 | U5: =SUMIF($E$8:$E$162,"이미지",U$8:U$162) | V5: =SUMIF($E$8:$E$162,"이미지",V$8:V$162) | W5: =SUMIF($E$8:$E$162,"이미지",W$8:W$162) | X5: =SUMIF($E$8:$E$162,"이미지",X$8:X$162) | Y5: =SUMIF($E$8:$E$162,"이미지",Y$8:Y$162) | Z5: =SUMIF($E$8:$E$162,"이미지",Z$8:Z$162) | AA5: =SUMIF($E$8:$E$162,"이미지",AA$8:AA$162) | AB5: =SUMIF($E$8:$E$162,"이미지",AB$8:AB$162) | ... AY5: =SUMIF($E$8:$E$162,"이미지",AY$8:AY$162)
A6: 기획 TO | G6: 정원 | H6: ='마스터'!$J$10 | U6: =SUMIF($E$8:$E$162,"기획",U$8:U$162) | V6: =SUMIF($E$8:$E$162,"기획",V$8:V$162) | W6: =SUMIF($E$8:$E$162,"기획",W$8:W$162) | X6: =SUMIF($E$8:$E$162,"기획",X$8:X$162) | Y6: =SUMIF($E$8:$E$162,"기획",Y$8:Y$162) | Z6: =SUMIF($E$8:$E$162,"기획",Z$8:Z$162) | AA6: =SUMIF($E$8:$E$162,"기획",AA$8:AA$162) | AB6: =SUMIF($E$8:$E$162,"기획",AB$8:AB$162) | ... AY6: =SUMIF($E$8:$E$162,"기획",AY$8:AY$162)
A8: 마케팅1팀 (9~38행)
A9: =IF(D9="","",COUNTA($D$9:D9)) | C9: 마케팅1팀 | K9: =IF(SUM(U9:AY9)=0,"",SUM(U9:AY9)) | L9: =IFERROR(INDEX(U$2:AY$2,MATCH(TRUE,U9:AY9<>"",0)),"") | M9: =IFERROR(LOOKUP(2,1/(U9:AY9<>""),U$2:AY$2),"") | N9: =IF(OR(G9="",M9=""),"",G9-M9)
A10: =IF(D10="","",COUNTA($D$9:D10)) | C10: 마케팅1팀 | K10: =IF(SUM(U10:AY10)=0,"",SUM(U10:AY10)) | L10: =IFERROR(INDEX(U$2:AY$2,MATCH(TRUE,U10:AY10<>"",0)),"") | M10: =IFERROR(LOOKUP(2,1/(U10:AY10<>""),U$2:AY$2),"") | N10: =IF(OR(G10="",M10=""),"",G10-M10)
A11: =IF(D11="","",COUNTA($D$9:D11)) | C11: 마케팅1팀 | K11: =IF(SUM(U11:AY11)=0,"",SUM(U11:AY11)) | L11: =IFERROR(INDEX(U$2:AY$2,MATCH(TRUE,U11:AY11<>"",0)),"") | M11: =IFERROR(LOOKUP(2,1/(U11:AY11<>""),U$2:AY$2),"") | N11: =IF(OR(G11="",M11=""),"",G11-M11)
A12: =IF(D12="","",COUNTA($D$9:D12)) | C12: 마케팅1팀 | K12: =IF(SUM(U12:AY12)=0,"",SUM(U12:AY12)) | L12: =IFERROR(INDEX(U$2:AY$2,MATCH(TRUE,U12:AY12<>"",0)),"") | M12: =IFERROR(LOOKUP(2,1/(U12:AY12<>""),U$2:AY$2),"") | N12: =IF(OR(G12="",M12=""),"",G12-M12)
A13: =IF(D13="","",COUNTA($D$9:D13)) | C13: 마케팅1팀 | K13: =IF(SUM(U13:AY13)=0,"",SUM(U13:AY13)) | L13: =IFERROR(INDEX(U$2:AY$2,MATCH(TRUE,U13:AY13<>"",0)),"") | M13: =IFERROR(LOOKUP(2,1/(U13:AY13<>""),U$2:AY$2),"") | N13: =IF(OR(G13="",M13=""),"",G13-M13)
A14: =IF(D14="","",COUNTA($D$9:D14)) | C14: 마케팅1팀 | K14: =IF(SUM(U14:AY14)=0,"",SUM(U14:AY14)) | L14: =IFERROR(INDEX(U$2:AY$2,MATCH(TRUE,U14:AY14<>"",0)),"") | M14: =IFERROR(LOOKUP(2,1/(U14:AY14<>""),U$2:AY$2),"") | N14: =IF(OR(G14="",M14=""),"",G14-M14)
A15: =IF(D15="","",COUNTA($D$9:D15)) | C15: 마케팅1팀 | K15: =IF(SUM(U15:AY15)=0,"",SUM(U15:AY15)) | L15: =IFERROR(INDEX(U$2:AY$2,MATCH(TRUE,U15:AY15<>"",0)),"") | M15: =IFERROR(LOOKUP(2,1/(U15:AY15<>""),U$2:AY$2),"") | N15: =IF(OR(G15="",M15=""),"",G15-M15)
A16: =IF(D16="","",COUNTA($D$9:D16)) | C16: 마케팅1팀 | K16: =IF(SUM(U16:AY16)=0,"",SUM(U16:AY16)) | L16: =IFERROR(INDEX(U$2:AY$2,MATCH(TRUE,U16:AY16<>"",0)),"") | M16: =IFERROR(LOOKUP(2,1/(U16:AY16<>""),U$2:AY$2),"") | N16: =IF(OR(G16="",M16=""),"",G16-M16)
A17: =IF(D17="","",COUNTA($D$9:D17)) | C17: 마케팅1팀 | K17: =IF(SUM(U17:AY17)=0,"",SUM(U17:AY17)) | L17: =IFERROR(INDEX(U$2:AY$2,MATCH(TRUE,U17:AY17<>"",0)),"") | M17: =IFERROR(LOOKUP(2,1/(U17:AY17<>""),U$2:AY$2),"") | N17: =IF(OR(G17="",M17=""),"",G17-M17)
A18: =IF(D18="","",COUNTA($D$9:D18)) | C18: 마케팅1팀 | K18: =IF(SUM(U18:AY18)=0,"",SUM(U18:AY18)) | L18: =IFERROR(INDEX(U$2:AY$2,MATCH(TRUE,U18:AY18<>"",0)),"") | M18: =IFERROR(LOOKUP(2,1/(U18:AY18<>""),U$2:AY$2),"") | N18: =IF(OR(G18="",M18=""),"",G18-M18)
A19: =IF(D19="","",COUNTA($D$9:D19)) | C19: 마케팅1팀 | K19: =IF(SUM(U19:AY19)=0,"",SUM(U19:AY19)) | L19: =IFERROR(INDEX(U$2:AY$2,MATCH(TRUE,U19:AY19<>"",0)),"") | M19: =IFERROR(LOOKUP(2,1/(U19:AY19<>""),U$2:AY$2),"") | N19: =IF(OR(G19="",M19=""),"",G19-M19)
A20: =IF(D20="","",COUNTA($D$9:D20)) | C20: 마케팅1팀 | K20: =IF(SUM(U20:AY20)=0,"",SUM(U20:AY20)) | L20: =IFERROR(INDEX(U$2:AY$2,MATCH(TRUE,U20:AY20<>"",0)),"") | M20: =IFERROR(LOOKUP(2,1/(U20:AY20<>""),U$2:AY$2),"") | N20: =IF(OR(G20="",M20=""),"",G20-M20)
... A38: =IF(D38="","",COUNTA($D$9:D38)) | C38: 마케팅1팀 | K38: =IF(SUM(U38:AY38)=0,"",SUM(U38:AY38)) | L38: =IFERROR(INDEX(U$2:AY$2,MATCH(TRUE,U38:AY38<>"",0)),"") | M38: =IFERROR(LOOKUP(2,1/(U38:AY38<>""),U$2:AY$2),"") | N38: =IF(OR(G38="",M38=""),"",G38-M38)
A39: 마케팅2팀 (40~69행)
A40: =IF(D40="","",COUNTA($D$40:D40)) | C40: 마케팅2팀 | K40: =IF(SUM(U40:AY40)=0,"",SUM(U40:AY40)) | L40: =IFERROR(INDEX(U$2:AY$2,MATCH(TRUE,U40:AY40<>"",0)),"") | M40: =IFERROR(LOOKUP(2,1/(U40:AY40<>""),U$2:AY$2),"") | N40: =IF(OR(G40="",M40=""),"",G40-M40)
A41: =IF(D41="","",COUNTA($D$40:D41)) | C41: 마케팅2팀 | K41: =IF(SUM(U41:AY41)=0,"",SUM(U41:AY41)) | L41: =IFERROR(INDEX(U$2:AY$2,MATCH(TRUE,U41:AY41<>"",0)),"") | M41: =IFERROR(LOOKUP(2,1/(U41:AY41<>""),U$2:AY$2),"") | N41: =IF(OR(G41="",M41=""),"",G41-M41)
A42: =IF(D42="","",COUNTA($D$40:D42)) | C42: 마케팅2팀 | K42: =IF(SUM(U42:AY42)=0,"",SUM(U42:AY42)) | L42: =IFERROR(INDEX(U$2:AY$2,MATCH(TRUE,U42:AY42<>"",0)),"") | M42: =IFERROR(LOOKUP(2,1/(U42:AY42<>""),U$2:AY$2),"") | N42: =IF(OR(G42="",M42=""),"",G42-M42)
A43: =IF(D43="","",COUNTA($D$40:D43)) | C43: 마케팅2팀 | K43: =IF(SUM(U43:AY43)=0,"",SUM(U43:AY43)) | L43: =IFERROR(INDEX(U$2:AY$2,MATCH(TRUE,U43:AY43<>"",0)),"") | M43: =IFERROR(LOOKUP(2,1/(U43:AY43<>""),U$2:AY$2),"") | N43: =IF(OR(G43="",M43=""),"",G43-M43)
A44: =IF(D44="","",COUNTA($D$40:D44)) | C44: 마케팅2팀 | K44: =IF(SUM(U44:AY44)=0,"",SUM(U44:AY44)) | L44: =IFERROR(INDEX(U$2:AY$2,MATCH(TRUE,U44:AY44<>"",0)),"") | M44: =IFERROR(LOOKUP(2,1/(U44:AY44<>""),U$2:AY$2),"") | N44: =IF(OR(G44="",M44=""),"",G44-M44)
A45: =IF(D45="","",COUNTA($D$40:D45)) | C45: 마케팅2팀 | K45: =IF(SUM(U45:AY45)=0,"",SUM(U45:AY45)) | L45: =IFERROR(INDEX(U$2:AY$2,MATCH(TRUE,U45:AY45<>"",0)),"") | M45: =IFERROR(LOOKUP(2,1/(U45:AY45<>""),U$2:AY$2),"") | N45: =IF(OR(G45="",M45=""),"",G45-M45)
A46: =IF(D46="","",COUNTA($D$40:D46)) | C46: 마케팅2팀 | K46: =IF(SUM(U46:AY46)=0,"",SUM(U46:AY46)) | L46: =IFERROR(INDEX(U$2:AY$2,MATCH(TRUE,U46:AY46<>"",0)),"") | M46: =IFERROR(LOOKUP(2,1/(U46:AY46<>""),U$2:AY$2),"") | N46: =IF(OR(G46="",M46=""),"",G46-M46)
A47: =IF(D47="","",COUNTA($D$40:D47)) | C47: 마케팅2팀 | K47: =IF(SUM(U47:AY47)=0,"",SUM(U47:AY47)) | L47: =IFERROR(INDEX(U$2:AY$2,MATCH(TRUE,U47:AY47<>"",0)),"") | M47: =IFERROR(LOOKUP(2,1/(U47:AY47<>""),U$2:AY$2),"") | N47: =IF(OR(G47="",M47=""),"",G47-M47)
A48: =IF(D48="","",COUNTA($D$40:D48)) | C48: 마케팅2팀 | K48: =IF(SUM(U48:AY48)=0,"",SUM(U48:AY48)) | L48: =IFERROR(INDEX(U$2:AY$2,MATCH(TRUE,U48:AY48<>"",0)),"") | M48: =IFERROR(LOOKUP(2,1/(U48:AY48<>""),U$2:AY$2),"") | N48: =IF(OR(G48="",M48=""),"",G48-M48)
A49: =IF(D49="","",COUNTA($D$40:D49)) | C49: 마케팅2팀 | K49: =IF(SUM(U49:AY49)=0,"",SUM(U49:AY49)) | L49: =IFERROR(INDEX(U$2:AY$2,MATCH(TRUE,U49:AY49<>"",0)),"") | M49: =IFERROR(LOOKUP(2,1/(U49:AY49<>""),U$2:AY$2),"") | N49: =IF(OR(G49="",M49=""),"",G49-M49)
A50: =IF(D50="","",COUNTA($D$40:D50)) | C50: 마케팅2팀 | K50: =IF(SUM(U50:AY50)=0,"",SUM(U50:AY50)) | L50: =IFERROR(INDEX(U$2:AY$2,MATCH(TRUE,U50:AY50<>"",0)),"") | M50: =IFERROR(LOOKUP(2,1/(U50:AY50<>""),U$2:AY$2),"") | N50: =IF(OR(G50="",M50=""),"",G50-M50)
A51: =IF(D51="","",COUNTA($D$40:D51)) | C51: 마케팅2팀 | K51: =IF(SUM(U51:AY51)=0,"",SUM(U51:AY51)) | L51: =IFERROR(INDEX(U$2:AY$2,MATCH(TRUE,U51:AY51<>"",0)),"") | M51: =IFERROR(LOOKUP(2,1/(U51:AY51<>""),U$2:AY$2),"") | N51: =IF(OR(G51="",M51=""),"",G51-M51)
... A69: =IF(D69="","",COUNTA($D$40:D69)) | C69: 마케팅2팀 | K69: =IF(SUM(U69:AY69)=0,"",SUM(U69:AY69)) | L69: =IFERROR(INDEX(U$2:AY$2,MATCH(TRUE,U69:AY69<>"",0)),"") | M69: =IFERROR(LOOKUP(2,1/(U69:AY69<>""),U$2:AY$2),"") | N69: =IF(OR(G69="",M69=""),"",G69-M69)
A70: 마케팅3팀 (71~100행)
A71: =IF(D71="","",COUNTA($D$71:D71)) | C71: 마케팅3팀 | K71: =IF(SUM(U71:AY71)=0,"",SUM(U71:AY71)) | L71: =IFERROR(INDEX(U$2:AY$2,MATCH(TRUE,U71:AY71<>"",0)),"") | M71: =IFERROR(LOOKUP(2,1/(U71:AY71<>""),U$2:AY$2),"") | N71: =IF(OR(G71="",M71=""),"",G71-M71)
A72: =IF(D72="","",COUNTA($D$71:D72)) | C72: 마케팅3팀 | K72: =IF(SUM(U72:AY72)=0,"",SUM(U72:AY72)) | L72: =IFERROR(INDEX(U$2:AY$2,MATCH(TRUE,U72:AY72<>"",0)),"") | M72: =IFERROR(LOOKUP(2,1/(U72:AY72<>""),U$2:AY$2),"") | N72: =IF(OR(G72="",M72=""),"",G72-M72)
A73: =IF(D73="","",COUNTA($D$71:D73)) | C73: 마케팅3팀 | K73: =IF(SUM(U73:AY73)=0,"",SUM(U73:AY73)) | L73: =IFERROR(INDEX(U$2:AY$2,MATCH(TRUE,U73:AY73<>"",0)),"") | M73: =IFERROR(LOOKUP(2,1/(U73:AY73<>""),U$2:AY$2),"") | N73: =IF(OR(G73="",M73=""),"",G73-M73)
A74: =IF(D74="","",COUNTA($D$71:D74)) | C74: 마케팅3팀 | K74: =IF(SUM(U74:AY74)=0,"",SUM(U74:AY74)) | L74: =IFERROR(INDEX(U$2:AY$2,MATCH(TRUE,U74:AY74<>"",0)),"") | M74: =IFERROR(LOOKUP(2,1/(U74:AY74<>""),U$2:AY$2),"") | N74: =IF(OR(G74="",M74=""),"",G74-M74)
A75: =IF(D75="","",COUNTA($D$71:D75)) | C75: 마케팅3팀 | K75: =IF(SUM(U75:AY75)=0,"",SUM(U75:AY75)) | L75: =IFERROR(INDEX(U$2:AY$2,MATCH(TRUE,U75:AY75<>"",0)),"") | M75: =IFERROR(LOOKUP(2,1/(U75:AY75<>""),U$2:AY$2),"") | N75: =IF(OR(G75="",M75=""),"",G75-M75)
...

Sheet 2월
A1: 2월 업무 정보 (소재명 = 직군별 줄) | H1: 수량 (소재당 1번만) | K1: 집계 / 일정 (자동) | U1: 2월 간트 - 날짜 칸에 MD 직접 입력 (주말+공휴일 회색) 상단 4줄=일자별 직군 TO 상태
A2: No | B2: 게임 타이틀명 | C2: 고객팀 | D2: 소재명(업무명) | E2: 직군 | F2: 담당자 | G2: 최종완료일 (고객전달) | H2: 영상 수 | I2: 사이즈 베리 | J2: 다국어 베리 | K2: 합계 MD | L2: 시작일 (자동) | M2: 완료일 (자동) | N2: 여유 | O2: 상태 | P2: 비고 | U2: =DATE('마스터'!$J$3,2,1) | V2: =U2+1 | W2: =V2+1 | X2: =W2+1 | Y2: =X2+1 | Z2: =Y2+1 | AA2: =Z2+1 | AB2: =AA2+1 | AC2: =AB2+1 | ... AY2: =AX2+1
A3: 전체 TO (일자별 부하) | G3: 정원 | H3: =SUM('마스터'!$J$8:$J$10) | U3: =SUM(U$8:U$162) | V3: =SUM(V$8:V$162) | W3: =SUM(W$8:W$162) | X3: =SUM(X$8:X$162) | Y3: =SUM(Y$8:Y$162) | Z3: =SUM(Z$8:Z$162) | AA3: =SUM(AA$8:AA$162) | AB3: =SUM(AB$8:AB$162) | ... AY3: =SUM(AY$8:AY$162)
A4: 영상 TO | G4: 정원 | H4: ='마스터'!$J$8 | U4: =SUMIF($E$8:$E$162,"영상",U$8:U$162) | V4: =SUMIF($E$8:$E$162,"영상",V$8:V$162) | W4: =SUMIF($E$8:$E$162,"영상",W$8:W$162) | X4: =SUMIF($E$8:$E$162,"영상",X$8:X$162) | Y4: =SUMIF($E$8:$E$162,"영상",Y$8:Y$162) | Z4: =SUMIF($E$8:$E$162,"영상",Z$8:Z$162) | AA4: =SUMIF($E$8:$E$162,"영상",AA$8:AA$162) | AB4: =SUMIF($E$8:$E$162,"영상",AB$8:AB$162) | ... AY4: =SUMIF($E$8:$E$162,"영상",AY$8:AY$162)
A5: 이미지 TO | G5: 정원 | H5: ='마스터'!$J$9 | U5: =SUMIF($E$8:$E$162,"이미지",U$8:U$162) | V5: =SUMIF($E$8:$E$162,"이미지",V$8:V$162) | W5: =SUMIF($E$8:$E$162,"이미지",W$8:W$162) | X5: =SUMIF($E$8:$E$162,"이미지",X$8:X$162) | Y5: =SUMIF($E$8:$E$162,"이미지",Y$8:Y$162) | Z5: =SUMIF($E$8:$E$162,"이미지",Z$8:Z$162) | AA5: =SUMIF($E$8:$E$162,"이미지",AA$8:AA$162) | AB5: =SUMIF($E$8:$E$162,"이미지",AB$8:AB$162) | ... AY5: =SUMIF($E$8:$E$162,"이미지",AY$8:AY$162)
A6: 기획 TO | G6: 정원 | H6: ='마스터'!$J$10 | U6: =SUMIF($E$8:$E$162,"기획",U$8:U$162) | V6: =SUMIF($E$8:$E$162,"기획",V$8:V$162) | W6: =SUMIF($E$8:$E$162,"기획",W$8:W$162) | X6: =SUMIF($E$8:$E$162,"기획",X$8:X$162) | Y6: =SUMIF($E$8:$E$162,"기획",Y$8:Y$162) | Z6: =SUMIF($E$8:$E$162,"기획",Z$8:Z$162) | AA6: =SUMIF($E$8:$E$162,"기획",AA$8:AA$162) | AB6: =SUMIF($E$8:$E$162,"기획",AB$8:AB$162) | ... AY6: =SUMIF($E$8:$E$162,"기획",AY$8:AY$162)
A8: 마케팅1팀 (9~38행)
A9: =IF(D9="","",COUNTA($D$9:D9)) | C9: 마케팅1팀 | K9: =IF(SUM(U9:AY9)=0,"",SUM(U9:AY9)) | L9: =IFERROR(INDEX(U$2:AY$2,MATCH(TRUE,U9:AY9<>"",0)),"") | M9: =IFERROR(LOOKUP(2,1/(U9:AY9<>""),U$2:AY$2),"") | N9: =IF(OR(G9="",M9=""),"",G9-M9)
A10: =IF(D10="","",COUNTA($D$9:D10)) | C10: 마케팅1팀 | K10: =IF(SUM(U10:AY10)=0,"",SUM(U10:AY10)) | L10: =IFERROR(INDEX(U$2:AY$2,MATCH(TRUE,U10:AY10<>"",0)),"") | M10: =IFERROR(LOOKUP(2,1/(U10:AY10<>""),U$2:AY$2),"") | N10: =IF(OR(G10="",M10=""),"",G10-M10)
A11: =IF(D11="","",COUNTA($D$9:D11)) | C11: 마케팅1팀 | K11: =IF(SUM(U11:AY11)=0,"",SUM(U11:AY11)) | L11: =IFERROR(INDEX(U$2:AY$2,MATCH(TRUE,U11:AY11<>"",0)),"") | M11: =IFERROR(LOOKUP(2,1/(U11:AY11<>""),U$2:AY$2),"") | N11: =IF(OR(G11="",M11=""),"",G11-M11)
A12: =IF(D12="","",COUNTA($D$9:D12)) | C12: 마케팅1팀 | K12: =IF(SUM(U12:AY12)=0,"",SUM(U12:AY12)) | L12: =IFERROR(INDEX(U$2:AY$2,MATCH(TRUE,U12:AY12<>"",0)),"") | M12: =IFERROR(LOOKUP(2,1/(U12:AY12<>""),U$2:AY$2),"") | N12: =IF(OR(G12="",M12=""),"",G12-M12)
A13: =IF(D13="","",COUNTA($D$9:D13)) | C13: 마케팅1팀 | K13: =IF(SUM(U13:AY13)=0,"",SUM(U13:AY13)) | L13: =IFERROR(INDEX(U$2:AY$2,MATCH(TRUE,U13:AY13<>"",0)),"") | M13: =IFERROR(LOOKUP(2,1/(U13:AY13<>""),U$2:AY$2),"") | N13: =IF(OR(G13="",M13=""),"",G13-M13)
A14: =IF(D14="","",COUNTA($D$9:D14)) | C14: 마케팅1팀 | K14: =IF(SUM(U14:AY14)=0,"",SUM(U14:AY14)) | L14: =IFERROR(INDEX(U$2:AY$2,MATCH(TRUE,U14:AY14<>"",0)),"") | M14: =IFERROR(LOOKUP(2,1/(U14:AY14<>""),U$2:AY$2),"") | N14: =IF(OR(G14="",M14=""),"",G14-M14)
A15: =IF(D15="","",COUNTA($D$9:D15)) | C15: 마케팅1팀 | K15: =IF(SUM(U15:AY15)=0,"",SUM(U15:AY15)) | L15: =IFERROR(INDEX(U$2:AY$2,MATCH(TRUE,U15:AY15<>"",0)),"") | M15: =IFERROR(LOOKUP(2,1/(U15:AY15<>""),U$2:AY$2),"") | N15: =IF(OR(G15="",M15=""),"",G15-M15)
A16: =IF(D16="","",COUNTA($D$9:D16)) | C16: 마케팅1팀 | K16: =IF(SUM(U16:AY16)=0,"",SUM(U16:AY16)) | L16: =IFERROR(INDEX(U$2:AY$2,MATCH(TRUE,U16:AY16<>"",0)),"") | M16: =IFERROR(LOOKUP(2,1/(U16:AY16<>""),U$2:AY$2),"") | N16: =IF(OR(G16="",M16=""),"",G16-M16)
A17: =IF(D17="","",COUNTA($D$9:D17)) | C17: 마케팅1팀 | K17: =IF(SUM(U17:AY17)=0,"",SUM(U17:AY17)) | L17: =IFERROR(INDEX(U$2:AY$2,MATCH(TRUE,U17:AY17<>"",0)),"") | M17: =IFERROR(LOOKUP(2,1/(U17:AY17<>""),U$2:AY$2),"") | N17: =IF(OR(G17="",M17=""),"",G17-M17)
A18: =IF(D18="","",COUNTA($D$9:D18)) | C18: 마케팅1팀 | K18: =IF(SUM(U18:AY18)=0,"",SUM(U18:AY18)) | L18: =IFERROR(INDEX(U$2:AY$2,MATCH(TRUE,U18:AY18<>"",0)),"") | M18: =IFERROR(LOOKUP(2,1/(U18:AY18<>""),U$2:AY$2),"") | N18: =IF(OR(G18="",M18=""),"",G18-M18)
A19: =IF(D19="","",COUNTA($D$9:D19)) | C19: 마케팅1팀 | K19: =IF(SUM(U19:AY19)=0,"",SUM(U19:AY19)) | L19: =IFERROR(INDEX(U$2:AY$2,MATCH(TRUE,U19:AY19<>"",0)),"") | M19: =IFERROR(LOOKUP(2,1/(U19:AY19<>""),U$2:AY$2),"") | N19: =IF(OR(G19="",M19=""),"",G19-M19)
A20: =IF(D20="","",COUNTA($D$9:D20)) | C20: 마케팅1팀 | K20: =IF(SUM(U20:AY20)=0,"",SUM(U20:AY20)) | L20: =IFERROR(INDEX(U$2:AY$2,MATCH(TRUE,U20:AY20<>"",0)),"") | M20: =IFERROR(LOOKUP(2,1/(U20:AY20<>""),U$2:AY$2),"") | N20: =IF(OR(G20="",M20=""),"",G20-M20)
... A38: =IF(D38="","",COUNTA($D$9:D38)) | C38: 마케팅1팀 | K38: =IF(SUM(U38:AY38)=0,"",SUM(U38:AY38)) | L38: =IFERROR(INDEX(U$2:AY$2,MATCH(TRUE,U38:AY38<>"",0)),"") | M38: =IFERROR(LOOKUP(2,1/(U38:AY38<>""),U$2:AY$2),"") | N38: =IF(OR(G38="",M38=""),"",G38-M38)
A39: 마케팅2팀 (40~69행)
A40: =IF(D40="","",COUNTA($D$40:D40)) | C40: 마케팅2팀 | K40: =IF(SUM(U40:AY40)=0,"",SUM(U40:AY40)) | L40: =IFERROR(INDEX(U$2:AY$2,MATCH(TRUE,U40:AY40<>"",0)),"") | M40: =IFERROR(LOOKUP(2,1/(U40:AY40<>""),U$2:AY$2),"") | N40: =IF(OR(G40="",M40=""),"",G40-M40)
A41: =IF(D41="","",COUNTA($D$40:D41)) | C41: 마케팅2팀 | K41: =IF(SUM(U41:AY41)=0,"",SUM(U41:AY41)) | L41: =IFERROR(INDEX(U$2:AY$2,MATCH(TRUE,U41:AY41<>"",0)),"") | M41: =IFERROR(LOOKUP(2,1/(U41:AY41<>""),U$2:AY$2),"") | N41: =IF(OR(G41="",M41=""),"",G41-M41)
A42: =IF(D42="","",COUNTA($D$40:D42)) | C42: 마케팅2팀 | K42: =IF(SUM(U42:AY42)=0,"",SUM(U42:AY42)) | L42: =IFERROR(INDEX(U$2:AY$2,MATCH(TRUE,U42:AY42<>"",0)),"") | M42: =IFERROR(LOOKUP(2,1/(U42:AY42<>""),U$2:AY$2),"") | N42: =IF(OR(G42="",M42=""),"",G42-M42)
A43: =IF(D43="","",COUNTA($D$40:D43)) | C43: 마케팅2팀 | K43: =IF(SUM(U43:AY43)=0,"",SUM(U43:AY43)) | L43: =IFERROR(INDEX(U$2:AY$2,MATCH(TRUE,U43:AY43<>"",0)),"") | M43: =IFERROR(LOOKUP(2,1/(U43:AY43<>""),U$2:AY$2),"") | N43: =IF(OR(G43="",M43=""),"",G43-M43)
A44: =IF(D44="","",COUNTA($D$40:D44)) | C44: 마케팅2팀 | K44: =IF(SUM(U44:AY44)=0,"",SUM(U44:AY44)) | L44: =IFERROR(INDEX(U$2:AY$2,MATCH(TRUE,U44:AY44<>"",0)),"") | M44: =IFERROR(LOOKUP(2,1/(U44:AY44<>""),U$2:AY$2),"") | N44: =IF(OR(G44="",M44=""),"",G44-M44)
A45: =IF(D45="","",COUNTA($D$40:D45)) | C45: 마케팅2팀 | K45: =IF(SUM(U45:AY45)=0,"",SUM(U45:AY45)) | L45: =IFERROR(INDEX(U$2:AY$2,MATCH(TRUE,U45:AY45<>"",0)),"") | M45: =IFERROR(LOOKUP(2,1/(U45:AY45<>""),U$2:AY$2),"") | N45: =IF(OR(G45="",M45=""),"",G45-M45)
A46: =IF(D46="","",COUNTA($D$40:D46)) | C46: 마케팅2팀 | K46: =IF(SUM(U46:AY46)=0,"",SUM(U46:AY46)) | L46: =IFERROR(INDEX(U$2:AY$2,MATCH(TRUE,U46:AY46<>"",0)),"") | M46: =IFERROR(LOOKUP(2,1/(U46:AY46<>""),U$2:AY$2),"") | N46: =IF(OR(G46="",M46=""),"",G46-M46)
A47: =IF(D47="","",COUNTA($D$40:D47)) | C47: 마케팅2팀 | K47: =IF(SUM(U47:AY47)=0,"",SUM(U47:AY47)) | L47: =IFERROR(INDEX(U$2:AY$2,MATCH(TRUE,U47:AY47<>"",0)),"") | M47: =IFERROR(LOOKUP(2,1/(U47:AY47<>""),U$2:AY$2),"") | N47: =IF(OR(G47="",M47=""),"",G47-M47)
A48: =IF(D48="","",COUNTA($D$40:D48)) | C48: 마케팅2팀 | K48: =IF(SUM(U48:AY48)=0,"",SUM(U48:AY48)) | L48: =IFERROR(INDEX(U$2:AY$2,MATCH(TRUE,U48:AY48<>"",0)),"") | M48: =IFERROR(LOOKUP(2,1/(U48:AY48<>""),U$2:AY$2),"") | N48: =IF(OR(G48="",M48=""),"",G48-M48)
A49: =IF(D49="","",COUNTA($D$40:D49)) | C49: 마케팅2팀 | K49: =IF(SUM(U49:AY49)=0,"",SUM(U49:AY49)) | L49: =IFERROR(INDEX(U$2:AY$2,MATCH(TRUE,U49:AY49<>"",0)),"") | M49: =IFERROR(LOOKUP(2,1/(U49:AY49<>""),U$2:AY$2),"") | N49: =IF(OR(G49="",M49=""),"",G49-M49)
A50: =IF(D50="","",COUNTA($D$40:D50)) | C50: 마케팅2팀 | K50: =IF(SUM(U50:AY50)=0,"",SUM(U50:AY50)) | L50: =IFERROR(INDEX(U$2:AY$2,MATCH(TRUE,U50:AY50<>"",0)),"") | M50: =IFERROR(LOOKUP(2,1/(U50:AY50<>""),U$2:AY$2),"") | N50: =IF(OR(G50="",M50=""),"",G50-M50)
A51: =IF(D51="","",COUNTA($D$40:D51)) | C51: 마케팅2팀 | K51: =IF(SUM(U51:AY51)=0,"",SUM(U51:AY51)) | L51: =IFERROR(INDEX(U$2:AY$2,MATCH(TRUE,U51:AY51<>"",0)),"") | M51: =IFERROR(LOOKUP(2,1/(U51:AY51<>""),U$2:AY$2),"") | N51: =IF(OR(G51="",M51=""),"",G51-M51)
... A69: =IF(D69="","",COUNTA($D$40:D69)) | C69: 마케팅2팀 | K69: =IF(SUM(U69:AY69)=0,"",SUM(U69:AY69)) | L69: =IFERROR(INDEX(U$2:AY$2,MATCH(TRUE,U69:AY69<>"",0)),"") | M69: =IFERROR(LOOKUP(2,1/(U69:AY69<>""),U$2:AY$2),"") | N69: =IF(OR(G69="",M69=""),"",G69-M69)
A70: 마케팅3팀 (71~100행)
A71: =IF(D71="","",COUNTA($D$71:D71)) | C71: 마케팅3팀 | K71: =IF(SUM(U71:AY71)=0,"",SUM(U71:AY71)) | L71: =IFERROR(INDEX(U$2:AY$2,MATCH(TRUE,U71:AY71<>"",0)),"") | M71: =IFERROR(LOOKUP(2,1/(U71:AY71<>""),U$2:AY$2),"") | N71: =IF(OR(G71="",M71=""),"",G71-M71)
A72: =IF(D72="","",COUNTA($D$71:D72)) | C72: 마케팅3팀 | K72: =IF(SUM(U72:AY72)=0,"",SUM(U72:AY72)) | L72: =IFERROR(INDEX(U$2:AY$2,MATCH(TRUE,U72:AY72<>"",0)),"") | M72: =IFERROR(LOOKUP(2,1/(U72:AY72<>""),U$2:AY$2),"") | N72: =IF(OR(G72="",M72=""),"",G72-M72)
A73: =IF(D73="","",COUNTA($D$71:D73)) | C73: 마케팅3팀 | K73: =IF(SUM(U73:AY73)=0,"",SUM(U73:AY73)) | L73: =IFERROR(INDEX(U$2:AY$2,MATCH(TRUE,U73:AY73<>"",0)),"") | M73: =IFERROR(LOOKUP(2,1/(U73:AY73<>""),U$2:AY$2),"") | N73: =IF(OR(G73="",M73=""),"",G73-M73)
A74: =IF(D74="","",COUNTA($D$71:D74)) | C74: 마케팅3팀 | K74: =IF(SUM(U74:AY74)=0,"",SUM(U74:AY74)) | L74: =IFERROR(INDEX(U$2:AY$2,MATCH(TRUE,U74:AY74<>"",0)),"") | M74: =IFERROR(LOOKUP(2,1/(U74:AY74<>""),U$2:AY$2),"") | N74: =IF(OR(G74="",M74=""),"",G74-M74)
A75: =IF(D75="","",COUNTA($D$71:D75)) | C75: 마케팅3팀 | K75: =IF(SUM(U75:AY75)=0,"",SUM(U75:AY75)) | L75: =IFERROR(INDEX(U$2:AY$2,MATCH(TRUE,U75:AY75<>"",0)),"") | M75: =IFERROR(LOOKUP(2,1/(U75:AY75<>""),U$2:AY$2),"") | N75: =IF(OR(G75="",M75=""),"",G75-M75)
...

Sheet 3월
A1: 3월 업무 정보 (소재명 = 직군별 줄) | H1: 수량 (소재당 1번만) | K1: 집계 / 일정 (자동) | U1: 3월 간트 - 날짜 칸에 MD 직접 입력 (주말+공휴일 회색) 상단 4줄=일자별 직군 TO 상태
A2: No | B2: 게임 타이틀명 | C2: 고객팀 | D2: 소재명(업무명) | E2: 직군 | F2: 담당자 | G2: 최종완료일 (고객전달) | H2: 영상 수 | I2: 사이즈 베리 | J2: 다국어 베리 | K2: 합계 MD | L2: 시작일 (자동) | M2: 완료일 (자동) | N2: 여유 | O2: 상태 | P2: 비고 | U2: =DATE('마스터'!$J$3,3,1) | V2: =U2+1 | W2: =V2+1 | X2: =W2+1 | Y2: =X2+1 | Z2: =Y2+1 | AA2: =Z2+1 | AB2: =AA2+1 | AC2: =AB2+1 | ... AY2: =AX2+1
A3: 전체 TO (일자별 부하) | G3: 정원 | H3: =SUM('마스터'!$J$8:$J$10) | U3: =SUM(U$8:U$162) | V3: =SUM(V$8:V$162) | W3: =SUM(W$8:W$162) | X3: =SUM(X$8:X$162) | Y3: =SUM(Y$8:Y$162) | Z3: =SUM(Z$8:Z$162) | AA3: =SUM(AA$8:AA$162) | AB3: =SUM(AB$8:AB$162) | ... AY3: =SUM(AY$8:AY$162)
A4: 영상 TO | G4: 정원 | H4: ='마스터'!$J$8 | U4: =SUMIF($E$8:$E$162,"영상",U$8:U$162) | V4: =SUMIF($E$8:$E$162,"영상",V$8:V$162) | W4: =SUMIF($E$8:$E$162,"영상",W$8:W$162) | X4: =SUMIF($E$8:$E$162,"영상",X$8:X$162) | Y4: =SUMIF($E$8:$E$162,"영상",Y$8:Y$162) | Z4: =SUMIF($E$8:$E$162,"영상",Z$8:Z$162) | AA4: =SUMIF($E$8:$E$162,"영상",AA$8:AA$162) | AB4: =SUMIF($E$8:$E$162,"영상",AB$8:AB$162) | ... AY4: =SUMIF($E$8:$E$162,"영상",AY$8:AY$162)
A5: 이미지 TO | G5: 정원 | H5: ='마스터'!$J$9 | U5: =SUMIF($E$8:$E$162,"이미지",U$8:U$162) | V5: =SUMIF($E$8:$E$162,"이미지",V$8:V$162) | W5: =SUMIF($E$8:$E$162,"이미지",W$8:W$162) | X5: =SUMIF($E$8:$E$162,"이미지",X$8:X$162) | Y5: =SUMIF($E$8:$E$162,"이미지",Y$8:Y$162) | Z5: =SUMIF($E$8:$E$162,"이미지",Z$8:Z$162) | AA5: =SUMIF($E$8:$E$162,"이미지",AA$8:AA$162) | AB5: =SUMIF($E$8:$E$162,"이미지",AB$8:AB$162) | ... AY5: =SUMIF($E$8:$E$162,"이미지",AY$8:AY$162)
A6: 기획 TO | G6: 정원 | H6: ='마스터'!$J$10 | U6: =SUMIF($E$8:$E$162,"기획",U$8:U$162) | V6: =SUMIF($E$8:$E$162,"기획",V$8:V$162) | W6: =SUMIF($E$8:$E$162,"기획",W$8:W$162) | X6: =SUMIF($E$8:$E$162,"기획",X$8:X$162) | Y6: =SUMIF($E$8:$E$162,"기획",Y$8:Y$162) | Z6: =SUMIF($E$8:$E$162,"기획",Z$8:Z$162) | AA6: =SUMIF($E$8:$E$162,"기획",AA$8:AA$162) | AB6: =SUMIF($E$8:$E$162,"기획",AB$8:AB$162) | ... AY6: =SUMIF($E$8:$E$162,"기획",AY$8:AY$162)
A8: 마케팅1팀 (9~38행)
A9: =IF(D9="","",COUNTA($D$9:D9)) | C9: 마케팅1팀 | K9: =IF(SUM(U9:AY9)=0,"",SUM(U9:AY9)) | L9: =IFERROR(INDEX(U$2:AY$2,MATCH(TRUE,U9:AY9<>"",0)),"") | M9: =IFERROR(LOOKUP(2,1/(U9:AY9<>""),U$2:AY$2),"") | N9: =IF(OR(G9="",M9=""),"",G9-M9)
A10: =IF(D10="","",COUNTA($D$9:D10)) | C10: 마케팅1팀 | K10: =IF(SUM(U10:AY10)=0,"",SUM(U10:AY10)) | L10: =IFERROR(INDEX(U$2:AY$2,MATCH(TRUE,U10:AY10<>"",0)),"") | M10: =IFERROR(LOOKUP(2,1/(U10:AY10<>""),U$2:AY$2),"") | N10: =IF(OR(G10="",M10=""),"",G10-M10)
A11: =IF(D11="","",COUNTA($D$9:D11)) | C11: 마케팅1팀 | K11: =IF(SUM(U11:AY11)=0,"",SUM(U11:AY11)) | L11: =IFERROR(INDEX(U$2:AY$2,MATCH(TRUE,U11:AY11<>"",0)),"") | M11: =IFERROR(LOOKUP(2,1/(U11:AY11<>""),U$2:AY$2),"") | N11: =IF(OR(G11="",M11=""),"",G11-M11)
A12: =IF(D12="","",COUNTA($D$9:D12)) | C12: 마케팅1팀 | K12: =IF(SUM(U12:AY12)=0,"",SUM(U12:AY12)) | L12: =IFERROR(INDEX(U$2:AY$2,MATCH(TRUE,U12:AY12<>"",0)),"") | M12: =IFERROR(LOOKUP(2,1/(U12:AY12<>""),U$2:AY$2),"") | N12: =IF(OR(G12="",M12=""),"",G12-M12)
A13: =IF(D13="","",COUNTA($D$9:D13)) | C13: 마케팅1팀 | K13: =IF(SUM(U13:AY13)=0,"",SUM(U13:AY13)) | L13: =IFERROR(INDEX(U$2:AY$2,MATCH(TRUE,U13:AY13<>"",0)),"") | M13: =IFERROR(LOOKUP(2,1/(U13:AY13<>""),U$2:AY$2),"") | N13: =IF(OR(G13="",M13=""),"",G13-M13)
A14: =IF(D14="","",COUNTA($D$9:D14)) | C14: 마케팅1팀 | K14: =IF(SUM(U14:AY14)=0,"",SUM(U14:AY14)) | L14: =IFERROR(INDEX(U$2:AY$2,MATCH(TRUE,U14:AY14<>"",0)),"") | M14: =IFERROR(LOOKUP(2,1/(U14:AY14<>""),U$2:AY$2),"") | N14: =IF(OR(G14="",M14=""),"",G14-M14)
A15: =IF(D15="","",COUNTA($D$9:D15)) | C15: 마케팅1팀 | K15: =IF(SUM(U15:AY15)=0,"",SUM(U15:AY15)) | L15: =IFERROR(INDEX(U$2:AY$2,MATCH(TRUE,U15:AY15<>"",0)),"") | M15: =IFERROR(LOOKUP(2,1/(U15:AY15<>""),U$2:AY$2),"") | N15: =IF(OR(G15="",M15=""),"",G15-M15)
A16: =IF(D16="","",COUNTA($D$9:D16)) | C16: 마케팅1팀 | K16: =IF(SUM(U16:AY16)=0,"",SUM(U16:AY16)) | L16: =IFERROR(INDEX(U$2:AY$2,MATCH(TRUE,U16:AY16<>"",0)),"") | M16: =IFERROR(LOOKUP(2,1/(U16:AY16<>""),U$2:AY$2),"") | N16: =IF(OR(G16="",M16=""),"",G16-M16)
A17: =IF(D17="","",COUNTA($D$9:D17)) | C17: 마케팅1팀 | K17: =IF(SUM(U17:AY17)=0,"",SUM(U17:AY17)) | L17: =IFERROR(INDEX(U$2:AY$2,MATCH(TRUE,U17:AY17<>"",0)),"") | M17: =IFERROR(LOOKUP(2,1/(U17:AY17<>""),U$2:AY$2),"") | N17: =IF(OR(G17="",M17=""),"",G17-M17)
A18: =IF(D18="","",COUNTA($D$9:D18)) | C18: 마케팅1팀 | K18: =IF(SUM(U18:AY18)=0,"",SUM(U18:AY18)) | L18: =IFERROR(INDEX(U$2:AY$2,MATCH(TRUE,U18:AY18<>"",0)),"") | M18: =IFERROR(LOOKUP(2,1/(U18:AY18<>""),U$2:AY$2),"") | N18: =IF(OR(G18="",M18=""),"",G18-M18)
A19: =IF(D19="","",COUNTA($D$9:D19)) | C19: 마케팅1팀 | K19: =IF(SUM(U19:AY19)=0,"",SUM(U19:AY19)) | L19: =IFERROR(INDEX(U$2:AY$2,MATCH(TRUE,U19:AY19<>"",0)),"") | M19: =IFERROR(LOOKUP(2,1/(U19:AY19<>""),U$2:AY$2),"") | N19: =IF(OR(G19="",M19=""),"",G19-M19)
A20: =IF(D20="","",COUNTA($D$9:D20)) | C20: 마케팅1팀 | K20: =IF(SUM(U20:AY20)=0,"",SUM(U20:AY20)) | L20: =IFERROR(INDEX(U$2:AY$2,MATCH(TRUE,U20:AY20<>"",0)),"") | M20: =IFERROR(LOOKUP(2,1/(U20:AY20<>""),U$2:AY$2),"") | N20: =IF(OR(G20="",M20=""),"",G20-M20)
... A38: =IF(D38="","",COUNTA($D$9:D38)) | C38: 마케팅1팀 | K38: =IF(SUM(U38:AY38)=0,"",SUM(U38:AY38)) | L38: =IFERROR(INDEX(U$2:AY$2,MATCH(TRUE,U38:AY38<>"",0)),"") | M38: =IFERROR(LOOKUP(2,1/(U38:AY38<>""),U$2:AY$2),"") | N38: =IF(OR(G38="",M38=""),"",G38-M38)
A39: 마케팅2팀 (40~69행)
A40: =IF(D40="","",COUNTA($D$40:D40)) | C40: 마케팅2팀 | K40: =IF(SUM(U40:AY40)=0,"",SUM(U40:AY40)) | L40: =IFERROR(INDEX(U$2:AY$2,MATCH(TRUE,U40:AY40<>"",0)),"") | M40: =IFERROR(LOOKUP(2,1/(U40:AY40<>""),U$2:AY$2),"") | N40: =IF(OR(G40="",M40=""),"",G40-M40)
A41: =IF(D41="","",COUNTA($D$40:D41)) | C41: 마케팅2팀 | K41: =IF(SUM(U41:AY41)=0,"",SUM(U41:AY41)) | L41: =IFERROR(INDEX(U$2:AY$2,MATCH(TRUE,U41:AY41<>"",0)),"") | M41: =IFERROR(LOOKUP(2,1/(U41:AY41<>""),U$2:AY$2),"") | N41: =IF(OR(G41="",M41=""),"",G41-M41)
A42: =IF(D42="","",COUNTA($D$40:D42)) | C42: 마케팅2팀 | K42: =IF(SUM(U42:AY42)=0,"",SUM(U42:AY42)) | L42: =IFERROR(INDEX(U$2:AY$2,MATCH(TRUE,U42:AY42<>"",0)),"") | M42: =IFERROR(LOOKUP(2,1/(U42:AY42<>""),U$2:AY$2),"") | N42: =IF(OR(G42="",M42=""),"",G42-M42)
A43: =IF(D43="","",COUNTA($D$40:D43)) | C43: 마케팅2팀 | K43: =IF(SUM(U43:AY43)=0,"",SUM(U43:AY43)) | L43: =IFERROR(INDEX(U$2:AY$2,MATCH(TRUE,U43:AY43<>"",0)),"") | M43: =IFERROR(LOOKUP(2,1/(U43:AY43<>""),U$2:AY$2),"") | N43: =IF(OR(G43="",M43=""),"",G43-M43)
A44: =IF(D44="","",COUNTA($D$40:D44)) | C44: 마케팅2팀 | K44: =IF(SUM(U44:AY44)=0,"",SUM(U44:AY44)) | L44: =IFERROR(INDEX(U$2:AY$2,MATCH(TRUE,U44:AY44<>"",0)),"") | M44: =IFERROR(LOOKUP(2,1/(U44:AY44<>""),U$2:AY$2),"") | N44: =IF(OR(G44="",M44=""),"",G44-M44)
A45: =IF(D45="","",COUNTA($D$40:D45)) | C45: 마케팅2팀 | K45: =IF(SUM(U45:AY45)=0,"",SUM(U45:AY45)) | L45: =IFERROR(INDEX(U$2:AY$2,MATCH(TRUE,U45:AY45<>"",0)),"") | M45: =IFERROR(LOOKUP(2,1/(U45:AY45<>""),U$2:AY$2),"") | N45: =IF(OR(G45="",M45=""),"",G45-M45)
A46: =IF(D46="","",COUNTA($D$40:D46)) | C46: 마케팅2팀 | K46: =IF(SUM(U46:AY46)=0,"",SUM(U46:AY46)) | L46: =IFERROR(INDEX(U$2:AY$2,MATCH(TRUE,U46:AY46<>"",0)),"") | M46: =IFERROR(LOOKUP(2,1/(U46:AY46<>""),U$2:AY$2),"") | N46: =IF(OR(G46="",M46=""),"",G46-M46)
A47: =IF(D47="","",COUNTA($D$40:D47)) | C47: 마케팅2팀 | K47: =IF(SUM(U47:AY47)=0,"",SUM(U47:AY47)) | L47: =IFERROR(INDEX(U$2:AY$2,MATCH(TRUE,U47:AY47<>"",0)),"") | M47: =IFERROR(LOOKUP(2,1/(U47:AY47<>""),U$2:AY$2),"") | N47: =IF(OR(G47="",M47=""),"",G47-M47)
A48: =IF(D48="","",COUNTA($D$40:D48)) | C48: 마케팅2팀 | K48: =IF(SUM(U48:AY48)=0,"",SUM(U48:AY48)) | L48: =IFERROR(INDEX(U$2:AY$2,MATCH(TRUE,U48:AY48<>"",0)),"") | M48: =IFERROR(LOOKUP(2,1/(U48:AY48<>""),U$2:AY$2),"") | N48: =IF(OR(G48="",M48=""),"",G48-M48)
A49: =IF(D49="","",COUNTA($D$40:D49)) | C49: 마케팅2팀 | K49: =IF(SUM(U49:AY49)=0,"",SUM(U49:AY49)) | L49: =IFERROR(INDEX(U$2:AY$2,MATCH(TRUE,U49:AY49<>"",0)),"") | M49: =IFERROR(LOOKUP(2,1/(U49:AY49<>""),U$2:AY$2),"") | N49: =IF(OR(G49="",M49=""),"",G49-M49)
A50: =IF(D50="","",COUNTA($D$40:D50)) | C50: 마케팅2팀 | K50: =IF(SUM(U50:AY50)=0,"",SUM(U50:AY50)) | L50: =IFERROR(INDEX(U$2:AY$2,MATCH(TRUE,U50:AY50<>"",0)),"") | M50: =IFERROR(LOOKUP(2,1/(U50:AY50<>""),U$2:AY$2),"") | N50: =IF(OR(G50="",M50=""),"",G50-M50)
A51: =IF(D51="","",COUNTA($D$40:D51)) | C51: 마케팅2팀 | K51: =IF(SUM(U51:AY51)=0,"",SUM(U51:AY51)) | L51: =IFERROR(INDEX(U$2:AY$2,MATCH(TRUE,U51:AY51<>"",0)),"") | M51: =IFERROR(LOOKUP(2,1/(U51:AY51<>""),U$2:AY$2),"") | N51: =IF(OR(G51="",M51=""),"",G51-M51)
... A69: =IF(D69="","",COUNTA($D$40:D69)) | C69: 마케팅2팀 | K69: =IF(SUM(U69:AY69)=0,"",SUM(U69:AY69)) | L69: =IFERROR(INDEX(U$2:AY$2,MATCH(TRUE,U69:AY69<>"",0)),"") | M69: =IFERROR(LOOKUP(2,1/(U69:AY69<>""),U$2:AY$2),"") | N69: =IF(OR(G69="",M69=""),"",G69-M69)
A70: 마케팅3팀 (71~100행)
A71: =IF(D71="","",COUNTA($D$71:D71)) | C71: 마케팅3팀 | K71: =IF(SUM(U71:AY71)=0,"",SUM(U71:AY71)) | L71: =IFERROR(INDEX(U$2:AY$2,MATCH(TRUE,U71:AY71<>"",0)),"") | M71: =IFERROR(LOOKUP(2,1/(U71:AY71<>""),U$2:AY$2),"") | N71: =IF(OR(G71="",M71=""),"",G71-M71)
A72: =IF(D72="","",COUNTA($D$71:D72)) | C72: 마케팅3팀 | K72: =IF(SUM(U72:AY72)=0,"",SUM(U72:AY72)) | L72: =IFERROR(INDEX(U$2:AY$2,MATCH(TRUE,U72:AY72<>"",0)),"") | M72: =IFERROR(LOOKUP(2,1/(U72:AY72<>""),U$2:AY$2),"") | N72: =IF(OR(G72="",M72=""),"",G72-M72)
A73: =IF(D73="","",COUNTA($D$71:D73)) | C73: 마케팅3팀 | K73: =IF(SUM(U73:AY73)=0,"",SUM(U73:AY73)) | L73: =IFERROR(INDEX(U$2:AY$2,MATCH(TRUE,U73:AY73<>"",0)),"") | M73: =IFERROR(LOOKUP(2,1/(U73:AY73<>""),U$2:AY$2),"") | N73: =IF(OR(G73="",M73=""),"",G73-M73)
A74: =IF(D74="","",COUNTA($D$71:D74)) | C74: 마케팅3팀 | K74: =IF(SUM(U74:AY74)=0,"",SUM(U74:AY74)) | L74: =IFERROR(INDEX(U$2:AY$2,MATCH(TRUE,U74:AY74<>"",0)),"") | M74: =IFERROR(LOOKUP(2,1/(U74:AY74<>""),U$2:AY$2),"") | N74: =IF(OR(G74="",M74=""),"",G74-M74)
A75: =IF(D75="","",COUNTA($D$71:D75)) | C75: 마케팅3팀 | K75: =IF(SUM(U75:AY75)=0,"",SUM(U75:AY75)) | L75: =IFERROR(INDEX(U$2:AY$2,MATCH(TRUE,U75:AY75<>"",0)),"") | M75: =IFERROR(LOOKUP(2,1/(U75:AY75<>""),U$2:AY$2),"") | N75: =IF(OR(G75="",M75=""),"",G75-M75)
...

Sheet 4월
A1: 4월 업무 정보 (소재명 = 직군별 줄) | H1: 수량 (소재당 1번만) | K1: 집계 / 일정 (자동) | U1: 4월 간트 - 날짜 칸에 MD 직접 입력 (주말+공휴일 회색) 상단 4줄=일자별 직군 TO 상태
A2: No | B2: 게임 타이틀명 | C2: 고객팀 | D2: 소재명(업무명) | E2: 직군 | F2: 담당자 | G2: 최종완료일 (고객전달) | H2: 영상 수 | I2: 사이즈 베리 | J2: 다국어 베리 | K2: 합계 MD | L2: 시작일 (자동) | M2: 완료일 (자동) | N2: 여유 | O2: 상태 | P2: 비고 | U2: =DATE('마스터'!$J$3,4,1) | V2: =U2+1 | W2: =V2+1 | X2: =W2+1 | Y2: =X2+1 | Z2: =Y2+1 | AA2: =Z2+1 | AB2: =AA2+1 | AC2: =AB2+1 | ... AY2: =AX2+1
A3: 전체 TO (일자별 부하) | G3: 정원 | H3: =SUM('마스터'!$J$8:$J$10) | U3: =SUM(U$8:U$162) | V3: =SUM(V$8:V$162) | W3: =SUM(W$8:W$162) | X3: =SUM(X$8:X$162) | Y3: =SUM(Y$8:Y$162) | Z3: =SUM(Z$8:Z$162) | AA3: =SUM(AA$8:AA$162) | AB3: =SUM(AB$8:AB$162) | ... AY3: =SUM(AY$8:AY$162)
A4: 영상 TO | G4: 정원 | H4: ='마스터'!$J$8 | U4: =SUMIF($E$8:$E$162,"영상",U$8:U$162) | V4: =SUMIF($E$8:$E$162,"영상",V$8:V$162) | W4: =SUMIF($E$8:$E$162,"영상",W$8:W$162) | X4: =SUMIF($E$8:$E$162,"영상",X$8:X$162) | Y4: =SUMIF($E$8:$E$162,"영상",Y$8:Y$162) | Z4: =SUMIF($E$8:$E$162,"영상",Z$8:Z$162) | AA4: =SUMIF($E$8:$E$162,"영상",AA$8:AA$162) | AB4: =SUMIF($E$8:$E$162,"영상",AB$8:AB$162) | ... AY4: =SUMIF($E$8:$E$162,"영상",AY$8:AY$162)
A5: 이미지 TO | G5: 정원 | H5: ='마스터'!$J$9 | U5: =SUMIF($E$8:$E$162,"이미지",U$8:U$162) | V5: =SUMIF($E$8:$E$162,"이미지",V$8:V$162) | W5: =SUMIF($E$8:$E$162,"이미지",W$8:W$162) | X5: =SUMIF($E$8:$E$162,"이미지",X$8:X$162) | Y5: =SUMIF($E$8:$E$162,"이미지",Y$8:Y$162) | Z5: =SUMIF($E$8:$E$162,"이미지",Z$8:Z$162) | AA5: =SUMIF($E$8:$E$162,"이미지",AA$8:AA$162) | AB5: =SUMIF($E$8:$E$162,"이미지",AB$8:AB$162) | ... AY5: =SUMIF($E$8:$E$162,"이미지",AY$8:AY$162)
A6: 기획 TO | G6: 정원 | H6: ='마스터'!$J$10 | U6: =SUMIF($E$8:$E$162,"기획",U$8:U$162) | V6: =SUMIF($E$8:$E$162,"기획",V$8:V$162) | W6: =SUMIF($E$8:$E$162,"기획",W$8:W$162) | X6: =SUMIF($E$8:$E$162,"기획",X$8:X$162) | Y6: =SUMIF($E$8:$E$162,"기획",Y$8:Y$162) | Z6: =SUMIF($E$8:$E$162,"기획",Z$8:Z$162) | AA6: =SUMIF($E$8:$E$162,"기획",AA$8:AA$162) | AB6: =SUMIF($E$8:$E$162,"기획",AB$8:AB$162) | ... AY6: =SUMIF($E$8:$E$162,"기획",AY$8:AY$162)
A8: 마케팅1팀 (9~38행)
A9: =IF(D9="","",COUNTA($D$9:D9)) | C9: 마케팅1팀 | K9: =IF(SUM(U9:AY9)=0,"",SUM(U9:AY9)) | L9: =IFERROR(INDEX(U$2:AY$2,MATCH(TRUE,U9:AY9<>"",0)),"") | M9: =IFERROR(LOOKUP(2,1/(U9:AY9<>""),U$2:AY$2),"") | N9: =IF(OR(G9="",M9=""),"",G9-M9)
