Workbook

Sheet 사용법
B2: AI 파이프라인 · 리소스 & 스케줄 통합 관리 시트
B3: v1.0 — 리소스 분배(실별 MD·견적) × 간트 스케줄 × 자동 마감예측을 한 장에서 관리
B5: ① 이 시트가 푸는 문제
B6: 기존 예시의 한계 | C6: 동희 실장 리소스 시트: 실별 MD 분배·견적은 강하나 '언제 끝나나(간트)'가 없음. 밀리·라인 시트: 간트는 있으나 실별 분배·견적이 약함. → 두 장으로 갈라짐.
B7: 이 시트의 해법 | C7: 업무(소재) 1행에 [실별 MD] + [시작일·소요일]만 넣으면 → 예상완료일·D-day·실별 부하·월 MM·가동률·견적분배가 전부 자동 계산.
B9: ② 시트 구성
B10: ⚙️ 기준정보 | C10: 시간→MD 환산표 · 실(팀) 마스터(TO·단가) · 소재유형별 표준공수 · 비나 시나리오 정의 · 간트 시작일. 노란 칸만 조직 실측치로 교체.
B11: 📊 통합관리 | C11: 메인. 업무 1건 = 1행. 노란 입력칸(실별 MD·시작일·희망마감·상태)만 채우면 나머지는 수식. 오른쪽에 데일리 간트, 하단에 실별 일일 부하 히트맵.
B12: 📈 대시보드 | C12: 실별 월 MD·MM·비중·가동률·견적분배 자동 집계. 상단 '비나 운영 시나리오' 드롭다운(방안1~4)을 바꾸면 견적 귀속 로직이 실시간 변경.
B14: ③ 입력 규칙 (노란 칸만 편집)
B15: 실별 MD 입력 | C15: 각 소재 행에서 투입되는 실 칸에 MD를 입력. MD 환산: 1일=8시간=1.0MD, 1시간=0.125MD (기준정보 환산표 참조).
B16: 시작일 / 상태 | C16: 시작일(날짜)과 상태(대기·진행·검수·완료) 선택 → 간트 막대가 상태 색으로 자동 표시(주말 제외).
B17: 소요일·예상완료 | C17: 자동. 소요일 = 병목 실(가장 MD 큰 실)의 MD를 올림 → 실들이 병렬 작업한다고 보고 최장 실이 마감을 결정. 예상완료 = 시작일 + 소요일(영업일).
B18: 여유(일) | C18: 희망마감 − 예상완료. 음수(빨강)=지연 위험, 0~1(노랑)=빠듯, 그 외(초록)=여유.
B20: ④ 병렬 진행 마감 관리 (핵심)
B21: 자동 마감예측 | C21: 각 업무의 예상완료일이 자동 계산 → 병렬로 여러 건이 떠 있어도 마감일이 바로 보임.
B22: 실별 부하 히트맵 | C22: 통합관리 하단. 날짜별로 각 실에 실제로 걸린 MD를 합산 → 해당 실의 일일 캐파(TO수) 초과 시 빨강. '이 실이 이 날 조율 필요'가 즉시 보임(동희 시트의 1TO 오버 개념).
B24: ⑤ 비나(VINA) 운영 4시나리오
B25: 방안 1 | C25: 기획+내부디자인+비나영상 제작 → 기획·디자인 공수는 각 실, 비나 영상제작 공수는 MAX실 매출로 귀속.
B26: 방안 2 | C26: 비나는 사이즈베리만 → 영상 사이즈베리는 디자인실 공수로 흡수(디자인 부하↑).
B27: 방안 3 | C27: 비나 이미지팀 TO 추가발주(전담 배치) → 비나 독립 라인 + 이미지TO 추가비용 별도 가산.
B28: 방안 4 | C28: 본사 프로세스: 비나 영상팀+이미지팀 통합 제작(이미지 TO 추가발주 없음).
B29: 전환 방법 | C29: 대시보드 상단 드롭다운에서 방안 번호만 바꾸면 견적 분배가 자동 재계산 → 어느 방안이 유리한지 즉시 비교.
B31: ⑥ 색상 범례
B32: 노랑 칸 | C32: 사용자 입력 칸 (여기만 편집).
B33: 파랑 글씨 | C33: 가정치/입력값. 검정 글씨 = 자동 수식. 회색 = 참고.
B34: 간트 막대 | C34: 진행=파랑 · 검수=주황 · 완료=초록 · 대기=회색. 주말=옅은 회색 음영.

Sheet 기준정보
A1: ⚙️ 기준정보 (BASIS)
A2: 시간→MD 환산 (1일 8h = 1.0MD) | G2: 운영 파라미터
A3: 시간 | B3: MD | G3: 월 가동일수 | H3: 20 | I3: ↩ 노란 칸은 조직 실측치로 교체하세요.
A4: 1 | B4: =A4/8 | G4: 1일 = MD | H4: 1
A5: 2 | B5: =A5/8 | G5: 간트 시작일 | H5: =DATE(2026,7,1)
A6: 3 | B6: =A6/8
A7: 4 | B7: =A7/8
A8: 5 | B8: =A8/8
A9: 6 | B9: =A9/8
A10: 7 | B10: =A10/8
A11: 8 | B11: =A11/8
A12: 9 | B12: =A12/8
A13: 10 | B13: =A13/8
A15: 실(팀) 마스터 — 기획 / 디자인 / 영상
A16: 실명 | B16: 대분류 | C16: TO수 | D16: 일단가(원) | E16: 월가용MD
A17: 기획실 | B17: 기획 | C17: 2 | D17: 450000 | E17: =C17*$H$3
A18: BXP실 | B18: 디자인 | C18: 3 | D18: 420000 | E18: =C18*$H$3
A19: GXD1실 | B19: 디자인 | C19: 2 | D19: 420000 | E19: =C19*$H$3
A20: GXD2실 | B20: 디자인 | C20: 2 | D20: 420000 | E20: =C20*$H$3
A21: MAX실 | B21: 영상 | C21: 3 | D21: 500000 | E21: =C21*$H$3
A22: VINA | B22: 영상 | C22: 2 | D22: 350000 | E22: =C22*$H$3
A24: 소재유형별 표준공수 (참고 · 소재에 따라 ±1h)
A25: 소재유형 | B25: 시안(MD) | C25: 사이즈베리 | D25: 다국어베리 | E25: 표준총MD
A26: 영상 30" | B26: 1.75 | C26: 0.75 | D26: 0.5 | E26: =B26+C26+D26
A27: 영상 15" | B27: 1.25 | C27: 0.5 | D27: 0.25 | E27: =B27+C27+D27
A28: 영상 6" | B28: 0.5 | C28: 0.25 | D28: 0 | E28: =B28+C28+D28
A29: 홈 아이콘 | B29: 0.13 | C29: 0 | D29: 0 | E29: =B29+C29+D29
A30: 퍼즐 앨범 | B30: 0.69 | C30: 0.56 | D30: 0.13 | E30: =B30+C30+D30
A31: 로그인 보너스 | B31: 0.44 | C31: 0.25 | D31: 0.13 | E31: =B31+C31+D31
A32: 스페셜 미션 | B32: 0.38 | C32: 0.31 | D32: 0.13 | E32: =B32+C32+D32
A33: OA CBU | B33: 0.38 | C33: 0 | D33: 0.13 | E33: =B33+C33+D33
A34: 세일즈 팝업 | B34: 0.31 | C34: 0 | D34: 0.13 | E34: =B34+C34+D34
A35: 원픽팩 | B35: 0.31 | C35: 0 | D35: 0.13 | E35: =B35+C35+D35
A36: 상점 배너 | B36: 0.19 | C36: 0 | D36: 0.13 | E36: =B36+C36+D36
A37: 기타/신규 | B37: 0.5 | C37: 0.25 | D37: 0.13 | E37: =B37+C37+D37
A39: 비나(VINA) 운영 시나리오
A40: 방안 | B40: 견적 귀속 규칙
A41: 방안 1 | B41: 기획+내부디자인+비나영상 제작 → 기획·디자인 공수는 각 실 / 비나 영상제작 공수는 MAX실 매출로 귀속
A42: 방안 2 | B42: 비나는 사이즈베리만 진행 → 영상 사이즈베리는 디자인실 공수로 흡수 (디자인 부하↑, 비나 몫 최소)
A43: 방안 3 | B43: 비나 이미지팀 TO 추가발주(전담) → 비나 독립 라인 + 이미지TO 추가비용 별도 가산
...

Sheet 통합관리
A1: 📊 통합관리 — 리소스 분배 · 스케줄 · 자동 마감예측 | H1: 기획 | I1: 디자인 | L1: 영상 | N1: 집계(MD) | R1: 스케줄 | Z1: 일정 간트 · 주말 음영 · 상태색
A2: No | B2: 타이틀 | C2: 소재명 / 업무 | D2: 소재유형 | E2: 표준MD (참고) | F2: 수량 | G2: 스펙 | H2: 기획실 | I2: BXP실 | J2: GXD1실 | K2: GXD2실 | L2: MAX실 | M2: VINA | N2: 소재 MD합 | O2: 기획 | P2: 디자인 | Q2: 영상 | R2: 담당자 | S2: 상태 | T2: 시작일 | U2: 소요일 (자동) | V2: 예상완료 (자동) | W2: 희망 마감 | X2: 여유 (일) | Z2: ='기준정보'!$H$5 | AA2: =Z2+1 | AB2: =AA2+1 | AC2: =AB2+1 | AD2: =AC2+1 | AE2: =AD2+1 | AF2: =AE2+1 | AG2: =AF2+1 | AH2: =AG2+1 | ... BA2: =AZ2+1
A3: =IF(COUNTA(C3:C3)=0,"",ROW()-2) | B3: 세나리버스 | C3: 여름 이벤트 KV 영상(30") | D3: 영상 30" | E3: =IFERROR(INDEX('기준정보'!$E$26:$E$37,MATCH(D3,'기준정보'!$A$26:$A$37,0))*IF(F3="",1,F3),"") | F3: 1 | G3: 30" | H3: 0.2 | I3: 0.4 | J3: 0 | K3: 0.1 | L3: 2.5 | M3: 0 | N3: =IF(SUM(H3:M3)=0,"",SUM(H3:M3)) | O3: =IF(H3="","",H3) | P3: =IF(SUM(I3:K3)=0,"",SUM(I3:K3)) | Q3: =IF(SUM(L3:M3)=0,"",SUM(L3:M3)) | R3: Neo | S3: 진행 | T3: =DATE(2026,7,1) | U3: =IF(SUM(H3:M3)=0,0,ROUNDUP(MAX(H3:M3)/'기준정보'!$H$4,0)) | V3: =IF(OR(T3="",U3=0),"",WORKDAY(T3-1,U3)) | W3: =DATE(2026,7,6) | X3: =IF(OR(W3="",V3=""),"",W3-V3)
A4: =IF(COUNTA(C4:C4)=0,"",ROW()-2) | B4: 칠대죄오리진 | C4: 고우더 리워드 라이브포스터(15") | D4: 영상 15" | E4: =IFERROR(INDEX('기준정보'!$E$26:$E$37,MATCH(D4,'기준정보'!$A$26:$A$37,0))*IF(F4="",1,F4),"") | F4: 1 | G4: 15" | H4: 0 | I4: 0.4 | J4: 0.3 | K4: 0 | L4: 1.5 | M4: 0.5 | N4: =IF(SUM(H4:M4)=0,"",SUM(H4:M4)) | O4: =IF(H4="","",H4) | P4: =IF(SUM(I4:K4)=0,"",SUM(I4:K4)) | Q4: =IF(SUM(L4:M4)=0,"",SUM(L4:M4)) | R4: Sopia | S4: 진행 | T4: =DATE(2026,7,2) | U4: =IF(SUM(H4:M4)=0,0,ROUNDUP(MAX(H4:M4)/'기준정보'!$H$4,0)) | V4: =IF(OR(T4="",U4=0),"",WORKDAY(T4-1,U4)) | W4: =DATE(2026,7,7) | X4: =IF(OR(W4="",V4=""),"",W4-V4)
A5: =IF(COUNTA(C5:C5)=0,"",ROW()-2) | B5: 세나리버스 | C5: 엔드카드 영상 사이즈베리(6") | D5: 영상 6" | E5: =IFERROR(INDEX('기준정보'!$E$26:$E$37,MATCH(D5,'기준정보'!$A$26:$A$37,0))*IF(F5="",1,F5),"") | F5: 1 | G5: 6" | H5: 0 | I5: 0.3 | J5: 0 | K5: 0 | L5: 0.5 | M5: 0.5 | N5: =IF(SUM(H5:M5)=0,"",SUM(H5:M5)) | O5: =IF(H5="","",H5) | P5: =IF(SUM(I5:K5)=0,"",SUM(I5:K5)) | Q5: =IF(SUM(L5:M5)=0,"",SUM(L5:M5)) | R5: Brush | S5: 대기 | T5: =DATE(2026,7,3) | U5: =IF(SUM(H5:M5)=0,0,ROUNDUP(MAX(H5:M5)/'기준정보'!$H$4,0)) | V5: =IF(OR(T5="",U5=0),"",WORKDAY(T5-1,U5)) | W5: =DATE(2026,7,4) | X5: =IF(OR(W5="",V5=""),"",W5-V5)
A6: =IF(COUNTA(C6:C6)=0,"",ROW()-2) | E6: =IFERROR(INDEX('기준정보'!$E$26:$E$37,MATCH(D6,'기준정보'!$A$26:$A$37,0))*IF(F6="",1,F6),"") | N6: =IF(SUM(H6:M6)=0,"",SUM(H6:M6)) | O6: =IF(H6="","",H6) | P6: =IF(SUM(I6:K6)=0,"",SUM(I6:K6)) | Q6: =IF(SUM(L6:M6)=0,"",SUM(L6:M6)) | U6: =IF(SUM(H6:M6)=0,0,ROUNDUP(MAX(H6:M6)/'기준정보'!$H$4,0)) | V6: =IF(OR(T6="",U6=0),"",WORKDAY(T6-1,U6)) | X6: =IF(OR(W6="",V6=""),"",W6-V6)
A7: =IF(COUNTA(C7:C7)=0,"",ROW()-2) | E7: =IFERROR(INDEX('기준정보'!$E$26:$E$37,MATCH(D7,'기준정보'!$A$26:$A$37,0))*IF(F7="",1,F7),"") | N7: =IF(SUM(H7:M7)=0,"",SUM(H7:M7)) | O7: =IF(H7="","",H7) | P7: =IF(SUM(I7:K7)=0,"",SUM(I7:K7)) | Q7: =IF(SUM(L7:M7)=0,"",SUM(L7:M7)) | U7: =IF(SUM(H7:M7)=0,0,ROUNDUP(MAX(H7:M7)/'기준정보'!$H$4,0)) | V7: =IF(OR(T7="",U7=0),"",WORKDAY(T7-1,U7)) | X7: =IF(OR(W7="",V7=""),"",W7-V7)
A8: =IF(COUNTA(C8:C8)=0,"",ROW()-2) | E8: =IFERROR(INDEX('기준정보'!$E$26:$E$37,MATCH(D8,'기준정보'!$A$26:$A$37,0))*IF(F8="",1,F8),"") | N8: =IF(SUM(H8:M8)=0,"",SUM(H8:M8)) | O8: =IF(H8="","",H8) | P8: =IF(SUM(I8:K8)=0,"",SUM(I8:K8)) | Q8: =IF(SUM(L8:M8)=0,"",SUM(L8:M8)) | U8: =IF(SUM(H8:M8)=0,0,ROUNDUP(MAX(H8:M8)/'기준정보'!$H$4,0)) | V8: =IF(OR(T8="",U8=0),"",WORKDAY(T8-1,U8)) | X8: =IF(OR(W8="",V8=""),"",W8-V8)
A9: =IF(COUNTA(C9:C9)=0,"",ROW()-2) | E9: =IFERROR(INDEX('기준정보'!$E$26:$E$37,MATCH(D9,'기준정보'!$A$26:$A$37,0))*IF(F9="",1,F9),"") | N9: =IF(SUM(H9:M9)=0,"",SUM(H9:M9)) | O9: =IF(H9="","",H9) | P9: =IF(SUM(I9:K9)=0,"",SUM(I9:K9)) | Q9: =IF(SUM(L9:M9)=0,"",SUM(L9:M9)) | U9: =IF(SUM(H9:M9)=0,0,ROUNDUP(MAX(H9:M9)/'기준정보'!$H$4,0)) | V9: =IF(OR(T9="",U9=0),"",WORKDAY(T9-1,U9)) | X9: =IF(OR(W9="",V9=""),"",W9-V9)
A10: =IF(COUNTA(C10:C10)=0,"",ROW()-2) | E10: =IFERROR(INDEX('기준정보'!$E$26:$E$37,MATCH(D10,'기준정보'!$A$26:$A$37,0))*IF(F10="",1,F10),"") | N10: =IF(SUM(H10:M10)=0,"",SUM(H10:M10)) | O10: =IF(H10="","",H10) | P10: =IF(SUM(I10:K10)=0,"",SUM(I10:K10)) | Q10: =IF(SUM(L10:M10)=0,"",SUM(L10:M10)) | U10: =IF(SUM(H10:M10)=0,0,ROUNDUP(MAX(H10:M10)/'기준정보'!$H$4,0)) | V10: =IF(OR(T10="",U10=0),"",WORKDAY(T10-1,U10)) | X10: =IF(OR(W10="",V10=""),"",W10-V10)
A11: =IF(COUNTA(C11:C11)=0,"",ROW()-2) | E11: =IFERROR(INDEX('기준정보'!$E$26:$E$37,MATCH(D11,'기준정보'!$A$26:$A$37,0))*IF(F11="",1,F11),"") | N11: =IF(SUM(H11:M11)=0,"",SUM(H11:M11)) | O11: =IF(H11="","",H11) | P11: =IF(SUM(I11:K11)=0,"",SUM(I11:K11)) | Q11: =IF(SUM(L11:M11)=0,"",SUM(L11:M11)) | U11: =IF(SUM(H11:M11)=0,0,ROUNDUP(MAX(H11:M11)/'기준정보'!$H$4,0)) | V11: =IF(OR(T11="",U11=0),"",WORKDAY(T11-1,U11)) | X11: =IF(OR(W11="",V11=""),"",W11-V11)
A12: =IF(COUNTA(C12:C12)=0,"",ROW()-2) | E12: =IFERROR(INDEX('기준정보'!$E$26:$E$37,MATCH(D12,'기준정보'!$A$26:$A$37,0))*IF(F12="",1,F12),"") | N12: =IF(SUM(H12:M12)=0,"",SUM(H12:M12)) | O12: =IF(H12="","",H12) | P12: =IF(SUM(I12:K12)=0,"",SUM(I12:K12)) | Q12: =IF(SUM(L12:M12)=0,"",SUM(L12:M12)) | U12: =IF(SUM(H12:M12)=0,0,ROUNDUP(MAX(H12:M12)/'기준정보'!$H$4,0)) | V12: =IF(OR(T12="",U12=0),"",WORKDAY(T12-1,U12)) | X12: =IF(OR(W12="",V12=""),"",W12-V12)
A13: =IF(COUNTA(C13:C13)=0,"",ROW()-2) | E13: =IFERROR(INDEX('기준정보'!$E$26:$E$37,MATCH(D13,'기준정보'!$A$26:$A$37,0))*IF(F13="",1,F13),"") | N13: =IF(SUM(H13:M13)=0,"",SUM(H13:M13)) | O13: =IF(H13="","",H13) | P13: =IF(SUM(I13:K13)=0,"",SUM(I13:K13)) | Q13: =IF(SUM(L13:M13)=0,"",SUM(L13:M13)) | U13: =IF(SUM(H13:M13)=0,0,ROUNDUP(MAX(H13:M13)/'기준정보'!$H$4,0)) | V13: =IF(OR(T13="",U13=0),"",WORKDAY(T13-1,U13)) | X13: =IF(OR(W13="",V13=""),"",W13-V13)
A14: =IF(COUNTA(C14:C14)=0,"",ROW()-2) | E14: =IFERROR(INDEX('기준정보'!$E$26:$E$37,MATCH(D14,'기준정보'!$A$26:$A$37,0))*IF(F14="",1,F14),"") | N14: =IF(SUM(H14:M14)=0,"",SUM(H14:M14)) | O14: =IF(H14="","",H14) | P14: =IF(SUM(I14:K14)=0,"",SUM(I14:K14)) | Q14: =IF(SUM(L14:M14)=0,"",SUM(L14:M14)) | U14: =IF(SUM(H14:M14)=0,0,ROUNDUP(MAX(H14:M14)/'기준정보'!$H$4,0)) | V14: =IF(OR(T14="",U14=0),"",WORKDAY(T14-1,U14)) | X14: =IF(OR(W14="",V14=""),"",W14-V14)
A15: =IF(COUNTA(C15:C15)=0,"",ROW()-2) | E15: =IFERROR(INDEX('기준정보'!$E$26:$E$37,MATCH(D15,'기준정보'!$A$26:$A$37,0))*IF(F15="",1,F15),"") | N15: =IF(SUM(H15:M15)=0,"",SUM(H15:M15)) | O15: =IF(H15="","",H15) | P15: =IF(SUM(I15:K15)=0,"",SUM(I15:K15)) | Q15: =IF(SUM(L15:M15)=0,"",SUM(L15:M15)) | U15: =IF(SUM(H15:M15)=0,0,ROUNDUP(MAX(H15:M15)/'기준정보'!$H$4,0)) | V15: =IF(OR(T15="",U15=0),"",WORKDAY(T15-1,U15)) | X15: =IF(OR(W15="",V15=""),"",W15-V15)
A16: =IF(COUNTA(C16:C16)=0,"",ROW()-2) | E16: =IFERROR(INDEX('기준정보'!$E$26:$E$37,MATCH(D16,'기준정보'!$A$26:$A$37,0))*IF(F16="",1,F16),"") | N16: =IF(SUM(H16:M16)=0,"",SUM(H16:M16)) | O16: =IF(H16="","",H16) | P16: =IF(SUM(I16:K16)=0,"",SUM(I16:K16)) | Q16: =IF(SUM(L16:M16)=0,"",SUM(L16:M16)) | U16: =IF(SUM(H16:M16)=0,0,ROUNDUP(MAX(H16:M16)/'기준정보'!$H$4,0)) | V16: =IF(OR(T16="",U16=0),"",WORKDAY(T16-1,U16)) | X16: =IF(OR(W16="",V16=""),"",W16-V16)
A17: =IF(COUNTA(C17:C17)=0,"",ROW()-2) | E17: =IFERROR(INDEX('기준정보'!$E$26:$E$37,MATCH(D17,'기준정보'!$A$26:$A$37,0))*IF(F17="",1,F17),"") | N17: =IF(SUM(H17:M17)=0,"",SUM(H17:M17)) | O17: =IF(H17="","",H17) | P17: =IF(SUM(I17:K17)=0,"",SUM(I17:K17)) | Q17: =IF(SUM(L17:M17)=0,"",SUM(L17:M17)) | U17: =IF(SUM(H17:M17)=0,0,ROUNDUP(MAX(H17:M17)/'기준정보'!$H$4,0)) | V17: =IF(OR(T17="",U17=0),"",WORKDAY(T17-1,U17)) | X17: =IF(OR(W17="",V17=""),"",W17-V17)
... A32: =IF(COUNTA(C32:C32)=0,"",ROW()-2) | E32: =IFERROR(INDEX('기준정보'!$E$26:$E$37,MATCH(D32,'기준정보'!$A$26:$A$37,0))*IF(F32="",1,F32),"") | N32: =IF(SUM(H32:M32)=0,"",SUM(H32:M32)) | O32: =IF(H32="","",H32) | P32: =IF(SUM(I32:K32)=0,"",SUM(I32:K32)) | Q32: =IF(SUM(L32:M32)=0,"",SUM(L32:M32)) | U32: =IF(SUM(H32:M32)=0,0,ROUNDUP(MAX(H32:M32)/'기준정보'!$H$4,0)) | V32: =IF(OR(T32="",U32=0),"",WORKDAY(T32-1,U32)) | X32: =IF(OR(W32="",V32=""),"",W32-V32)
A35: 🔥 실별 일일 부하 (MD) — 일일 캐파(TO) 초과 시 빨강 · 80%↑ 노랑
A36: 실 (대분류) | X36: 일캐파 | Z36: =Z2 | AA36: =AA2 | AB36: =AB2 | AC36: =AC2 | AD36: =AD2 | AE36: =AE2 | AF36: =AF2 | AG36: =AG2 | ... BA36: =BA2
A37: 기획실 | X37: ='기준정보'!$C$17 | Z37: =SUMPRODUCT(($T$3:$T$32<>"")*($T$3:$T$32<=Z$2)*($V$3:$V$32>=Z$2)*(WEEKDAY(Z$2,2)<6)*($H$3:$H$32)/($U$3:$U$32+($U$3:$U$32=0))) | AA37: =SUMPRODUCT(($T$3:$T$32<>"")*($T$3:$T$32<=AA$2)*($V$3:$V$32>=AA$2)*(WEEKDAY(AA$2,2)<6)*($H$3:$H$32)/($U$3:$U$32+($U$3:$U$32=0))) | AB37: =SUMPRODUCT(($T$3:$T$32<>"")*($T$3:$T$32<=AB$2)*($V$3:$V$32>=AB$2)*(WEEKDAY(AB$2,2)<6)*($H$3:$H$32)/($U$3:$U$32+($U$3:$U$32=0))) | AC37: =SUMPRODUCT(($T$3:$T$32<>"")*($T$3:$T$32<=AC$2)*($V$3:$V$32>=AC$2)*(WEEKDAY(AC$2,2)<6)*($H$3:$H$32)/($U$3:$U$32+($U$3:$U$32=0))) | AD37: =SUMPRODUCT(($T$3:$T$32<>"")*($T$3:$T$32<=AD$2)*($V$3:$V$32>=AD$2)*(WEEKDAY(AD$2,2)<6)*($H$3:$H$32)/($U$3:$U$32+($U$3:$U$32=0))) | AE37: =SUMPRODUCT(($T$3:$T$32<>"")*($T$3:$T$32<=AE$2)*($V$3:$V$32>=AE$2)*(WEEKDAY(AE$2,2)<6)*($H$3:$H$32)/($U$3:$U$32+($U$3:$U$32=0))) | AF37: =SUMPRODUCT(($T$3:$T$32<>"")*($T$3:$T$32<=AF$2)*($V$3:$V$32>=AF$2)*(WEEKDAY(AF$2,2)<6)*($H$3:$H$32)/($U$3:$U$32+($U$3:$U$32=0))) | AG37: =SUMPRODUCT(($T$3:$T$32<>"")*($T$3:$T$32<=AG$2)*($V$3:$V$32>=AG$2)*(WEEKDAY(AG$2,2)<6)*($H$3:$H$32)/($U$3:$U$32+($U$3:$U$32=0))) | ... BA37: =SUMPRODUCT(($T$3:$T$32<>"")*($T$3:$T$32<=BA$2)*($V$3:$V$32>=BA$2)*(WEEKDAY(BA$2,2)<6)*($H$3:$H$32)/($U$3:$U$32+($U$3:$U$32=0)))
A38: BXP실 | X38: ='기준정보'!$C$18 | Z38: =SUMPRODUCT(($T$3:$T$32<>"")*($T$3:$T$32<=Z$2)*($V$3:$V$32>=Z$2)*(WEEKDAY(Z$2,2)<6)*($I$3:$I$32)/($U$3:$U$32+($U$3:$U$32=0))) | AA38: =SUMPRODUCT(($T$3:$T$32<>"")*($T$3:$T$32<=AA$2)*($V$3:$V$32>=AA$2)*(WEEKDAY(AA$2,2)<6)*($I$3:$I$32)/($U$3:$U$32+($U$3:$U$32=0))) | AB38: =SUMPRODUCT(($T$3:$T$32<>"")*($T$3:$T$32<=AB$2)*($V$3:$V$32>=AB$2)*(WEEKDAY(AB$2,2)<6)*($I$3:$I$32)/($U$3:$U$32+($U$3:$U$32=0))) | AC38: =SUMPRODUCT(($T$3:$T$32<>"")*($T$3:$T$32<=AC$2)*($V$3:$V$32>=AC$2)*(WEEKDAY(AC$2,2)<6)*($I$3:$I$32)/($U$3:$U$32+($U$3:$U$32=0))) | AD38: =SUMPRODUCT(($T$3:$T$32<>"")*($T$3:$T$32<=AD$2)*($V$3:$V$32>=AD$2)*(WEEKDAY(AD$2,2)<6)*($I$3:$I$32)/($U$3:$U$32+($U$3:$U$32=0))) | AE38: =SUMPRODUCT(($T$3:$T$32<>"")*($T$3:$T$32<=AE$2)*($V$3:$V$32>=AE$2)*(WEEKDAY(AE$2,2)<6)*($I$3:$I$32)/($U$3:$U$32+($U$3:$U$32=0))) | AF38: =SUMPRODUCT(($T$3:$T$32<>"")*($T$3:$T$32<=AF$2)*($V$3:$V$32>=AF$2)*(WEEKDAY(AF$2,2)<6)*($I$3:$I$32)/($U$3:$U$32+($U$3:$U$32=0))) | AG38: =SUMPRODUCT(($T$3:$T$32<>"")*($T$3:$T$32<=AG$2)*($V$3:$V$32>=AG$2)*(WEEKDAY(AG$2,2)<6)*($I$3:$I$32)/($U$3:$U$32+($U$3:$U$32=0))) | ... BA38: =SUMPRODUCT(($T$3:$T$32<>"")*($T$3:$T$32<=BA$2)*($V$3:$V$32>=BA$2)*(WEEKDAY(BA$2,2)<6)*($I$3:$I$32)/($U$3:$U$32+($U$3:$U$32=0)))
A39: GXD1실 | X39: ='기준정보'!$C$19 | Z39: =SUMPRODUCT(($T$3:$T$32<>"")*($T$3:$T$32<=Z$2)*($V$3:$V$32>=Z$2)*(WEEKDAY(Z$2,2)<6)*($J$3:$J$32)/($U$3:$U$32+($U$3:$U$32=0))) | AA39: =SUMPRODUCT(($T$3:$T$32<>"")*($T$3:$T$32<=AA$2)*($V$3:$V$32>=AA$2)*(WEEKDAY(AA$2,2)<6)*($J$3:$J$32)/($U$3:$U$32+($U$3:$U$32=0))) | AB39: =SUMPRODUCT(($T$3:$T$32<>"")*($T$3:$T$32<=AB$2)*($V$3:$V$32>=AB$2)*(WEEKDAY(AB$2,2)<6)*($J$3:$J$32)/($U$3:$U$32+($U$3:$U$32=0))) | AC39: =SUMPRODUCT(($T$3:$T$32<>"")*($T$3:$T$32<=AC$2)*($V$3:$V$32>=AC$2)*(WEEKDAY(AC$2,2)<6)*($J$3:$J$32)/($U$3:$U$32+($U$3:$U$32=0))) | AD39: =SUMPRODUCT(($T$3:$T$32<>"")*($T$3:$T$32<=AD$2)*($V$3:$V$32>=AD$2)*(WEEKDAY(AD$2,2)<6)*($J$3:$J$32)/($U$3:$U$32+($U$3:$U$32=0))) | AE39: =SUMPRODUCT(($T$3:$T$32<>"")*($T$3:$T$32<=AE$2)*($V$3:$V$32>=AE$2)*(WEEKDAY(AE$2,2)<6)*($J$3:$J$32)/($U$3:$U$32+($U$3:$U$32=0))) | AF39: =SUMPRODUCT(($T$3:$T$32<>"")*($T$3:$T$32<=AF$2)*($V$3:$V$32>=AF$2)*(WEEKDAY(AF$2,2)<6)*($J$3:$J$32)/($U$3:$U$32+($U$3:$U$32=0))) | AG39: =SUMPRODUCT(($T$3:$T$32<>"")*($T$3:$T$32<=AG$2)*($V$3:$V$32>=AG$2)*(WEEKDAY(AG$2,2)<6)*($J$3:$J$32)/($U$3:$U$32+($U$3:$U$32=0))) | ... BA39: =SUMPRODUCT(($T$3:$T$32<>"")*($T$3:$T$32<=BA$2)*($V$3:$V$32>=BA$2)*(WEEKDAY(BA$2,2)<6)*($J$3:$J$32)/($U$3:$U$32+($U$3:$U$32=0)))
A40: GXD2실 | X40: ='기준정보'!$C$20 | Z40: =SUMPRODUCT(($T$3:$T$32<>"")*($T$3:$T$32<=Z$2)*($V$3:$V$32>=Z$2)*(WEEKDAY(Z$2,2)<6)*($K$3:$K$32)/($U$3:$U$32+($U$3:$U$32=0))) | AA40: =SUMPRODUCT(($T$3:$T$32<>"")*($T$3:$T$32<=AA$2)*($V$3:$V$32>=AA$2)*(WEEKDAY(AA$2,2)<6)*($K$3:$K$32)/($U$3:$U$32+($U$3:$U$32=0))) | AB40: =SUMPRODUCT(($T$3:$T$32<>"")*($T$3:$T$32<=AB$2)*($V$3:$V$32>=AB$2)*(WEEKDAY(AB$2,2)<6)*($K$3:$K$32)/($U$3:$U$32+($U$3:$U$32=0))) | AC40: =SUMPRODUCT(($T$3:$T$32<>"")*($T$3:$T$32<=AC$2)*($V$3:$V$32>=AC$2)*(WEEKDAY(AC$2,2)<6)*($K$3:$K$32)/($U$3:$U$32+($U$3:$U$32=0))) | AD40: =SUMPRODUCT(($T$3:$T$32<>"")*($T$3:$T$32<=AD$2)*($V$3:$V$32>=AD$2)*(WEEKDAY(AD$2,2)<6)*($K$3:$K$32)/($U$3:$U$32+($U$3:$U$32=0))) | AE40: =SUMPRODUCT(($T$3:$T$32<>"")*($T$3:$T$32<=AE$2)*($V$3:$V$32>=AE$2)*(WEEKDAY(AE$2,2)<6)*($K$3:$K$32)/($U$3:$U$32+($U$3:$U$32=0))) | AF40: =SUMPRODUCT(($T$3:$T$32<>"")*($T$3:$T$32<=AF$2)*($V$3:$V$32>=AF$2)*(WEEKDAY(AF$2,2)<6)*($K$3:$K$32)/($U$3:$U$32+($U$3:$U$32=0))) | AG40: =SUMPRODUCT(($T$3:$T$32<>"")*($T$3:$T$32<=AG$2)*($V$3:$V$32>=AG$2)*(WEEKDAY(AG$2,2)<6)*($K$3:$K$32)/($U$3:$U$32+($U$3:$U$32=0))) | ... BA40: =SUMPRODUCT(($T$3:$T$32<>"")*($T$3:$T$32<=BA$2)*($V$3:$V$32>=BA$2)*(WEEKDAY(BA$2,2)<6)*($K$3:$K$32)/($U$3:$U$32+($U$3:$U$32=0)))
A41: MAX실 | X41: ='기준정보'!$C$21 | Z41: =SUMPRODUCT(($T$3:$T$32<>"")*($T$3:$T$32<=Z$2)*($V$3:$V$32>=Z$2)*(WEEKDAY(Z$2,2)<6)*($L$3:$L$32)/($U$3:$U$32+($U$3:$U$32=0))) | AA41: =SUMPRODUCT(($T$3:$T$32<>"")*($T$3:$T$32<=AA$2)*($V$3:$V$32>=AA$2)*(WEEKDAY(AA$2,2)<6)*($L$3:$L$32)/($U$3:$U$32+($U$3:$U$32=0))) | AB41: =SUMPRODUCT(($T$3:$T$32<>"")*($T$3:$T$32<=AB$2)*($V$3:$V$32>=AB$2)*(WEEKDAY(AB$2,2)<6)*($L$3:$L$32)/($U$3:$U$32+($U$3:$U$32=0))) | AC41: =SUMPRODUCT(($T$3:$T$32<>"")*($T$3:$T$32<=AC$2)*($V$3:$V$32>=AC$2)*(WEEKDAY(AC$2,2)<6)*($L$3:$L$32)/($U$3:$U$32+($U$3:$U$32=0))) | AD41: =SUMPRODUCT(($T$3:$T$32<>"")*($T$3:$T$32<=AD$2)*($V$3:$V$32>=AD$2)*(WEEKDAY(AD$2,2)<6)*($L$3:$L$32)/($U$3:$U$32+($U$3:$U$32=0))) | AE41: =SUMPRODUCT(($T$3:$T$32<>"")*($T$3:$T$32<=AE$2)*($V$3:$V$32>=AE$2)*(WEEKDAY(AE$2,2)<6)*($L$3:$L$32)/($U$3:$U$32+($U$3:$U$32=0))) | AF41: =SUMPRODUCT(($T$3:$T$32<>"")*($T$3:$T$32<=AF$2)*($V$3:$V$32>=AF$2)*(WEEKDAY(AF$2,2)<6)*($L$3:$L$32)/($U$3:$U$32+($U$3:$U$32=0))) | AG41: =SUMPRODUCT(($T$3:$T$32<>"")*($T$3:$T$32<=AG$2)*($V$3:$V$32>=AG$2)*(WEEKDAY(AG$2,2)<6)*($L$3:$L$32)/($U$3:$U$32+($U$3:$U$32=0))) | ... BA41: =SUMPRODUCT(($T$3:$T$32<>"")*($T$3:$T$32<=BA$2)*($V$3:$V$32>=BA$2)*(WEEKDAY(BA$2,2)<6)*($L$3:$L$32)/($U$3:$U$32+($U$3:$U$32=0)))
A42: VINA | X42: ='기준정보'!$C$22 | Z42: =SUMPRODUCT(($T$3:$T$32<>"")*($T$3:$T$32<=Z$2)*($V$3:$V$32>=Z$2)*(WEEKDAY(Z$2,2)<6)*($M$3:$M$32)/($U$3:$U$32+($U$3:$U$32=0))) | AA42: =SUMPRODUCT(($T$3:$T$32<>"")*($T$3:$T$32<=AA$2)*($V$3:$V$32>=AA$2)*(WEEKDAY(AA$2,2)<6)*($M$3:$M$32)/($U$3:$U$32+($U$3:$U$32=0))) | AB42: =SUMPRODUCT(($T$3:$T$32<>"")*($T$3:$T$32<=AB$2)*($V$3:$V$32>=AB$2)*(WEEKDAY(AB$2,2)<6)*($M$3:$M$32)/($U$3:$U$32+($U$3:$U$32=0))) | AC42: =SUMPRODUCT(($T$3:$T$32<>"")*($T$3:$T$32<=AC$2)*($V$3:$V$32>=AC$2)*(WEEKDAY(AC$2,2)<6)*($M$3:$M$32)/($U$3:$U$32+($U$3:$U$32=0))) | AD42: =SUMPRODUCT(($T$3:$T$32<>"")*($T$3:$T$32<=AD$2)*($V$3:$V$32>=AD$2)*(WEEKDAY(AD$2,2)<6)*($M$3:$M$32)/($U$3:$U$32+($U$3:$U$32=0))) | AE42: =SUMPRODUCT(($T$3:$T$32<>"")*($T$3:$T$32<=AE$2)*($V$3:$V$32>=AE$2)*(WEEKDAY(AE$2,2)<6)*($M$3:$M$32)/($U$3:$U$32+($U$3:$U$32=0))) | AF42: =SUMPRODUCT(($T$3:$T$32<>"")*($T$3:$T$32<=AF$2)*($V$3:$V$32>=AF$2)*(WEEKDAY(AF$2,2)<6)*($M$3:$M$32)/($U$3:$U$32+($U$3:$U$32=0))) | AG42: =SUMPRODUCT(($T$3:$T$32<>"")*($T$3:$T$32<=AG$2)*($V$3:$V$32>=AG$2)*(WEEKDAY(AG$2,2)<6)*($M$3:$M$32)/($U$3:$U$32+($U$3:$U$32=0))) | ... BA42: =SUMPRODUCT(($T$3:$T$32<>"")*($T$3:$T$32<=BA$2)*($V$3:$V$32>=BA$2)*(WEEKDAY(BA$2,2)<6)*($M$3:$M$32)/($U$3:$U$32+($U$3:$U$32=0)))

Sheet 대시보드
B2: 📈 대시보드 — 실별 리소스 · 가동률 · 견적 분배
B4: 총 영상 견적(원) | D4: 92000000
B5: 비나 운영 시나리오 | D5: 1 | E5: =IF($D$5=1,"방안1: 기획·디자인 각 실 / 비나 영상제작 공수는 MAX실 매출로 귀속",IF($D$5=2,"방안2: 비나는 사이즈베리만 · 영상 사이즈베리는 디자인실 공수로 흡수",IF($D$5=3,"방안3: 비나 이미지팀 TO 추가발주(전담) · 이미지TO 추가비용 별도 가산","방안4: 본사 프로세스 — 비나 영상팀+이미지팀 통합 제작(이미지 TO 추가발주 없음)")))
B6: 비나 이미지TO 추가비용(원) | D6: 0
B9: 실 | C9: 대분류 | D9: MD | E9: MM | F9: 비중 | G9: TO | H9: 가동률 | I9: 귀속MD | J9: 견적 분배(원)
B10: 기획실 | C10: 기획 | D10: =SUM('통합관리'!H$3:H$32) | E10: =D10/'기준정보'!$H$3 | F10: =IFERROR(D10/$D$16,0) | G10: =IFERROR(E10/'기준정보'!$C$17,0) | H10: =D10 | I10: =IFERROR($D$4*H10/$H$16,0)
B11: BXP실 | C11: 디자인 | D11: =SUM('통합관리'!I$3:I$32) | E11: =D11/'기준정보'!$H$3 | F11: =IFERROR(D11/$D$16,0) | G11: =IFERROR(E11/'기준정보'!$C$18,0) | H11: =D11 | I11: =IFERROR($D$4*H11/$H$16,0)
B12: GXD1실 | C12: 디자인 | D12: =SUM('통합관리'!J$3:J$32) | E12: =D12/'기준정보'!$H$3 | F12: =IFERROR(D12/$D$16,0) | G12: =IFERROR(E12/'기준정보'!$C$19,0) | H12: =D12 | I12: =IFERROR($D$4*H12/$H$16,0)
B13: GXD2실 | C13: 디자인 | D13: =SUM('통합관리'!K$3:K$32) | E13: =D13/'기준정보'!$H$3 | F13: =IFERROR(D13/$D$16,0) | G13: =IFERROR(E13/'기준정보'!$C$20,0) | H13: =D13 | I13: =IFERROR($D$4*H13/$H$16,0)
B14: MAX실 | C14: 영상 | D14: =SUM('통합관리'!L$3:L$32) | E14: =D14/'기준정보'!$H$3 | F14: =IFERROR(D14/$D$16,0) | G14: =IFERROR(E14/'기준정보'!$C$21,0) | H14: =SUM('통합관리'!L$3:L$32)+IF($D$5=1,SUM('통합관리'!M$3:M$32),0) | I14: =IFERROR($D$4*H14/$H$16,0)
B15: VINA | C15: 영상 | D15: =SUM('통합관리'!M$3:M$32) | E15: =D15/'기준정보'!$H$3 | F15: =IFERROR(D15/$D$16,0) | G15: =IFERROR(E15/'기준정보'!$C$22,0) | H15: =IF($D$5=1,0,SUM('통합관리'!M$3:M$32)) | I15: =IFERROR($D$4*H15/$H$16,0)+IF($D$5=3,$D$6,0)
B16: 합계 | D16: =SUM(D10:D15) | E16: =SUM(E10:E15) | F16: =SUM(F10:F15) | H16: =SUM(H10:H15) | I16: =SUM(I10:I15)
B18: 대분류 소계
B19: 대분류 | C19: MM | D19: 비중
B20: 기획 | C20: =E10 | D20: =IFERROR((D10)/$D$16,0)
B21: 디자인 | C21: =E11+E12+E13 | D21: =IFERROR((D11+D12+D13)/$D$16,0)
B22: 영상 | C22: =E14+E15 | D22: =IFERROR((D14+D15)/$D$16,0)
B24: ※ 가동률 100%↑(빨강)=증원/외주 필요, 80%↑(노랑)=여유 부족. MM = MD ÷ 월가동일. 견적은 귀속MD 비중 배분(비나 시나리오 반영).
