Workbook

Sheet 사용법
B2: AI 파이프라인 통합 리소스/스케줄 관리 시트 v8
B3: 월별 탭 + 팀별 30행 색상 구간 + 주말/공휴일 워킹데이 반영 + 연간요약
B5: 색 표시
B6: 파랑 | C6: 해당 직군 정원(TO)의 80~100% 채워진 상태
B7: 보라 | C7: 정원(TO) 초과 - 조율 필요
B8: 회색 | C8: 주말(토/일) 또는 대한민국 공휴일 - 실제 워킹데이 아님
B10: 1. 월별 탭
B11: 탭 구조 | C11: 1월~12월 탭이 각각 독립된 통합관리. 그 달 업무만 그 탭에 입력.
B12: 행 = 한 업무명 | C12: 영상 파이프라인 기준. 영상/이미지/기획(SB)이 각각 담당+MD 칸으로 붙음. 붙는 직군만 기입, 나머지 비움.
B13: 요청일 위치 | C13: 소재명 바로 오른쪽. 완료일은 요일 없이 날짜만 표기(예: 8/14). 요청일·예상완료는 요일 포함 표기.
B14: 수량 | C14: 영상 수 / 사이즈베리 수 / 다국어베리 수 3개 분리.
B16: 2. 팀별 색상 구간
B17: 30행 구간 | C17: 각 월 탭 안에서 마케팅1~4팀 + 기타, 팀마다 30행씩 고정 구간으로 미리 배치. 구간 상단에 팀 이름 색상 배너.
B18: 고객팀 자동 | C18: 구간 안 행의 '고객팀' 칸은 그 팀 이름과 색으로 자동 고정 - 별도 입력/선택 불필요. 다른 팀 업무는 해당 팀 구간에 입력.
B19: 30행 초과 시 | C19: 해당 팀 업무가 30건을 넘으면 시트에서 행 삽입(우클릭 > 행 삽입)으로 구간을 늘리면 됩니다.
B21: 3. 워킹데이 (주말 + 대한민국 공휴일)
B22: 회색 처리 | C22: 간트와 상단 TO 상태 모두 토/일 + 마스터의 대한민국 공휴일 목록에 해당하는 날짜는 회색 처리.
B23: 일정 계산 | C23: 소요일 산정 시에도 공휴일을 제외하고 계산 - 예상완료일이 실제 근무일 기준으로 정확해짐.
B24: 공휴일 수정 | C24: 마스터 시트의 공휴일 목록(설날/추석 등 음력 기반 포함)은 참고용 - 정부 발표 기준으로 매년 확인 후 수정 필요.
B26: 4. 연간요약
B27: 월별/누적 | C27: 12개 월 탭에서 직접 집계. 매월 누적, 상반기(1-6)/하반기(7-12)/연간 합계, 월별 가동률.
B28: 팀/타이틀 | C28: 고객팀x유형 연간 건수, 게임타이틀별 연간 MD - 12개 탭 합산.

Sheet 마스터
A1: 마스터 / 기준정보
A2: 게임 타이틀 (25) | C2: 고객팀 | E2: 유형 | G2: 상태 | I2: 운영 파라미터
A3: 뱀피르 | C3: 마케팅1팀 | E3: 영상 | G3: 대기 | I3: 연도 | J3: 2026
A4: RF 글로벌 | C4: 마케팅2팀 | E4: 영상+이미지 | G4: 진행 | I4: 월 가동일수 | J4: 20
A5: SOL 인챈트 | C5: 마케팅3팀 | E5: 이미지 | G5: 검수 | I5: 1일=MD | J5: 1
A6: 스톤에이지펫월드 | C6: 마케팅4팀 | E6: 베리 | G6: 완료
A7: 칠대죄오리진 | C7: 기타 | E7: 기획 | I7: 직군 일 TO 정원
A8: 세나리버스 | E8: 기타 | I8: 영상 | J8: 6
A9: 몬길 | I9: 이미지 | J9: 8
A10: 왕겜(GOT) | I10: 기획 | J10: 3
A11: 몬스터길들이기
A12: 라이즈오브 | I12: 대한민국 공휴일 (참고 - 연도별 확인/수정 필요)
I13: 신정 | J13: =DATE(2026,1,1)
I14: 설날연휴 | J14: =DATE(2026,2,16)
I15: 설날 | J15: =DATE(2026,2,17)
I16: 설날연휴 | J16: =DATE(2026,2,18)
I17: 삼일절(대체) | J17: =DATE(2026,3,2)
I18: 어린이날 | J18: =DATE(2026,5,5)
I19: 부처님오신날(음력,확인필요) | J19: =DATE(2026,5,24)
I20: 현충일 | J20: =DATE(2026,6,6)
I21: 광복절 | J21: =DATE(2026,8,15)
I22: 추석연휴(음력,확인필요) | J22: =DATE(2026,9,24)
I23: 추석(음력,확인필요) | J23: =DATE(2026,9,25)
I24: 추석연휴(음력,확인필요) | J24: =DATE(2026,9,26)
I25: 개천절 | J25: =DATE(2026,10,3)
I26: 한글날 | J26: =DATE(2026,10,9)
I27: 성탄절 | J27: =DATE(2026,12,25)
A30: 비나(VINA) 운영 시나리오 (참고)
A31: 방안 1 | C31: 기획+내부디자인+비나영상 - 비나 영상공수는 영상실 매출 귀속
A32: 방안 2 | C32: 비나=사이즈베리만 - 영상 베리는 디자인 흡수
A33: 방안 3 | C33: 비나 이미지TO 추가발주+추가비용
A34: 방안 4 | C34: 본사 프로세스 통합(이미지TO 추가X)

Sheet 연간요약
B2: 연간요약 - 월별 / 상하반기 / 매월 누적
B3: 각 월 탭에서 직접 집계. 입력은 해당 월 탭에서.
B5: 월 | C5: 영상MD | D5: 이미지MD | E5: 기획MD | F5: 합계MD | G5: 누적MD | H5: 영상수 | I5: 사이즈베리 | J5: 다국어베리 | K5: 가동률
B6: 1월 | C6: =SUM('1월'!L8:L162) | D6: =SUM('1월'!N8:N162) | E6: =SUM('1월'!P8:P162) | F6: =SUM(C6:E6) | G6: =SUM($F$6:F6) | H6: =SUM('1월'!H8:H162) | I6: =SUM('1월'!I8:I162) | J6: =SUM('1월'!J8:J162) | K6: =IFERROR(F6/(SUM('마스터'!$J$8:$J$10)*'마스터'!$J$4),0)
B7: 2월 | C7: =SUM('2월'!L8:L162) | D7: =SUM('2월'!N8:N162) | E7: =SUM('2월'!P8:P162) | F7: =SUM(C7:E7) | G7: =SUM($F$6:F7) | H7: =SUM('2월'!H8:H162) | I7: =SUM('2월'!I8:I162) | J7: =SUM('2월'!J8:J162) | K7: =IFERROR(F7/(SUM('마스터'!$J$8:$J$10)*'마스터'!$J$4),0)
B8: 3월 | C8: =SUM('3월'!L8:L162) | D8: =SUM('3월'!N8:N162) | E8: =SUM('3월'!P8:P162) | F8: =SUM(C8:E8) | G8: =SUM($F$6:F8) | H8: =SUM('3월'!H8:H162) | I8: =SUM('3월'!I8:I162) | J8: =SUM('3월'!J8:J162) | K8: =IFERROR(F8/(SUM('마스터'!$J$8:$J$10)*'마스터'!$J$4),0)
B9: 4월 | C9: =SUM('4월'!L8:L162) | D9: =SUM('4월'!N8:N162) | E9: =SUM('4월'!P8:P162) | F9: =SUM(C9:E9) | G9: =SUM($F$6:F9) | H9: =SUM('4월'!H8:H162) | I9: =SUM('4월'!I8:I162) | J9: =SUM('4월'!J8:J162) | K9: =IFERROR(F9/(SUM('마스터'!$J$8:$J$10)*'마스터'!$J$4),0)
B10: 5월 | C10: =SUM('5월'!L8:L162) | D10: =SUM('5월'!N8:N162) | E10: =SUM('5월'!P8:P162) | F10: =SUM(C10:E10) | G10: =SUM($F$6:F10) | H10: =SUM('5월'!H8:H162) | I10: =SUM('5월'!I8:I162) | J10: =SUM('5월'!J8:J162) | K10: =IFERROR(F10/(SUM('마스터'!$J$8:$J$10)*'마스터'!$J$4),0)
B11: 6월 | C11: =SUM('6월'!L8:L162) | D11: =SUM('6월'!N8:N162) | E11: =SUM('6월'!P8:P162) | F11: =SUM(C11:E11) | G11: =SUM($F$6:F11) | H11: =SUM('6월'!H8:H162) | I11: =SUM('6월'!I8:I162) | J11: =SUM('6월'!J8:J162) | K11: =IFERROR(F11/(SUM('마스터'!$J$8:$J$10)*'마스터'!$J$4),0)
B12: 7월 | C12: =SUM('7월'!L8:L162) | D12: =SUM('7월'!N8:N162) | E12: =SUM('7월'!P8:P162) | F12: =SUM(C12:E12) | G12: =SUM($F$6:F12) | H12: =SUM('7월'!H8:H162) | I12: =SUM('7월'!I8:I162) | J12: =SUM('7월'!J8:J162) | K12: =IFERROR(F12/(SUM('마스터'!$J$8:$J$10)*'마스터'!$J$4),0)
B13: 8월 | C13: =SUM('8월'!L8:L162) | D13: =SUM('8월'!N8:N162) | E13: =SUM('8월'!P8:P162) | F13: =SUM(C13:E13) | G13: =SUM($F$6:F13) | H13: =SUM('8월'!H8:H162) | I13: =SUM('8월'!I8:I162) | J13: =SUM('8월'!J8:J162) | K13: =IFERROR(F13/(SUM('마스터'!$J$8:$J$10)*'마스터'!$J$4),0)
B14: 9월 | C14: =SUM('9월'!L8:L162) | D14: =SUM('9월'!N8:N162) | E14: =SUM('9월'!P8:P162) | F14: =SUM(C14:E14) | G14: =SUM($F$6:F14) | H14: =SUM('9월'!H8:H162) | I14: =SUM('9월'!I8:I162) | J14: =SUM('9월'!J8:J162) | K14: =IFERROR(F14/(SUM('마스터'!$J$8:$J$10)*'마스터'!$J$4),0)
B15: 10월 | C15: =SUM('10월'!L8:L162) | D15: =SUM('10월'!N8:N162) | E15: =SUM('10월'!P8:P162) | F15: =SUM(C15:E15) | G15: =SUM($F$6:F15) | H15: =SUM('10월'!H8:H162) | I15: =SUM('10월'!I8:I162) | J15: =SUM('10월'!J8:J162) | K15: =IFERROR(F15/(SUM('마스터'!$J$8:$J$10)*'마스터'!$J$4),0)
B16: 11월 | C16: =SUM('11월'!L8:L162) | D16: =SUM('11월'!N8:N162) | E16: =SUM('11월'!P8:P162) | F16: =SUM(C16:E16) | G16: =SUM($F$6:F16) | H16: =SUM('11월'!H8:H162) | I16: =SUM('11월'!I8:I162) | J16: =SUM('11월'!J8:J162) | K16: =IFERROR(F16/(SUM('마스터'!$J$8:$J$10)*'마스터'!$J$4),0)
B17: 12월 | C17: =SUM('12월'!L8:L162) | D17: =SUM('12월'!N8:N162) | E17: =SUM('12월'!P8:P162) | F17: =SUM(C17:E17) | G17: =SUM($F$6:F17) | H17: =SUM('12월'!H8:H162) | I17: =SUM('12월'!I8:I162) | J17: =SUM('12월'!J8:J162) | K17: =IFERROR(F17/(SUM('마스터'!$J$8:$J$10)*'마스터'!$J$4),0)
B18: 상반기(1-6) | C18: =SUM(C6:C11) | D18: =SUM(D6:D11) | E18: =SUM(E6:E11) | F18: =SUM(F6:F11) | H18: =SUM(H6:H11) | I18: =SUM(I6:I11) | J18: =SUM(J6:J11) | K18: =IFERROR(F18/(SUM('마스터'!$J$8:$J$10)*'마스터'!$J$4*(11-6+1)),0)
B19: 하반기(7-12) | C19: =SUM(C12:C17) | D19: =SUM(D12:D17) | E19: =SUM(E12:E17) | F19: =SUM(F12:F17) | H19: =SUM(H12:H17) | I19: =SUM(I12:I17) | J19: =SUM(J12:J17) | K19: =IFERROR(F19/(SUM('마스터'!$J$8:$J$10)*'마스터'!$J$4*(17-12+1)),0)
B20: 연간 합계 | C20: =SUM(C6:C17) | D20: =SUM(D6:D17) | E20: =SUM(E6:E17) | F20: =SUM(F6:F17) | H20: =SUM(H6:H17) | I20: =SUM(I6:I17) | J20: =SUM(J6:J17) | K20: =IFERROR(F20/(SUM('마스터'!$J$8:$J$10)*'마스터'!$J$4*(17-6+1)),0)
B23: 고객팀 x 유형 (연간 건수) | H23: 게임타이틀별 (연간)
B24: 팀\유형 | C24: 영상 | D24: 이미지 | E24: 기획 | H24: 타이틀 | I24: 건수 | J24: MD
B25: 마케팅1팀 | C25: =COUNTIFS('1월'!$C$8:$C$162,$B25,'1월'!$D$8:$D$162,C$24)+COUNTIFS('2월'!$C$8:$C$162,$B25,'2월'!$D$8:$D$162,C$24)+COUNTIFS('3월'!$C$8:$C$162,$B25,'3월'!$D$8:$D$162,C$24)+COUNTIFS('4월'!$C$8:$C$162,$B25,'4월'!$D$8:$D$162,C$24)+COUNTIFS('5월'!$C$8:$C$162,$B25,'5월'!$D$8:$D$162,C$24)+COUNTIFS('6월'!$C$8:$C$162,$B25,'6월'!$D$8:$D$162,C$24)+COUNTIFS('7월'!$C$8:$C$162,$B25,'7월'!$D$8:$D$162,C$24)+COUNTIFS('8월'!$C$8:$C$162,$B25,'8월'!$D$8:$D$162,C$24)+COUNTIFS('9월'!$C$8:$C$162,$B25,'9월'!$D$8:$D$162,C$24)+COUNTIFS('10월'!$C$8:$C$162,$B25,'10월'!$D$8:$D$162,C$24)+COUNTIFS('11월'!$C$8:$C$162,$B25,'11월'!$D$8:$D$162,C$24)+COUNTIFS('12월'!$C$8:$C$162,$B25,'12월'!$D$8:$D$162,C$24) | D25: =COUNTIFS('1월'!$C$8:$C$162,$B25,'1월'!$D$8:$D$162,D$24)+COUNTIFS('2월'!$C$8:$C$162,$B25,'2월'!$D$8:$D$162,D$24)+COUNTIFS('3월'!$C$8:$C$162,$B25,'3월'!$D$8:$D$162,D$24)+COUNTIFS('4월'!$C$8:$C$162,$B25,'4월'!$D$8:$D$162,D$24)+COUNTIFS('5월'!$C$8:$C$162,$B25,'5월'!$D$8:$D$162,D$24)+COUNTIFS('6월'!$C$8:$C$162,$B25,'6월'!$D$8:$D$162,D$24)+COUNTIFS('7월'!$C$8:$C$162,$B25,'7월'!$D$8:$D$162,D$24)+COUNTIFS('8월'!$C$8:$C$162,$B25,'8월'!$D$8:$D$162,D$24)+COUNTIFS('9월'!$C$8:$C$162,$B25,'9월'!$D$8:$D$162,D$24)+COUNTIFS('10월'!$C$8:$C$162,$B25,'10월'!$D$8:$D$162,D$24)+COUNTIFS('11월'!$C$8:$C$162,$B25,'11월'!$D$8:$D$162,D$24)+COUNTIFS('12월'!$C$8:$C$162,$B25,'12월'!$D$8:$D$162,D$24) | E25: =COUNTIFS('1월'!$C$8:$C$162,$B25,'1월'!$D$8:$D$162,E$24)+COUNTIFS('2월'!$C$8:$C$162,$B25,'2월'!$D$8:$D$162,E$24)+COUNTIFS('3월'!$C$8:$C$162,$B25,'3월'!$D$8:$D$162,E$24)+COUNTIFS('4월'!$C$8:$C$162,$B25,'4월'!$D$8:$D$162,E$24)+COUNTIFS('5월'!$C$8:$C$162,$B25,'5월'!$D$8:$D$162,E$24)+COUNTIFS('6월'!$C$8:$C$162,$B25,'6월'!$D$8:$D$162,E$24)+COUNTIFS('7월'!$C$8:$C$162,$B25,'7월'!$D$8:$D$162,E$24)+COUNTIFS('8월'!$C$8:$C$162,$B25,'8월'!$D$8:$D$162,E$24)+COUNTIFS('9월'!$C$8:$C$162,$B25,'9월'!$D$8:$D$162,E$24)+COUNTIFS('10월'!$C$8:$C$162,$B25,'10월'!$D$8:$D$162,E$24)+COUNTIFS('11월'!$C$8:$C$162,$B25,'11월'!$D$8:$D$162,E$24)+COUNTIFS('12월'!$C$8:$C$162,$B25,'12월'!$D$8:$D$162,E$24) | H25: 뱀피르 | I25: =COUNTIF('1월'!$B$8:$B$162,$H25)+COUNTIF('2월'!$B$8:$B$162,$H25)+COUNTIF('3월'!$B$8:$B$162,$H25)+COUNTIF('4월'!$B$8:$B$162,$H25)+COUNTIF('5월'!$B$8:$B$162,$H25)+COUNTIF('6월'!$B$8:$B$162,$H25)+COUNTIF('7월'!$B$8:$B$162,$H25)+COUNTIF('8월'!$B$8:$B$162,$H25)+COUNTIF('9월'!$B$8:$B$162,$H25)+COUNTIF('10월'!$B$8:$B$162,$H25)+COUNTIF('11월'!$B$8:$B$162,$H25)+COUNTIF('12월'!$B$8:$B$162,$H25) | J25: =SUMIF('1월'!$B$8:$B$162,$H25,'1월'!$Q$8:$Q$162)+SUMIF('2월'!$B$8:$B$162,$H25,'2월'!$Q$8:$Q$162)+SUMIF('3월'!$B$8:$B$162,$H25,'3월'!$Q$8:$Q$162)+SUMIF('4월'!$B$8:$B$162,$H25,'4월'!$Q$8:$Q$162)+SUMIF('5월'!$B$8:$B$162,$H25,'5월'!$Q$8:$Q$162)+SUMIF('6월'!$B$8:$B$162,$H25,'6월'!$Q$8:$Q$162)+SUMIF('7월'!$B$8:$B$162,$H25,'7월'!$Q$8:$Q$162)+SUMIF('8월'!$B$8:$B$162,$H25,'8월'!$Q$8:$Q$162)+SUMIF('9월'!$B$8:$B$162,$H25,'9월'!$Q$8:$Q$162)+SUMIF('10월'!$B$8:$B$162,$H25,'10월'!$Q$8:$Q$162)+SUMIF('11월'!$B$8:$B$162,$H25,'11월'!$Q$8:$Q$162)+SUMIF('12월'!$B$8:$B$162,$H25,'12월'!$Q$8:$Q$162)
B26: 마케팅2팀 | C26: =COUNTIFS('1월'!$C$8:$C$162,$B26,'1월'!$D$8:$D$162,C$24)+COUNTIFS('2월'!$C$8:$C$162,$B26,'2월'!$D$8:$D$162,C$24)+COUNTIFS('3월'!$C$8:$C$162,$B26,'3월'!$D$8:$D$162,C$24)+COUNTIFS('4월'!$C$8:$C$162,$B26,'4월'!$D$8:$D$162,C$24)+COUNTIFS('5월'!$C$8:$C$162,$B26,'5월'!$D$8:$D$162,C$24)+COUNTIFS('6월'!$C$8:$C$162,$B26,'6월'!$D$8:$D$162,C$24)+COUNTIFS('7월'!$C$8:$C$162,$B26,'7월'!$D$8:$D$162,C$24)+COUNTIFS('8월'!$C$8:$C$162,$B26,'8월'!$D$8:$D$162,C$24)+COUNTIFS('9월'!$C$8:$C$162,$B26,'9월'!$D$8:$D$162,C$24)+COUNTIFS('10월'!$C$8:$C$162,$B26,'10월'!$D$8:$D$162,C$24)+COUNTIFS('11월'!$C$8:$C$162,$B26,'11월'!$D$8:$D$162,C$24)+COUNTIFS('12월'!$C$8:$C$162,$B26,'12월'!$D$8:$D$162,C$24) | D26: =COUNTIFS('1월'!$C$8:$C$162,$B26,'1월'!$D$8:$D$162,D$24)+COUNTIFS('2월'!$C$8:$C$162,$B26,'2월'!$D$8:$D$162,D$24)+COUNTIFS('3월'!$C$8:$C$162,$B26,'3월'!$D$8:$D$162,D$24)+COUNTIFS('4월'!$C$8:$C$162,$B26,'4월'!$D$8:$D$162,D$24)+COUNTIFS('5월'!$C$8:$C$162,$B26,'5월'!$D$8:$D$162,D$24)+COUNTIFS('6월'!$C$8:$C$162,$B26,'6월'!$D$8:$D$162,D$24)+COUNTIFS('7월'!$C$8:$C$162,$B26,'7월'!$D$8:$D$162,D$24)+COUNTIFS('8월'!$C$8:$C$162,$B26,'8월'!$D$8:$D$162,D$24)+COUNTIFS('9월'!$C$8:$C$162,$B26,'9월'!$D$8:$D$162,D$24)+COUNTIFS('10월'!$C$8:$C$162,$B26,'10월'!$D$8:$D$162,D$24)+COUNTIFS('11월'!$C$8:$C$162,$B26,'11월'!$D$8:$D$162,D$24)+COUNTIFS('12월'!$C$8:$C$162,$B26,'12월'!$D$8:$D$162,D$24) | E26: =COUNTIFS('1월'!$C$8:$C$162,$B26,'1월'!$D$8:$D$162,E$24)+COUNTIFS('2월'!$C$8:$C$162,$B26,'2월'!$D$8:$D$162,E$24)+COUNTIFS('3월'!$C$8:$C$162,$B26,'3월'!$D$8:$D$162,E$24)+COUNTIFS('4월'!$C$8:$C$162,$B26,'4월'!$D$8:$D$162,E$24)+COUNTIFS('5월'!$C$8:$C$162,$B26,'5월'!$D$8:$D$162,E$24)+COUNTIFS('6월'!$C$8:$C$162,$B26,'6월'!$D$8:$D$162,E$24)+COUNTIFS('7월'!$C$8:$C$162,$B26,'7월'!$D$8:$D$162,E$24)+COUNTIFS('8월'!$C$8:$C$162,$B26,'8월'!$D$8:$D$162,E$24)+COUNTIFS('9월'!$C$8:$C$162,$B26,'9월'!$D$8:$D$162,E$24)+COUNTIFS('10월'!$C$8:$C$162,$B26,'10월'!$D$8:$D$162,E$24)+COUNTIFS('11월'!$C$8:$C$162,$B26,'11월'!$D$8:$D$162,E$24)+COUNTIFS('12월'!$C$8:$C$162,$B26,'12월'!$D$8:$D$162,E$24) | H26: RF 글로벌 | I26: =COUNTIF('1월'!$B$8:$B$162,$H26)+COUNTIF('2월'!$B$8:$B$162,$H26)+COUNTIF('3월'!$B$8:$B$162,$H26)+COUNTIF('4월'!$B$8:$B$162,$H26)+COUNTIF('5월'!$B$8:$B$162,$H26)+COUNTIF('6월'!$B$8:$B$162,$H26)+COUNTIF('7월'!$B$8:$B$162,$H26)+COUNTIF('8월'!$B$8:$B$162,$H26)+COUNTIF('9월'!$B$8:$B$162,$H26)+COUNTIF('10월'!$B$8:$B$162,$H26)+COUNTIF('11월'!$B$8:$B$162,$H26)+COUNTIF('12월'!$B$8:$B$162,$H26) | J26: =SUMIF('1월'!$B$8:$B$162,$H26,'1월'!$Q$8:$Q$162)+SUMIF('2월'!$B$8:$B$162,$H26,'2월'!$Q$8:$Q$162)+SUMIF('3월'!$B$8:$B$162,$H26,'3월'!$Q$8:$Q$162)+SUMIF('4월'!$B$8:$B$162,$H26,'4월'!$Q$8:$Q$162)+SUMIF('5월'!$B$8:$B$162,$H26,'5월'!$Q$8:$Q$162)+SUMIF('6월'!$B$8:$B$162,$H26,'6월'!$Q$8:$Q$162)+SUMIF('7월'!$B$8:$B$162,$H26,'7월'!$Q$8:$Q$162)+SUMIF('8월'!$B$8:$B$162,$H26,'8월'!$Q$8:$Q$162)+SUMIF('9월'!$B$8:$B$162,$H26,'9월'!$Q$8:$Q$162)+SUMIF('10월'!$B$8:$B$162,$H26,'10월'!$Q$8:$Q$162)+SUMIF('11월'!$B$8:$B$162,$H26,'11월'!$Q$8:$Q$162)+SUMIF('12월'!$B$8:$B$162,$H26,'12월'!$Q$8:$Q$162)
B27: 마케팅3팀 | C27: =COUNTIFS('1월'!$C$8:$C$162,$B27,'1월'!$D$8:$D$162,C$24)+COUNTIFS('2월'!$C$8:$C$162,$B27,'2월'!$D$8:$D$162,C$24)+COUNTIFS('3월'!$C$8:$C$162,$B27,'3월'!$D$8:$D$162,C$24)+COUNTIFS('4월'!$C$8:$C$162,$B27,'4월'!$D$8:$D$162,C$24)+COUNTIFS('5월'!$C$8:$C$162,$B27,'5월'!$D$8:$D$162,C$24)+COUNTIFS('6월'!$C$8:$C$162,$B27,'6월'!$D$8:$D$162,C$24)+COUNTIFS('7월'!$C$8:$C$162,$B27,'7월'!$D$8:$D$162,C$24)+COUNTIFS('8월'!$C$8:$C$162,$B27,'8월'!$D$8:$D$162,C$24)+COUNTIFS('9월'!$C$8:$C$162,$B27,'9월'!$D$8:$D$162,C$24)+COUNTIFS('10월'!$C$8:$C$162,$B27,'10월'!$D$8:$D$162,C$24)+COUNTIFS('11월'!$C$8:$C$162,$B27,'11월'!$D$8:$D$162,C$24)+COUNTIFS('12월'!$C$8:$C$162,$B27,'12월'!$D$8:$D$162,C$24) | D27: =COUNTIFS('1월'!$C$8:$C$162,$B27,'1월'!$D$8:$D$162,D$24)+COUNTIFS('2월'!$C$8:$C$162,$B27,'2월'!$D$8:$D$162,D$24)+COUNTIFS('3월'!$C$8:$C$162,$B27,'3월'!$D$8:$D$162,D$24)+COUNTIFS('4월'!$C$8:$C$162,$B27,'4월'!$D$8:$D$162,D$24)+COUNTIFS('5월'!$C$8:$C$162,$B27,'5월'!$D$8:$D$162,D$24)+COUNTIFS('6월'!$C$8:$C$162,$B27,'6월'!$D$8:$D$162,D$24)+COUNTIFS('7월'!$C$8:$C$162,$B27,'7월'!$D$8:$D$162,D$24)+COUNTIFS('8월'!$C$8:$C$162,$B27,'8월'!$D$8:$D$162,D$24)+COUNTIFS('9월'!$C$8:$C$162,$B27,'9월'!$D$8:$D$162,D$24)+COUNTIFS('10월'!$C$8:$C$162,$B27,'10월'!$D$8:$D$162,D$24)+COUNTIFS('11월'!$C$8:$C$162,$B27,'11월'!$D$8:$D$162,D$24)+COUNTIFS('12월'!$C$8:$C$162,$B27,'12월'!$D$8:$D$162,D$24) | E27: =COUNTIFS('1월'!$C$8:$C$162,$B27,'1월'!$D$8:$D$162,E$24)+COUNTIFS('2월'!$C$8:$C$162,$B27,'2월'!$D$8:$D$162,E$24)+COUNTIFS('3월'!$C$8:$C$162,$B27,'3월'!$D$8:$D$162,E$24)+COUNTIFS('4월'!$C$8:$C$162,$B27,'4월'!$D$8:$D$162,E$24)+COUNTIFS('5월'!$C$8:$C$162,$B27,'5월'!$D$8:$D$162,E$24)+COUNTIFS('6월'!$C$8:$C$162,$B27,'6월'!$D$8:$D$162,E$24)+COUNTIFS('7월'!$C$8:$C$162,$B27,'7월'!$D$8:$D$162,E$24)+COUNTIFS('8월'!$C$8:$C$162,$B27,'8월'!$D$8:$D$162,E$24)+COUNTIFS('9월'!$C$8:$C$162,$B27,'9월'!$D$8:$D$162,E$24)+COUNTIFS('10월'!$C$8:$C$162,$B27,'10월'!$D$8:$D$162,E$24)+COUNTIFS('11월'!$C$8:$C$162,$B27,'11월'!$D$8:$D$162,E$24)+COUNTIFS('12월'!$C$8:$C$162,$B27,'12월'!$D$8:$D$162,E$24) | H27: SOL 인챈트 | I27: =COUNTIF('1월'!$B$8:$B$162,$H27)+COUNTIF('2월'!$B$8:$B$162,$H27)+COUNTIF('3월'!$B$8:$B$162,$H27)+COUNTIF('4월'!$B$8:$B$162,$H27)+COUNTIF('5월'!$B$8:$B$162,$H27)+COUNTIF('6월'!$B$8:$B$162,$H27)+COUNTIF('7월'!$B$8:$B$162,$H27)+COUNTIF('8월'!$B$8:$B$162,$H27)+COUNTIF('9월'!$B$8:$B$162,$H27)+COUNTIF('10월'!$B$8:$B$162,$H27)+COUNTIF('11월'!$B$8:$B$162,$H27)+COUNTIF('12월'!$B$8:$B$162,$H27) | J27: =SUMIF('1월'!$B$8:$B$162,$H27,'1월'!$Q$8:$Q$162)+SUMIF('2월'!$B$8:$B$162,$H27,'2월'!$Q$8:$Q$162)+SUMIF('3월'!$B$8:$B$162,$H27,'3월'!$Q$8:$Q$162)+SUMIF('4월'!$B$8:$B$162,$H27,'4월'!$Q$8:$Q$162)+SUMIF('5월'!$B$8:$B$162,$H27,'5월'!$Q$8:$Q$162)+SUMIF('6월'!$B$8:$B$162,$H27,'6월'!$Q$8:$Q$162)+SUMIF('7월'!$B$8:$B$162,$H27,'7월'!$Q$8:$Q$162)+SUMIF('8월'!$B$8:$B$162,$H27,'8월'!$Q$8:$Q$162)+SUMIF('9월'!$B$8:$B$162,$H27,'9월'!$Q$8:$Q$162)+SUMIF('10월'!$B$8:$B$162,$H27,'10월'!$Q$8:$Q$162)+SUMIF('11월'!$B$8:$B$162,$H27,'11월'!$Q$8:$Q$162)+SUMIF('12월'!$B$8:$B$162,$H27,'12월'!$Q$8:$Q$162)
B28: 마케팅4팀 | C28: =COUNTIFS('1월'!$C$8:$C$162,$B28,'1월'!$D$8:$D$162,C$24)+COUNTIFS('2월'!$C$8:$C$162,$B28,'2월'!$D$8:$D$162,C$24)+COUNTIFS('3월'!$C$8:$C$162,$B28,'3월'!$D$8:$D$162,C$24)+COUNTIFS('4월'!$C$8:$C$162,$B28,'4월'!$D$8:$D$162,C$24)+COUNTIFS('5월'!$C$8:$C$162,$B28,'5월'!$D$8:$D$162,C$24)+COUNTIFS('6월'!$C$8:$C$162,$B28,'6월'!$D$8:$D$162,C$24)+COUNTIFS('7월'!$C$8:$C$162,$B28,'7월'!$D$8:$D$162,C$24)+COUNTIFS('8월'!$C$8:$C$162,$B28,'8월'!$D$8:$D$162,C$24)+COUNTIFS('9월'!$C$8:$C$162,$B28,'9월'!$D$8:$D$162,C$24)+COUNTIFS('10월'!$C$8:$C$162,$B28,'10월'!$D$8:$D$162,C$24)+COUNTIFS('11월'!$C$8:$C$162,$B28,'11월'!$D$8:$D$162,C$24)+COUNTIFS('12월'!$C$8:$C$162,$B28,'12월'!$D$8:$D$162,C$24) | D28: =COUNTIFS('1월'!$C$8:$C$162,$B28,'1월'!$D$8:$D$162,D$24)+COUNTIFS('2월'!$C$8:$C$162,$B28,'2월'!$D$8:$D$162,D$24)+COUNTIFS('3월'!$C$8:$C$162,$B28,'3월'!$D$8:$D$162,D$24)+COUNTIFS('4월'!$C$8:$C$162,$B28,'4월'!$D$8:$D$162,D$24)+COUNTIFS('5월'!$C$8:$C$162,$B28,'5월'!$D$8:$D$162,D$24)+COUNTIFS('6월'!$C$8:$C$162,$B28,'6월'!$D$8:$D$162,D$24)+COUNTIFS('7월'!$C$8:$C$162,$B28,'7월'!$D$8:$D$162,D$24)+COUNTIFS('8월'!$C$8:$C$162,$B28,'8월'!$D$8:$D$162,D$24)+COUNTIFS('9월'!$C$8:$C$162,$B28,'9월'!$D$8:$D$162,D$24)+COUNTIFS('10월'!$C$8:$C$162,$B28,'10월'!$D$8:$D$162,D$24)+COUNTIFS('11월'!$C$8:$C$162,$B28,'11월'!$D$8:$D$162,D$24)+COUNTIFS('12월'!$C$8:$C$162,$B28,'12월'!$D$8:$D$162,D$24) | E28: =COUNTIFS('1월'!$C$8:$C$162,$B28,'1월'!$D$8:$D$162,E$24)+COUNTIFS('2월'!$C$8:$C$162,$B28,'2월'!$D$8:$D$162,E$24)+COUNTIFS('3월'!$C$8:$C$162,$B28,'3월'!$D$8:$D$162,E$24)+COUNTIFS('4월'!$C$8:$C$162,$B28,'4월'!$D$8:$D$162,E$24)+COUNTIFS('5월'!$C$8:$C$162,$B28,'5월'!$D$8:$D$162,E$24)+COUNTIFS('6월'!$C$8:$C$162,$B28,'6월'!$D$8:$D$162,E$24)+COUNTIFS('7월'!$C$8:$C$162,$B28,'7월'!$D$8:$D$162,E$24)+COUNTIFS('8월'!$C$8:$C$162,$B28,'8월'!$D$8:$D$162,E$24)+COUNTIFS('9월'!$C$8:$C$162,$B28,'9월'!$D$8:$D$162,E$24)+COUNTIFS('10월'!$C$8:$C$162,$B28,'10월'!$D$8:$D$162,E$24)+COUNTIFS('11월'!$C$8:$C$162,$B28,'11월'!$D$8:$D$162,E$24)+COUNTIFS('12월'!$C$8:$C$162,$B28,'12월'!$D$8:$D$162,E$24) | H28: 스톤에이지펫월드 | I28: =COUNTIF('1월'!$B$8:$B$162,$H28)+COUNTIF('2월'!$B$8:$B$162,$H28)+COUNTIF('3월'!$B$8:$B$162,$H28)+COUNTIF('4월'!$B$8:$B$162,$H28)+COUNTIF('5월'!$B$8:$B$162,$H28)+COUNTIF('6월'!$B$8:$B$162,$H28)+COUNTIF('7월'!$B$8:$B$162,$H28)+COUNTIF('8월'!$B$8:$B$162,$H28)+COUNTIF('9월'!$B$8:$B$162,$H28)+COUNTIF('10월'!$B$8:$B$162,$H28)+COUNTIF('11월'!$B$8:$B$162,$H28)+COUNTIF('12월'!$B$8:$B$162,$H28) | J28: =SUMIF('1월'!$B$8:$B$162,$H28,'1월'!$Q$8:$Q$162)+SUMIF('2월'!$B$8:$B$162,$H28,'2월'!$Q$8:$Q$162)+SUMIF('3월'!$B$8:$B$162,$H28,'3월'!$Q$8:$Q$162)+SUMIF('4월'!$B$8:$B$162,$H28,'4월'!$Q$8:$Q$162)+SUMIF('5월'!$B$8:$B$162,$H28,'5월'!$Q$8:$Q$162)+SUMIF('6월'!$B$8:$B$162,$H28,'6월'!$Q$8:$Q$162)+SUMIF('7월'!$B$8:$B$162,$H28,'7월'!$Q$8:$Q$162)+SUMIF('8월'!$B$8:$B$162,$H28,'8월'!$Q$8:$Q$162)+SUMIF('9월'!$B$8:$B$162,$H28,'9월'!$Q$8:$Q$162)+SUMIF('10월'!$B$8:$B$162,$H28,'10월'!$Q$8:$Q$162)+SUMIF('11월'!$B$8:$B$162,$H28,'11월'!$Q$8:$Q$162)+SUMIF('12월'!$B$8:$B$162,$H28,'12월'!$Q$8:$Q$162)
B29: 기타 | C29: =COUNTIFS('1월'!$C$8:$C$162,$B29,'1월'!$D$8:$D$162,C$24)+COUNTIFS('2월'!$C$8:$C$162,$B29,'2월'!$D$8:$D$162,C$24)+COUNTIFS('3월'!$C$8:$C$162,$B29,'3월'!$D$8:$D$162,C$24)+COUNTIFS('4월'!$C$8:$C$162,$B29,'4월'!$D$8:$D$162,C$24)+COUNTIFS('5월'!$C$8:$C$162,$B29,'5월'!$D$8:$D$162,C$24)+COUNTIFS('6월'!$C$8:$C$162,$B29,'6월'!$D$8:$D$162,C$24)+COUNTIFS('7월'!$C$8:$C$162,$B29,'7월'!$D$8:$D$162,C$24)+COUNTIFS('8월'!$C$8:$C$162,$B29,'8월'!$D$8:$D$162,C$24)+COUNTIFS('9월'!$C$8:$C$162,$B29,'9월'!$D$8:$D$162,C$24)+COUNTIFS('10월'!$C$8:$C$162,$B29,'10월'!$D$8:$D$162,C$24)+COUNTIFS('11월'!$C$8:$C$162,$B29,'11월'!$D$8:$D$162,C$24)+COUNTIFS('12월'!$C$8:$C$162,$B29,'12월'!$D$8:$D$162,C$24) | D29: =COUNTIFS('1월'!$C$8:$C$162,$B29,'1월'!$D$8:$D$162,D$24)+COUNTIFS('2월'!$C$8:$C$162,$B29,'2월'!$D$8:$D$162,D$24)+COUNTIFS('3월'!$C$8:$C$162,$B29,'3월'!$D$8:$D$162,D$24)+COUNTIFS('4월'!$C$8:$C$162,$B29,'4월'!$D$8:$D$162,D$24)+COUNTIFS('5월'!$C$8:$C$162,$B29,'5월'!$D$8:$D$162,D$24)+COUNTIFS('6월'!$C$8:$C$162,$B29,'6월'!$D$8:$D$162,D$24)+COUNTIFS('7월'!$C$8:$C$162,$B29,'7월'!$D$8:$D$162,D$24)+COUNTIFS('8월'!$C$8:$C$162,$B29,'8월'!$D$8:$D$162,D$24)+COUNTIFS('9월'!$C$8:$C$162,$B29,'9월'!$D$8:$D$162,D$24)+COUNTIFS('10월'!$C$8:$C$162,$B29,'10월'!$D$8:$D$162,D$24)+COUNTIFS('11월'!$C$8:$C$162,$B29,'11월'!$D$8:$D$162,D$24)+COUNTIFS('12월'!$C$8:$C$162,$B29,'12월'!$D$8:$D$162,D$24) | E29: =COUNTIFS('1월'!$C$8:$C$162,$B29,'1월'!$D$8:$D$162,E$24)+COUNTIFS('2월'!$C$8:$C$162,$B29,'2월'!$D$8:$D$162,E$24)+COUNTIFS('3월'!$C$8:$C$162,$B29,'3월'!$D$8:$D$162,E$24)+COUNTIFS('4월'!$C$8:$C$162,$B29,'4월'!$D$8:$D$162,E$24)+COUNTIFS('5월'!$C$8:$C$162,$B29,'5월'!$D$8:$D$162,E$24)+COUNTIFS('6월'!$C$8:$C$162,$B29,'6월'!$D$8:$D$162,E$24)+COUNTIFS('7월'!$C$8:$C$162,$B29,'7월'!$D$8:$D$162,E$24)+COUNTIFS('8월'!$C$8:$C$162,$B29,'8월'!$D$8:$D$162,E$24)+COUNTIFS('9월'!$C$8:$C$162,$B29,'9월'!$D$8:$D$162,E$24)+COUNTIFS('10월'!$C$8:$C$162,$B29,'10월'!$D$8:$D$162,E$24)+COUNTIFS('11월'!$C$8:$C$162,$B29,'11월'!$D$8:$D$162,E$24)+COUNTIFS('12월'!$C$8:$C$162,$B29,'12월'!$D$8:$D$162,E$24) | H29: 칠대죄오리진 | I29: =COUNTIF('1월'!$B$8:$B$162,$H29)+COUNTIF('2월'!$B$8:$B$162,$H29)+COUNTIF('3월'!$B$8:$B$162,$H29)+COUNTIF('4월'!$B$8:$B$162,$H29)+COUNTIF('5월'!$B$8:$B$162,$H29)+COUNTIF('6월'!$B$8:$B$162,$H29)+COUNTIF('7월'!$B$8:$B$162,$H29)+COUNTIF('8월'!$B$8:$B$162,$H29)+COUNTIF('9월'!$B$8:$B$162,$H29)+COUNTIF('10월'!$B$8:$B$162,$H29)+COUNTIF('11월'!$B$8:$B$162,$H29)+COUNTIF('12월'!$B$8:$B$162,$H29) | J29: =SUMIF('1월'!$B$8:$B$162,$H29,'1월'!$Q$8:$Q$162)+SUMIF('2월'!$B$8:$B$162,$H29,'2월'!$Q$8:$Q$162)+SUMIF('3월'!$B$8:$B$162,$H29,'3월'!$Q$8:$Q$162)+SUMIF('4월'!$B$8:$B$162,$H29,'4월'!$Q$8:$Q$162)+SUMIF('5월'!$B$8:$B$162,$H29,'5월'!$Q$8:$Q$162)+SUMIF('6월'!$B$8:$B$162,$H29,'6월'!$Q$8:$Q$162)+SUMIF('7월'!$B$8:$B$162,$H29,'7월'!$Q$8:$Q$162)+SUMIF('8월'!$B$8:$B$162,$H29,'8월'!$Q$8:$Q$162)+SUMIF('9월'!$B$8:$B$162,$H29,'9월'!$Q$8:$Q$162)+SUMIF('10월'!$B$8:$B$162,$H29,'10월'!$Q$8:$Q$162)+SUMIF('11월'!$B$8:$B$162,$H29,'11월'!$Q$8:$Q$162)+SUMIF('12월'!$B$8:$B$162,$H29,'12월'!$Q$8:$Q$162)
H30: 세나리버스 | I30: =COUNTIF('1월'!$B$8:$B$162,$H30)+COUNTIF('2월'!$B$8:$B$162,$H30)+COUNTIF('3월'!$B$8:$B$162,$H30)+COUNTIF('4월'!$B$8:$B$162,$H30)+COUNTIF('5월'!$B$8:$B$162,$H30)+COUNTIF('6월'!$B$8:$B$162,$H30)+COUNTIF('7월'!$B$8:$B$162,$H30)+COUNTIF('8월'!$B$8:$B$162,$H30)+COUNTIF('9월'!$B$8:$B$162,$H30)+COUNTIF('10월'!$B$8:$B$162,$H30)+COUNTIF('11월'!$B$8:$B$162,$H30)+COUNTIF('12월'!$B$8:$B$162,$H30) | J30: =SUMIF('1월'!$B$8:$B$162,$H30,'1월'!$Q$8:$Q$162)+SUMIF('2월'!$B$8:$B$162,$H30,'2월'!$Q$8:$Q$162)+SUMIF('3월'!$B$8:$B$162,$H30,'3월'!$Q$8:$Q$162)+SUMIF('4월'!$B$8:$B$162,$H30,'4월'!$Q$8:$Q$162)+SUMIF('5월'!$B$8:$B$162,$H30,'5월'!$Q$8:$Q$162)+SUMIF('6월'!$B$8:$B$162,$H30,'6월'!$Q$8:$Q$162)+SUMIF('7월'!$B$8:$B$162,$H30,'7월'!$Q$8:$Q$162)+SUMIF('8월'!$B$8:$B$162,$H30,'8월'!$Q$8:$Q$162)+SUMIF('9월'!$B$8:$B$162,$H30,'9월'!$Q$8:$Q$162)+SUMIF('10월'!$B$8:$B$162,$H30,'10월'!$Q$8:$Q$162)+SUMIF('11월'!$B$8:$B$162,$H30,'11월'!$Q$8:$Q$162)+SUMIF('12월'!$B$8:$B$162,$H30,'12월'!$Q$8:$Q$162)
H31: 몬길 | I31: =COUNTIF('1월'!$B$8:$B$162,$H31)+COUNTIF('2월'!$B$8:$B$162,$H31)+COUNTIF('3월'!$B$8:$B$162,$H31)+COUNTIF('4월'!$B$8:$B$162,$H31)+COUNTIF('5월'!$B$8:$B$162,$H31)+COUNTIF('6월'!$B$8:$B$162,$H31)+COUNTIF('7월'!$B$8:$B$162,$H31)+COUNTIF('8월'!$B$8:$B$162,$H31)+COUNTIF('9월'!$B$8:$B$162,$H31)+COUNTIF('10월'!$B$8:$B$162,$H31)+COUNTIF('11월'!$B$8:$B$162,$H31)+COUNTIF('12월'!$B$8:$B$162,$H31) | J31: =SUMIF('1월'!$B$8:$B$162,$H31,'1월'!$Q$8:$Q$162)+SUMIF('2월'!$B$8:$B$162,$H31,'2월'!$Q$8:$Q$162)+SUMIF('3월'!$B$8:$B$162,$H31,'3월'!$Q$8:$Q$162)+SUMIF('4월'!$B$8:$B$162,$H31,'4월'!$Q$8:$Q$162)+SUMIF('5월'!$B$8:$B$162,$H31,'5월'!$Q$8:$Q$162)+SUMIF('6월'!$B$8:$B$162,$H31,'6월'!$Q$8:$Q$162)+SUMIF('7월'!$B$8:$B$162,$H31,'7월'!$Q$8:$Q$162)+SUMIF('8월'!$B$8:$B$162,$H31,'8월'!$Q$8:$Q$162)+SUMIF('9월'!$B$8:$B$162,$H31,'9월'!$Q$8:$Q$162)+SUMIF('10월'!$B$8:$B$162,$H31,'10월'!$Q$8:$Q$162)+SUMIF('11월'!$B$8:$B$162,$H31,'11월'!$Q$8:$Q$162)+SUMIF('12월'!$B$8:$B$162,$H31,'12월'!$Q$8:$Q$162)
H32: 왕겜(GOT) | I32: =COUNTIF('1월'!$B$8:$B$162,$H32)+COUNTIF('2월'!$B$8:$B$162,$H32)+COUNTIF('3월'!$B$8:$B$162,$H32)+COUNTIF('4월'!$B$8:$B$162,$H32)+COUNTIF('5월'!$B$8:$B$162,$H32)+COUNTIF('6월'!$B$8:$B$162,$H32)+COUNTIF('7월'!$B$8:$B$162,$H32)+COUNTIF('8월'!$B$8:$B$162,$H32)+COUNTIF('9월'!$B$8:$B$162,$H32)+COUNTIF('10월'!$B$8:$B$162,$H32)+COUNTIF('11월'!$B$8:$B$162,$H32)+COUNTIF('12월'!$B$8:$B$162,$H32) | J32: =SUMIF('1월'!$B$8:$B$162,$H32,'1월'!$Q$8:$Q$162)+SUMIF('2월'!$B$8:$B$162,$H32,'2월'!$Q$8:$Q$162)+SUMIF('3월'!$B$8:$B$162,$H32,'3월'!$Q$8:$Q$162)+SUMIF('4월'!$B$8:$B$162,$H32,'4월'!$Q$8:$Q$162)+SUMIF('5월'!$B$8:$B$162,$H32,'5월'!$Q$8:$Q$162)+SUMIF('6월'!$B$8:$B$162,$H32,'6월'!$Q$8:$Q$162)+SUMIF('7월'!$B$8:$B$162,$H32,'7월'!$Q$8:$Q$162)+SUMIF('8월'!$B$8:$B$162,$H32,'8월'!$Q$8:$Q$162)+SUMIF('9월'!$B$8:$B$162,$H32,'9월'!$Q$8:$Q$162)+SUMIF('10월'!$B$8:$B$162,$H32,'10월'!$Q$8:$Q$162)+SUMIF('11월'!$B$8:$B$162,$H32,'11월'!$Q$8:$Q$162)+SUMIF('12월'!$B$8:$B$162,$H32,'12월'!$Q$8:$Q$162)
H33: 몬스터길들이기 | I33: =COUNTIF('1월'!$B$8:$B$162,$H33)+COUNTIF('2월'!$B$8:$B$162,$H33)+COUNTIF('3월'!$B$8:$B$162,$H33)+COUNTIF('4월'!$B$8:$B$162,$H33)+COUNTIF('5월'!$B$8:$B$162,$H33)+COUNTIF('6월'!$B$8:$B$162,$H33)+COUNTIF('7월'!$B$8:$B$162,$H33)+COUNTIF('8월'!$B$8:$B$162,$H33)+COUNTIF('9월'!$B$8:$B$162,$H33)+COUNTIF('10월'!$B$8:$B$162,$H33)+COUNTIF('11월'!$B$8:$B$162,$H33)+COUNTIF('12월'!$B$8:$B$162,$H33) | J33: =SUMIF('1월'!$B$8:$B$162,$H33,'1월'!$Q$8:$Q$162)+SUMIF('2월'!$B$8:$B$162,$H33,'2월'!$Q$8:$Q$162)+SUMIF('3월'!$B$8:$B$162,$H33,'3월'!$Q$8:$Q$162)+SUMIF('4월'!$B$8:$B$162,$H33,'4월'!$Q$8:$Q$162)+SUMIF('5월'!$B$8:$B$162,$H33,'5월'!$Q$8:$Q$162)+SUMIF('6월'!$B$8:$B$162,$H33,'6월'!$Q$8:$Q$162)+SUMIF('7월'!$B$8:$B$162,$H33,'7월'!$Q$8:$Q$162)+SUMIF('8월'!$B$8:$B$162,$H33,'8월'!$Q$8:$Q$162)+SUMIF('9월'!$B$8:$B$162,$H33,'9월'!$Q$8:$Q$162)+SUMIF('10월'!$B$8:$B$162,$H33,'10월'!$Q$8:$Q$162)+SUMIF('11월'!$B$8:$B$162,$H33,'11월'!$Q$8:$Q$162)+SUMIF('12월'!$B$8:$B$162,$H33,'12월'!$Q$8:$Q$162)
H34: 라이즈오브 | I34: =COUNTIF('1월'!$B$8:$B$162,$H34)+COUNTIF('2월'!$B$8:$B$162,$H34)+COUNTIF('3월'!$B$8:$B$162,$H34)+COUNTIF('4월'!$B$8:$B$162,$H34)+COUNTIF('5월'!$B$8:$B$162,$H34)+COUNTIF('6월'!$B$8:$B$162,$H34)+COUNTIF('7월'!$B$8:$B$162,$H34)+COUNTIF('8월'!$B$8:$B$162,$H34)+COUNTIF('9월'!$B$8:$B$162,$H34)+COUNTIF('10월'!$B$8:$B$162,$H34)+COUNTIF('11월'!$B$8:$B$162,$H34)+COUNTIF('12월'!$B$8:$B$162,$H34) | J34: =SUMIF('1월'!$B$8:$B$162,$H34,'1월'!$Q$8:$Q$162)+SUMIF('2월'!$B$8:$B$162,$H34,'2월'!$Q$8:$Q$162)+SUMIF('3월'!$B$8:$B$162,$H34,'3월'!$Q$8:$Q$162)+SUMIF('4월'!$B$8:$B$162,$H34,'4월'!$Q$8:$Q$162)+SUMIF('5월'!$B$8:$B$162,$H34,'5월'!$Q$8:$Q$162)+SUMIF('6월'!$B$8:$B$162,$H34,'6월'!$Q$8:$Q$162)+SUMIF('7월'!$B$8:$B$162,$H34,'7월'!$Q$8:$Q$162)+SUMIF('8월'!$B$8:$B$162,$H34,'8월'!$Q$8:$Q$162)+SUMIF('9월'!$B$8:$B$162,$H34,'9월'!$Q$8:$Q$162)+SUMIF('10월'!$B$8:$B$162,$H34,'10월'!$Q$8:$Q$162)+SUMIF('11월'!$B$8:$B$162,$H34,'11월'!$Q$8:$Q$162)+SUMIF('12월'!$B$8:$B$162,$H34,'12월'!$Q$8:$Q$162)

Sheet 1월
A1: 1월 업무 정보 (소재명 / 요청일) | H1: 수량 | K1: 영상 (본체) | M1: 이미지 | O1: 기획(SB) | Q1: 집계 / 일정 / 자동 | Z1: 1월 간트 (MD 숫자 분산 / 주말+공휴일 회색) 상단 4줄=일자별 직군 TO 상태
A2: No | B2: 게임 타이틀명 | C2: 고객팀 | D2: 유형 | E2: 소재명(업무명) | F2: 요청일 | G2: 완료일 | H2: 영상 수 | I2: 사이즈 베리 | J2: 다국어 베리 | K2: 영상 담당 | L2: 영상 MD | M2: 이미지 담당 | N2: 이미지 MD | O2: 기획 담당 | P2: 기획 MD | Q2: 합계 MD | R2: 투입 직군 | S2: 주차 | T2: 상태 | U2: 소요일 | V2: 예상완료 | W2: 여유 | X2: 비고 | Z2: =DATE('마스터'!$J$3,1,1) | AA2: =Z2+1 | AB2: =AA2+1 | AC2: =AB2+1 | AD2: =AC2+1 | AE2: =AD2+1 | AF2: =AE2+1 | AG2: =AF2+1 | AH2: =AG2+1 | ... BD2: =BC2+1
A3: 전체 TO (일자별 부하) | G3: 정원 | H3: =SUM('마스터'!$J$8:$J$10) | Z3: =SUMPRODUCT(($F$8:$F$162<>"")*($F$8:$F$162<=Z$2)*($V$8:$V$162>=Z$2)*(WEEKDAY(Z$2,2)<6)*(COUNTIF('마스터'!$J$13:$J$27,Z$2)=0)*($L$8:$L$162+$N$8:$N$162+$P$8:$P$162)/($U$8:$U$162+($U$8:$U$162=0))) | AA3: =SUMPRODUCT(($F$8:$F$162<>"")*($F$8:$F$162<=AA$2)*($V$8:$V$162>=AA$2)*(WEEKDAY(AA$2,2)<6)*(COUNTIF('마스터'!$J$13:$J$27,AA$2)=0)*($L$8:$L$162+$N$8:$N$162+$P$8:$P$162)/($U$8:$U$162+($U$8:$U$162=0))) | AB3: =SUMPRODUCT(($F$8:$F$162<>"")*($F$8:$F$162<=AB$2)*($V$8:$V$162>=AB$2)*(WEEKDAY(AB$2,2)<6)*(COUNTIF('마스터'!$J$13:$J$27,AB$2)=0)*($L$8:$L$162+$N$8:$N$162+$P$8:$P$162)/($U$8:$U$162+($U$8:$U$162=0))) | AC3: =SUMPRODUCT(($F$8:$F$162<>"")*($F$8:$F$162<=AC$2)*($V$8:$V$162>=AC$2)*(WEEKDAY(AC$2,2)<6)*(COUNTIF('마스터'!$J$13:$J$27,AC$2)=0)*($L$8:$L$162+$N$8:$N$162+$P$8:$P$162)/($U$8:$U$162+($U$8:$U$162=0))) | AD3: =SUMPRODUCT(($F$8:$F$162<>"")*($F$8:$F$162<=AD$2)*($V$8:$V$162>=AD$2)*(WEEKDAY(AD$2,2)<6)*(COUNTIF('마스터'!$J$13:$J$27,AD$2)=0)*($L$8:$L$162+$N$8:$N$162+$P$8:$P$162)/($U$8:$U$162+($U$8:$U$162=0))) | AE3: =SUMPRODUCT(($F$8:$F$162<>"")*($F$8:$F$162<=AE$2)*($V$8:$V$162>=AE$2)*(WEEKDAY(AE$2,2)<6)*(COUNTIF('마스터'!$J$13:$J$27,AE$2)=0)*($L$8:$L$162+$N$8:$N$162+$P$8:$P$162)/($U$8:$U$162+($U$8:$U$162=0))) | AF3: =SUMPRODUCT(($F$8:$F$162<>"")*($F$8:$F$162<=AF$2)*($V$8:$V$162>=AF$2)*(WEEKDAY(AF$2,2)<6)*(COUNTIF('마스터'!$J$13:$J$27,AF$2)=0)*($L$8:$L$162+$N$8:$N$162+$P$8:$P$162)/($U$8:$U$162+($U$8:$U$162=0))) | AG3: =SUMPRODUCT(($F$8:$F$162<>"")*($F$8:$F$162<=AG$2)*($V$8:$V$162>=AG$2)*(WEEKDAY(AG$2,2)<6)*(COUNTIF('마스터'!$J$13:$J$27,AG$2)=0)*($L$8:$L$162+$N$8:$N$162+$P$8:$P$162)/($U$8:$U$162+($U$8:$U$162=0))) | ... BD3: =SUMPRODUCT(($F$8:$F$162<>"")*($F$8:$F$162<=BD$2)*($V$8:$V$162>=BD$2)*(WEEKDAY(BD$2,2)<6)*(COUNTIF('마스터'!$J$13:$J$27,BD$2)=0)*($L$8:$L$162+$N$8:$N$162+$P$8:$P$162)/($U$8:$U$162+($U$8:$U$162=0)))
A4: 영상 TO | G4: 정원 | H4: ='마스터'!$J$8 | Z4: =SUMPRODUCT(($F$8:$F$162<>"")*($F$8:$F$162<=Z$2)*($V$8:$V$162>=Z$2)*(WEEKDAY(Z$2,2)<6)*(COUNTIF('마스터'!$J$13:$J$27,Z$2)=0)*($L$8:$L$162)/($U$8:$U$162+($U$8:$U$162=0))) | AA4: =SUMPRODUCT(($F$8:$F$162<>"")*($F$8:$F$162<=AA$2)*($V$8:$V$162>=AA$2)*(WEEKDAY(AA$2,2)<6)*(COUNTIF('마스터'!$J$13:$J$27,AA$2)=0)*($L$8:$L$162)/($U$8:$U$162+($U$8:$U$162=0))) | AB4: =SUMPRODUCT(($F$8:$F$162<>"")*($F$8:$F$162<=AB$2)*($V$8:$V$162>=AB$2)*(WEEKDAY(AB$2,2)<6)*(COUNTIF('마스터'!$J$13:$J$27,AB$2)=0)*($L$8:$L$162)/($U$8:$U$162+($U$8:$U$162=0))) | AC4: =SUMPRODUCT(($F$8:$F$162<>"")*($F$8:$F$162<=AC$2)*($V$8:$V$162>=AC$2)*(WEEKDAY(AC$2,2)<6)*(COUNTIF('마스터'!$J$13:$J$27,AC$2)=0)*($L$8:$L$162)/($U$8:$U$162+($U$8:$U$162=0))) | AD4: =SUMPRODUCT(($F$8:$F$162<>"")*($F$8:$F$162<=AD$2)*($V$8:$V$162>=AD$2)*(WEEKDAY(AD$2,2)<6)*(COUNTIF('마스터'!$J$13:$J$27,AD$2)=0)*($L$8:$L$162)/($U$8:$U$162+($U$8:$U$162=0))) | AE4: =SUMPRODUCT(($F$8:$F$162<>"")*($F$8:$F$162<=AE$2)*($V$8:$V$162>=AE$2)*(WEEKDAY(AE$2,2)<6)*(COUNTIF('마스터'!$J$13:$J$27,AE$2)=0)*($L$8:$L$162)/($U$8:$U$162+($U$8:$U$162=0))) | AF4: =SUMPRODUCT(($F$8:$F$162<>"")*($F$8:$F$162<=AF$2)*($V$8:$V$162>=AF$2)*(WEEKDAY(AF$2,2)<6)*(COUNTIF('마스터'!$J$13:$J$27,AF$2)=0)*($L$8:$L$162)/($U$8:$U$162+($U$8:$U$162=0))) | AG4: =SUMPRODUCT(($F$8:$F$162<>"")*($F$8:$F$162<=AG$2)*($V$8:$V$162>=AG$2)*(WEEKDAY(AG$2,2)<6)*(COUNTIF('마스터'!$J$13:$J$27,AG$2)=0)*($L$8:$L$162)/($U$8:$U$162+($U$8:$U$162=0))) | ... BD4: =SUMPRODUCT(($F$8:$F$162<>"")*($F$8:$F$162<=BD$2)*($V$8:$V$162>=BD$2)*(WEEKDAY(BD$2,2)<6)*(COUNTIF('마스터'!$J$13:$J$27,BD$2)=0)*($L$8:$L$162)/($U$8:$U$162+($U$8:$U$162=0)))
A5: 이미지 TO | G5: 정원 | H5: ='마스터'!$J$9 | Z5: =SUMPRODUCT(($F$8:$F$162<>"")*($F$8:$F$162<=Z$2)*($V$8:$V$162>=Z$2)*(WEEKDAY(Z$2,2)<6)*(COUNTIF('마스터'!$J$13:$J$27,Z$2)=0)*($N$8:$N$162)/($U$8:$U$162+($U$8:$U$162=0))) | AA5: =SUMPRODUCT(($F$8:$F$162<>"")*($F$8:$F$162<=AA$2)*($V$8:$V$162>=AA$2)*(WEEKDAY(AA$2,2)<6)*(COUNTIF('마스터'!$J$13:$J$27,AA$2)=0)*($N$8:$N$162)/($U$8:$U$162+($U$8:$U$162=0))) | AB5: =SUMPRODUCT(($F$8:$F$162<>"")*($F$8:$F$162<=AB$2)*($V$8:$V$162>=AB$2)*(WEEKDAY(AB$2,2)<6)*(COUNTIF('마스터'!$J$13:$J$27,AB$2)=0)*($N$8:$N$162)/($U$8:$U$162+($U$8:$U$162=0))) | AC5: =SUMPRODUCT(($F$8:$F$162<>"")*($F$8:$F$162<=AC$2)*($V$8:$V$162>=AC$2)*(WEEKDAY(AC$2,2)<6)*(COUNTIF('마스터'!$J$13:$J$27,AC$2)=0)*($N$8:$N$162)/($U$8:$U$162+($U$8:$U$162=0))) | AD5: =SUMPRODUCT(($F$8:$F$162<>"")*($F$8:$F$162<=AD$2)*($V$8:$V$162>=AD$2)*(WEEKDAY(AD$2,2)<6)*(COUNTIF('마스터'!$J$13:$J$27,AD$2)=0)*($N$8:$N$162)/($U$8:$U$162+($U$8:$U$162=0))) | AE5: =SUMPRODUCT(($F$8:$F$162<>"")*($F$8:$F$162<=AE$2)*($V$8:$V$162>=AE$2)*(WEEKDAY(AE$2,2)<6)*(COUNTIF('마스터'!$J$13:$J$27,AE$2)=0)*($N$8:$N$162)/($U$8:$U$162+($U$8:$U$162=0))) | AF5: =SUMPRODUCT(($F$8:$F$162<>"")*($F$8:$F$162<=AF$2)*($V$8:$V$162>=AF$2)*(WEEKDAY(AF$2,2)<6)*(COUNTIF('마스터'!$J$13:$J$27,AF$2)=0)*($N$8:$N$162)/($U$8:$U$162+($U$8:$U$162=0))) | AG5: =SUMPRODUCT(($F$8:$F$162<>"")*($F$8:$F$162<=AG$2)*($V$8:$V$162>=AG$2)*(WEEKDAY(AG$2,2)<6)*(COUNTIF('마스터'!$J$13:$J$27,AG$2)=0)*($N$8:$N$162)/($U$8:$U$162+($U$8:$U$162=0))) | ... BD5: =SUMPRODUCT(($F$8:$F$162<>"")*($F$8:$F$162<=BD$2)*($V$8:$V$162>=BD$2)*(WEEKDAY(BD$2,2)<6)*(COUNTIF('마스터'!$J$13:$J$27,BD$2)=0)*($N$8:$N$162)/($U$8:$U$162+($U$8:$U$162=0)))
A6: 기획 TO | G6: 정원 | H6: ='마스터'!$J$10 | Z6: =SUMPRODUCT(($F$8:$F$162<>"")*($F$8:$F$162<=Z$2)*($V$8:$V$162>=Z$2)*(WEEKDAY(Z$2,2)<6)*(COUNTIF('마스터'!$J$13:$J$27,Z$2)=0)*($P$8:$P$162)/($U$8:$U$162+($U$8:$U$162=0))) | AA6: =SUMPRODUCT(($F$8:$F$162<>"")*($F$8:$F$162<=AA$2)*($V$8:$V$162>=AA$2)*(WEEKDAY(AA$2,2)<6)*(COUNTIF('마스터'!$J$13:$J$27,AA$2)=0)*($P$8:$P$162)/($U$8:$U$162+($U$8:$U$162=0))) | AB6: =SUMPRODUCT(($F$8:$F$162<>"")*($F$8:$F$162<=AB$2)*($V$8:$V$162>=AB$2)*(WEEKDAY(AB$2,2)<6)*(COUNTIF('마스터'!$J$13:$J$27,AB$2)=0)*($P$8:$P$162)/($U$8:$U$162+($U$8:$U$162=0))) | AC6: =SUMPRODUCT(($F$8:$F$162<>"")*($F$8:$F$162<=AC$2)*($V$8:$V$162>=AC$2)*(WEEKDAY(AC$2,2)<6)*(COUNTIF('마스터'!$J$13:$J$27,AC$2)=0)*($P$8:$P$162)/($U$8:$U$162+($U$8:$U$162=0))) | AD6: =SUMPRODUCT(($F$8:$F$162<>"")*($F$8:$F$162<=AD$2)*($V$8:$V$162>=AD$2)*(WEEKDAY(AD$2,2)<6)*(COUNTIF('마스터'!$J$13:$J$27,AD$2)=0)*($P$8:$P$162)/($U$8:$U$162+($U$8:$U$162=0))) | AE6: =SUMPRODUCT(($F$8:$F$162<>"")*($F$8:$F$162<=AE$2)*($V$8:$V$162>=AE$2)*(WEEKDAY(AE$2,2)<6)*(COUNTIF('마스터'!$J$13:$J$27,AE$2)=0)*($P$8:$P$162)/($U$8:$U$162+($U$8:$U$162=0))) | AF6: =SUMPRODUCT(($F$8:$F$162<>"")*($F$8:$F$162<=AF$2)*($V$8:$V$162>=AF$2)*(WEEKDAY(AF$2,2)<6)*(COUNTIF('마스터'!$J$13:$J$27,AF$2)=0)*($P$8:$P$162)/($U$8:$U$162+($U$8:$U$162=0))) | AG6: =SUMPRODUCT(($F$8:$F$162<>"")*($F$8:$F$162<=AG$2)*($V$8:$V$162>=AG$2)*(WEEKDAY(AG$2,2)<6)*(COUNTIF('마스터'!$J$13:$J$27,AG$2)=0)*($P$8:$P$162)/($U$8:$U$162+($U$8:$U$162=0))) | ... BD6: =SUMPRODUCT(($F$8:$F$162<>"")*($F$8:$F$162<=BD$2)*($V$8:$V$162>=BD$2)*(WEEKDAY(BD$2,2)<6)*(COUNTIF('마스터'!$J$13:$J$27,BD$2)=0)*($P$8:$P$162)/($U$8:$U$162+($U$8:$U$162=0)))
A8: 마케팅1팀 (9~38행)
A9: =IF(E9="","",COUNTA($E$9:E9)) | C9: 마케팅1팀 | Q9: =IF(SUM(L9,N9,P9)=0,"",SUM(L9,N9,P9)) | R9: =IF(L9>0,"영 ","")&IF(N9>0,"이 ","")&IF(P9>0,"기 ","") | S9: =IF(F9="","","W"&ROUNDUP(DAY(F9)/7,0)) | U9: =IF(Q9="",0,ROUNDUP(MAX(L9,N9,P9)/'마스터'!$J$5,0)) | V9: =IF(OR(F9="",U9=0),"",WORKDAY(F9,U9-1,'마스터'!$J$13:$J$27)) | W9: =IF(OR(G9="",V9=""),"",G9-V9) | Z9: =IF(AND($F9<>"",$V9<>"",Z$2>=$F9,Z$2<=$V9,WEEKDAY(Z$2,2)<6,COUNTIF('마스터'!$J$13:$J$27,Z$2)=0),$Q9/$U9,"") | AA9: =IF(AND($F9<>"",$V9<>"",AA$2>=$F9,AA$2<=$V9,WEEKDAY(AA$2,2)<6,COUNTIF('마스터'!$J$13:$J$27,AA$2)=0),$Q9/$U9,"") | AB9: =IF(AND($F9<>"",$V9<>"",AB$2>=$F9,AB$2<=$V9,WEEKDAY(AB$2,2)<6,COUNTIF('마스터'!$J$13:$J$27,AB$2)=0),$Q9/$U9,"") | AC9: =IF(AND($F9<>"",$V9<>"",AC$2>=$F9,AC$2<=$V9,WEEKDAY(AC$2,2)<6,COUNTIF('마스터'!$J$13:$J$27,AC$2)=0),$Q9/$U9,"") | AD9: =IF(AND($F9<>"",$V9<>"",AD$2>=$F9,AD$2<=$V9,WEEKDAY(AD$2,2)<6,COUNTIF('마스터'!$J$13:$J$27,AD$2)=0),$Q9/$U9,"") | AE9: =IF(AND($F9<>"",$V9<>"",AE$2>=$F9,AE$2<=$V9,WEEKDAY(AE$2,2)<6,COUNTIF('마스터'!$J$13:$J$27,AE$2)=0),$Q9/$U9,"") | AF9: =IF(AND($F9<>"",$V9<>"",AF$2>=$F9,AF$2<=$V9,WEEKDAY(AF$2,2)<6,COUNTIF('마스터'!$J$13:$J$27,AF$2)=0),$Q9/$U9,"") | AG9: =IF(AND($F9<>"",$V9<>"",AG$2>=$F9,AG$2<=$V9,WEEKDAY(AG$2,2)<6,COUNTIF('마스터'!$J$13:$J$27,AG$2)=0),$Q9/$U9,"") | ... BD9: =IF(AND($F9<>"",$V9<>"",BD$2>=$F9,BD$2<=$V9,WEEKDAY(BD$2,2)<6,COUNTIF('마스터'!$J$13:$J$27,BD$2)=0),$Q9/$U9,"")
A10: =IF(E10="","",COUNTA($E$9:E10)) | C10: 마케팅1팀 | Q10: =IF(SUM(L10,N10,P10)=0,"",SUM(L10,N10,P10)) | R10: =IF(L10>0,"영 ","")&IF(N10>0,"이 ","")&IF(P10>0,"기 ","") | S10: =IF(F10="","","W"&ROUNDUP(DAY(F10)/7,0)) | U10: =IF(Q10="",0,ROUNDUP(MAX(L10,N10,P10)/'마스터'!$J$5,0)) | V10: =IF(OR(F10="",U10=0),"",WORKDAY(F10,U10-1,'마스터'!$J$13:$J$27)) | W10: =IF(OR(G10="",V10=""),"",G10-V10) | Z10: =IF(AND($F10<>"",$V10<>"",Z$2>=$F10,Z$2<=$V10,WEEKDAY(Z$2,2)<6,COUNTIF('마스터'!$J$13:$J$27,Z$2)=0),$Q10/$U10,"") | AA10: =IF(AND($F10<>"",$V10<>"",AA$2>=$F10,AA$2<=$V10,WEEKDAY(AA$2,2)<6,COUNTIF('마스터'!$J$13:$J$27,AA$2)=0),$Q10/$U10,"") | AB10: =IF(AND($F10<>"",$V10<>"",AB$2>=$F10,AB$2<=$V10,WEEKDAY(AB$2,2)<6,COUNTIF('마스터'!$J$13:$J$27,AB$2)=0),$Q10/$U10,"") | AC10: =IF(AND($F10<>"",$V10<>"",AC$2>=$F10,AC$2<=$V10,WEEKDAY(AC$2,2)<6,COUNTIF('마스터'!$J$13:$J$27,AC$2)=0),$Q10/$U10,"") | AD10: =IF(AND($F10<>"",$V10<>"",AD$2>=$F10,AD$2<=$V10,WEEKDAY(AD$2,2)<6,COUNTIF('마스터'!$J$13:$J$27,AD$2)=0),$Q10/$U10,"") | AE10: =IF(AND($F10<>"",$V10<>"",AE$2>=$F10,AE$2<=$V10,WEEKDAY(AE$2,2)<6,COUNTIF('마스터'!$J$13:$J$27,AE$2)=0),$Q10/$U10,"") | AF10: =IF(AND($F10<>"",$V10<>"",AF$2>=$F10,AF$2<=$V10,WEEKDAY(AF$2,2)<6,COUNTIF('마스터'!$J$13:$J$27,AF$2)=0),$Q10/$U10,"") | AG10: =IF(AND($F10<>"",$V10<>"",AG$2>=$F10,AG$2<=$V10,WEEKDAY(AG$2,2)<6,COUNTIF('마스터'!$J$13:$J$27,AG$2)=0),$Q10/$U10,"") | ... BD10: =IF(AND($F10<>"",$V10<>"",BD$2>=$F10,BD$2<=$V10,WEEKDAY(BD$2,2)<6,COUNTIF('마스터'!$J$13:$J$27,BD$2)=0),$Q10/$U10,"")
A11: =IF(E11="","",COUNTA($E$9:E11)) | C11: 마케팅1팀 | Q11: =IF(SUM(L11,N11,P11)=0,"",SUM(L11,N11,P11)) | R11: =IF(L11>0,"영 ","")&IF(N11>0,"이 ","")&IF(P11>0,"기 ","") | S11: =IF(F11="","","W"&ROUNDUP(DAY(F11)/7,0)) | U11: =IF(Q11="",0,ROUNDUP(MAX(L11,N11,P11)/'마스터'!$J$5,0)) | V11: =IF(OR(F11="",U11=0),"",WORKDAY(F11,U11-1,'마스터'!$J$13:$J$27)) | W11: =IF(OR(G11="",V11=""),"",G11-V11) | Z11: =IF(AND($F11<>"",$V11<>"",Z$2>=$F11,Z$2<=$V11,WEEKDAY(Z$2,2)<6,COUNTIF('마스터'!$J$13:$J$27,Z$2)=0),$Q11/$U11,"") | AA11: =IF(AND($F11<>"",$V11<>"",AA$2>=$F11,AA$2<=$V11,WEEKDAY(AA$2,2)<6,COUNTIF('마스터'!$J$13:$J$27,AA$2)=0),$Q11/$U11,"") | AB11: =IF(AND($F11<>"",$V11<>"",AB$2>=$F11,AB$2<=$V11,WEEKDAY(AB$2,2)<6,COUNTIF('마스터'!$J$13:$J$27,AB$2)=0),$Q11/$U11,"") | AC11: =IF(AND($F11<>"",$V11<>"",AC$2>=$F11,AC$2<=$V11,WEEKDAY(AC$2,2)<6,COUNTIF('마스터'!$J$13:$J$27,AC$2)=0),$Q11/$U11,"") | AD11: =IF(AND($F11<>"",$V11<>"",AD$2>=$F11,AD$2<=$V11,WEEKDAY(AD$2,2)<6,COUNTIF('마스터'!$J$13:$J$27,AD$2)=0),$Q11/$U11,"") | AE11: =IF(AND($F11<>"",$V11<>"",AE$2>=$F11,AE$2<=$V11,WEEKDAY(AE$2,2)<6,COUNTIF('마스터'!$J$13:$J$27,AE$2)=0),$Q11/$U11,"") | AF11: =IF(AND($F11<>"",$V11<>"",AF$2>=$F11,AF$2<=$V11,WEEKDAY(AF$2,2)<6,COUNTIF('마스터'!$J$13:$J$27,AF$2)=0),$Q11/$U11,"") | AG11: =IF(AND($F11<>"",$V11<>"",AG$2>=$F11,AG$2<=$V11,WEEKDAY(AG$2,2)<6,COUNTIF('마스터'!$J$13:$J$27,AG$2)=0),$Q11/$U11,"") | ... BD11: =IF(AND($F11<>"",$V11<>"",BD$2>=$F11,BD$2<=$V11,WEEKDAY(BD$2,2)<6,COUNTIF('마스터'!$J$13:$J$27,BD$2)=0),$Q11/$U11,"")
A12: =IF(E12="","",COUNTA($E$9:E12)) | C12: 마케팅1팀 | Q12: =IF(SUM(L12,N12,P12)=0,"",SUM(L12,N12,P12)) | R12: =IF(L12>0,"영 ","")&IF(N12>0,"이 ","")&IF(P12>0,"기 ","") | S12: =IF(F12="","","W"&ROUNDUP(DAY(F12)/7,0)) | U12: =IF(Q12="",0,ROUNDUP(MAX(L12,N12,P12)/'마스터'!$J$5,0)) | V12: =IF(OR(F12="",U12=0),"",WORKDAY(F12,U12-1,'마스터'!$J$13:$J$27)) | W12: =IF(OR(G12="",V12=""),"",G12-V12) | Z12: =IF(AND($F12<>"",$V12<>"",Z$2>=$F12,Z$2<=$V12,WEEKDAY(Z$2,2)<6,COUNTIF('마스터'!$J$13:$J$27,Z$2)=0),$Q12/$U12,"") | AA12: =IF(AND($F12<>"",$V12<>"",AA$2>=$F12,AA$2<=$V12,WEEKDAY(AA$2,2)<6,COUNTIF('마스터'!$J$13:$J$27,AA$2)=0),$Q12/$U12,"") | AB12: =IF(AND($F12<>"",$V12<>"",AB$2>=$F12,AB$2<=$V12,WEEKDAY(AB$2,2)<6,COUNTIF('마스터'!$J$13:$J$27,AB$2)=0),$Q12/$U12,"") | AC12: =IF(AND($F12<>"",$V12<>"",AC$2>=$F12,AC$2<=$V12,WEEKDAY(AC$2,2)<6,COUNTIF('마스터'!$J$13:$J$27,AC$2)=0),$Q12/$U12,"") | AD12: =IF(AND($F12<>"",$V12<>"",AD$2>=$F12,AD$2<=$V12,WEEKDAY(AD$2,2)<6,COUNTIF('마스터'!$J$13:$J$27,AD$2)=0),$Q12/$U12,"") | AE12: =IF(AND($F12<>"",$V12<>"",AE$2>=$F12,AE$2<=$V12,WEEKDAY(AE$2,2)<6,COUNTIF('마스터'!$J$13:$J$27,AE$2)=0),$Q12/$U12,"") | AF12: =IF(AND($F12<>"",$V12<>"",AF$2>=$F12,AF$2<=$V12,WEEKDAY(AF$2,2)<6,COUNTIF('마스터'!$J$13:$J$27,AF$2)=0),$Q12/$U12,"") | AG12: =IF(AND($F12<>"",$V12<>"",AG$2>=$F12,AG$2<=$V12,WEEKDAY(AG$2,2)<6,COUNTIF('마스터'!$J$13:$J$27,AG$2)=0),$Q12/$U12,"") | ... BD12: =IF(AND($F12<>"",$V12<>"",BD$2>=$F12,BD$2<=$V12,WEEKDAY(BD$2,2)<6,COUNTIF('마스터'!$J$13:$J$27,BD$2)=0),$Q12/$U12,"")
A13: =IF(E13="","",COUNTA($E$9:E13)) | C13: 마케팅1팀 | Q13: =IF(SUM(L13,N13,P13)=0,"",SUM(L13,N13,P13)) | R13: =IF(L13>0,"영 ","")&IF(N13>0,"이 ","")&IF(P13>0,"기 ","") | S13: =IF(F13="","","W"&ROUNDUP(DAY(F13)/7,0)) | U13: =IF(Q13="",0,ROUNDUP(MAX(L13,N13,P13)/'마스터'!$J$5,0)) | V13: =IF(OR(F13="",U13=0),"",WORKDAY(F13,U13-1,'마스터'!$J$13:$J$27)) | W13: =IF(OR(G13="",V13=""),"",G13-V13) | Z13: =IF(AND($F13<>"",$V13<>"",Z$2>=$F13,Z$2<=$V13,WEEKDAY(Z$2,2)<6,COUNTIF('마스터'!$J$13:$J$27,Z$2)=0),$Q13/$U13,"") | AA13: =IF(AND($F13<>"",$V13<>"",AA$2>=$F13,AA$2<=$V13,WEEKDAY(AA$2,2)<6,COUNTIF('마스터'!$J$13:$J$27,AA$2)=0),$Q13/$U13,"") | AB13: =IF(AND($F13<>"",$V13<>"",AB$2>=$F13,AB$2<=$V13,WEEKDAY(AB$2,2)<6,COUNTIF('마스터'!$J$13:$J$27,AB$2)=0),$Q13/$U13,"") | AC13: =IF(AND($F13<>"",$V13<>"",AC$2>=$F13,AC$2<=$V13,WEEKDAY(AC$2,2)<6,COUNTIF('마스터'!$J$13:$J$27,AC$2)=0),$Q13/$U13,"") | AD13: =IF(AND($F13<>"",$V13<>"",AD$2>=$F13,AD$2<=$V13,WEEKDAY(AD$2,2)<6,COUNTIF('마스터'!$J$13:$J$27,AD$2)=0),$Q13/$U13,"") | AE13: =IF(AND($F13<>"",$V13<>"",AE$2>=$F13,AE$2<=$V13,WEEKDAY(AE$2,2)<6,COUNTIF('마스터'!$J$13:$J$27,AE$2)=0),$Q13/$U13,"") | AF13: =IF(AND($F13<>"",$V13<>"",AF$2>=$F13,AF$2<=$V13,WEEKDAY(AF$2,2)<6,COUNTIF('마스터'!$J$13:$J$27,AF$2)=0),$Q13/$U13,"") | AG13: =IF(AND($F13<>"",$V13<>"",AG$2>=$F13,AG$2<=$V13,WEEKDAY(AG$2,2)<6,COUNTIF('마스터'!$J$13:$J$27,AG$2)=0),$Q13/$U13,"") | ... BD13: =IF(AND($F13<>"",$V13<>"",BD$2>=$F13,BD$2<=$V13,WEEKDAY(BD$2,2)<6,COUNTIF('마스터'!$J$13:$J$27,BD$2)=0),$Q13/$U13,"")
A14: =IF(E14="","",COUNTA($E$9:E14)) | C14: 마케팅1팀 | Q14: =IF(SUM(L14,N14,P14)=0,"",SUM(L14,N14,P14)) | R14: =IF(L14>0,"영 ","")&IF(N14>0,"이 ","")&IF(P14>0,"기 ","") | S14: =IF(F14="","","W"&ROUNDUP(DAY(F14)/7,0)) | U14: =IF(Q14="",0,ROUNDUP(MAX(L14,N14,P14)/'마스터'!$J$5,0)) | V14: =IF(OR(F14="",U14=0),"",WORKDAY(F14,U14-1,'마스터'!$J$13:$J$27)) | W14: =IF(OR(G14="",V14=""),"",G14-V14) | Z14: =IF(AND($F14<>"",$V14<>"",Z$2>=$F14,Z$2<=$V14,WEEKDAY(Z$2,2)<6,COUNTIF('마스터'!$J$13:$J$27,Z$2)=0),$Q14/$U14,"") | AA14: =IF(AND($F14<>"",$V14<>"",AA$2>=$F14,AA$2<=$V14,WEEKDAY(AA$2,2)<6,COUNTIF('마스터'!$J$13:$J$27,AA$2)=0),$Q14/$U14,"") | AB14: =IF(AND($F14<>"",$V14<>"",AB$2>=$F14,AB$2<=$V14,WEEKDAY(AB$2,2)<6,COUNTIF('마스터'!$J$13:$J$27,AB$2)=0),$Q14/$U14,"") | AC14: =IF(AND($F14<>"",$V14<>"",AC$2>=$F14,AC$2<=$V14,WEEKDAY(AC$2,2)<6,COUNTIF('마스터'!$J$13:$J$27,AC$2)=0),$Q14/$U14,"") | AD14: =IF(AND($F14<>"",$V14<>"",AD$2>=$F14,AD$2<=$V14,WEEKDAY(AD$2,2)<6,COUNTIF('마스터'!$J$13:$J$27,AD$2)=0),$Q14/$U14,"") | AE14: =IF(AND($F14<>"",$V14<>"",AE$2>=$F14,AE$2<=$V14,WEEKDAY(AE$2,2)<6,COUNTIF('마스터'!$J$13:$J$27,AE$2)=0),$Q14/$U14,"") | AF14: =IF(AND($F14<>"",$V14<>"",AF$2>=$F14,AF$2<=$V14,WEEKDAY(AF$2,2)<6,COUNTIF('마스터'!$J$13:$J$27,AF$2)=0),$Q14/$U14,"") | AG14: =IF(AND($F14<>"",$V14<>"",AG$2>=$F14,AG$2<=$V14,WEEKDAY(AG$2,2)<6,COUNTIF('마스터'!$J$13:$J$27,AG$2)=0),$Q14/$U14,"") | ... BD14: =IF(AND($F14<>"",$V14<>"",BD$2>=$F14,BD$2<=$V14,WEEKDAY(BD$2,2)<6,COUNTIF('마스터'!$J$13:$J$27,BD$2)=0),$Q14/$U14,"")
A15: =IF(E15="","",COUNTA($E$9:E15)) | C15: 마케팅1팀 | Q15: =IF(SUM(L15,N15,P15)=0,"",SUM(L15,N15,P15)) | R15: =IF(L15>0,"영 ","")&IF(N15>0,"이 ","")&IF(P15>0,"기 ","") | S15: =IF(F15="","","W"&ROUNDUP(DAY(F15)/7,0)) | U15: =IF(Q15="",0,ROUNDUP(MAX(L15,N15,P15)/'마스터'!$J$5,0)) | V15: =IF(OR(F15="",U15=0),"",WORKDAY(F15,U15-1,'마스터'!$J$13:$J$27)) | W15: =IF(OR(G15="",V15=""),"",G15-V15) | Z15: =IF(AND($F15<>"",$V15<>"",Z$2>=$F15,Z$2<=$V15,WEEKDAY(Z$2,2)<6,COUNTIF('마스터'!$J$13:$J$27,Z$2)=0),$Q15/$U15,"") | AA15: =IF(AND($F15<>"",$V15<>"",AA$2>=$F15,AA$2<=$V15,WEEKDAY(AA$2,2)<6,COUNTIF('마스터'!$J$13:$J$27,AA$2)=0),$Q15/$U15,"") | AB15: =IF(AND($F15<>"",$V15<>"",AB$2>=$F15,AB$2<=$V15,WEEKDAY(AB$2,2)<6,COUNTIF('마스터'!$J$13:$J$27,AB$2)=0),$Q15/$U15,"") | AC15: =IF(AND($F15<>"",$V15<>"",AC$2>=$F15,AC$2<=$V15,WEEKDAY(AC$2,2)<6,COUNTIF('마스터'!$J$13:$J$27,AC$2)=0),$Q15/$U15,"") | AD15: =IF(AND($F15<>"",$V15<>"",AD$2>=$F15,AD$2<=$V15,WEEKDAY(AD$2,2)<6,COUNTIF('마스터'!$J$13:$J$27,AD$2)=0),$Q15/$U15,"") | AE15: =IF(AND($F15<>"",$V15<>"",AE$2>=$F15,AE$2<=$V15,WEEKDAY(AE$2,2)<6,COUNTIF('마스터'!$J$13:$J$27,AE$2)=0),$Q15/$U15,"") | AF15: =IF(AND($F15<>"",$V15<>"",AF$2>=$F15,AF$2<=$V15,WEEKDAY(AF$2,2)<6,COUNTIF('마스터'!$J$13:$J$27,AF$2)=0),$Q15/$U15,"") | AG15: =IF(AND($F15<>"",$V15<>"",AG$2>=$F15,AG$2<=$V15,WEEKDAY(AG$2,2)<6,COUNTIF('마스터'!$J$13:$J$27,AG$2)=0),$Q15/$U15,"") | ... BD15: =IF(AND($F15<>"",$V15<>"",BD$2>=$F15,BD$2<=$V15,WEEKDAY(BD$2,2)<6,COUNTIF('마스터'!$J$13:$J$27,BD$2)=0),$Q15/$U15,"")
A16: =IF(E16="","",COUNTA($E$9:E16)) | C16: 마케팅1팀 | Q16: =IF(SUM(L16,N16,P16)=0,"",SUM(L16,N16,P16)) | R16: =IF(L16>0,"영 ","")&IF(N16>0,"이 ","")&IF(P16>0,"기 ","") | S16: =IF(F16="","","W"&ROUNDUP(DAY(F16)/7,0)) | U16: =IF(Q16="",0,ROUNDUP(MAX(L16,N16,P16)/'마스터'!$J$5,0)) | V16: =IF(OR(F16="",U16=0),"",WORKDAY(F16,U16-1,'마스터'!$J$13:$J$27)) | W16: =IF(OR(G16="",V16=""),"",G16-V16) | Z16: =IF(AND($F16<>"",$V16<>"",Z$2>=$F16,Z$2<=$V16,WEEKDAY(Z$2,2)<6,COUNTIF('마스터'!$J$13:$J$27,Z$2)=0),$Q16/$U16,"") | AA16: =IF(AND($F16<>"",$V16<>"",AA$2>=$F16,AA$2<=$V16,WEEKDAY(AA$2,2)<6,COUNTIF('마스터'!$J$13:$J$27,AA$2)=0),$Q16/$U16,"") | AB16: =IF(AND($F16<>"",$V16<>"",AB$2>=$F16,AB$2<=$V16,WEEKDAY(AB$2,2)<6,COUNTIF('마스터'!$J$13:$J$27,AB$2)=0),$Q16/$U16,"") | AC16: =IF(AND($F16<>"",$V16<>"",AC$2>=$F16,AC$2<=$V16,WEEKDAY(AC$2,2)<6,COUNTIF('마스터'!$J$13:$J$27,AC$2)=0),$Q16/$U16,"") | AD16: =IF(AND($F16<>"",$V16<>"",AD$2>=$F16,AD$2<=$V16,WEEKDAY(AD$2,2)<6,COUNTIF('마스터'!$J$13:$J$27,AD$2)=0),$Q16/$U16,"") | AE16: =IF(AND($F16<>"",$V16<>"",AE$2>=$F16,AE$2<=$V16,WEEKDAY(AE$2,2)<6,COUNTIF('마스터'!$J$13:$J$27,AE$2)=0),$Q16/$U16,"") | AF16: =IF(AND($F16<>"",$V16<>"",AF$2>=$F16,AF$2<=$V16,WEEKDAY(AF$2,2)<6,COUNTIF('마스터'!$J$13:$J$27,AF$2)=0),$Q16/$U16,"") | AG16: =IF(AND($F16<>"",$V16<>"",AG$2>=$F16,AG$2<=$V16,WEEKDAY(AG$2,2)<6,COUNTIF('마스터'!$J$13:$J$27,AG$2)=0),$Q16/$U16,"") | ... BD16: =IF(AND($F16<>"",$V16<>"",BD$2>=$F16,BD$2<=$V16,WEEKDAY(BD$2,2)<6,COUNTIF('마스터'!$J$13:$J$27,BD$2)=0),$Q16/$U16,"")
A17: =IF(E17="","",COUNTA($E$9:E17)) | C17: 마케팅1팀 | Q17: =IF(SUM(L17,N17,P17)=0,"",SUM(L17,N17,P17)) | R17: =IF(L17>0,"영 ","")&IF(N17>0,"이 ","")&IF(P17>0,"기 ","") | S17: =IF(F17="","","W"&ROUNDUP(DAY(F17)/7,0)) | U17: =IF(Q17="",0,ROUNDUP(MAX(L17,N17,P17)/'마스터'!$J$5,0)) | V17: =IF(OR(F17="",U17=0),"",WORKDAY(F17,U17-1,'마스터'!$J$13:$J$27)) | W17: =IF(OR(G17="",V17=""),"",G17-V17) | Z17: =IF(AND($F17<>"",$V17<>"",Z$2>=$F17,Z$2<=$V17,WEEKDAY(Z$2,2)<6,COUNTIF('마스터'!$J$13:$J$27,Z$2)=0),$Q17/$U17,"") | AA17: =IF(AND($F17<>"",$V17<>"",AA$2>=$F17,AA$2<=$V17,WEEKDAY(AA$2,2)<6,COUNTIF('마스터'!$J$13:$J$27,AA$2)=0),$Q17/$U17,"") | AB17: =IF(AND($F17<>"",$V17<>"",AB$2>=$F17,AB$2<=$V17,WEEKDAY(AB$2,2)<6,COUNTIF('마스터'!$J$13:$J$27,AB$2)=0),$Q17/$U17,"") | AC17: =IF(AND($F17<>"",$V17<>"",AC$2>=$F17,AC$2<=$V17,WEEKDAY(AC$2,2)<6,COUNTIF('마스터'!$J$13:$J$27,AC$2)=0),$Q17/$U17,"") | AD17: =IF(AND($F17<>"",$V17<>"",AD$2>=$F17,AD$2<=$V17,WEEKDAY(AD$2,2)<6,COUNTIF('마스터'!$J$13:$J$27,AD$2)=0),$Q17/$U17,"") | AE17: =IF(AND($F17<>"",$V17<>"",AE$2>=$F17,AE$2<=$V17,WEEKDAY(AE$2,2)<6,COUNTIF('마스터'!$J$13:$J$27,AE$2)=0),$Q17/$U17,"") | AF17: =IF(AND($F17<>"",$V17<>"",AF$2>=$F17,AF$2<=$V17,WEEKDAY(AF$2,2)<6,COUNTIF('마스터'!$J$13:$J$27,AF$2)=0),$Q17/$U17,"") | AG17: =IF(AND($F17<>"",$V17<>"",AG$2>=$F17,AG$2<=$V17,WEEKDAY(AG$2,2)<6,COUNTIF('마스터'!$J$13:$J$27,AG$2)=0),$Q17/$U17,"") | ... BD17: =IF(AND($F17<>"",$V17<>"",BD$2>=$F17,BD$2<=$V17,WEEKDAY(BD$2,2)<6,COUNTIF('마스터'!$J$13:$J$27,BD$2)=0),$Q17/$U17,"")
A18: =IF(E18="","",COUNTA($E$9:E18)) | C18: 마케팅1팀 | Q18: =IF(SUM(L18,N18,P18)=0,"",SUM(L18,N18,P18)) | R18: =IF(L18>0,"영 ","")&IF(N18>0,"이 ","")&IF(P18>0,"기 ","") | S18: =IF(F18="","","W"&ROUNDUP(DAY(F18)/7,0)) | U18: =IF(Q18="",0,ROUNDUP(MAX(L18,N18,P18)/'마스터'!$J$5,0)) | V18: =IF(OR(F18="",U18=0),"",WORKDAY(F18,U18-1,'마스터'!$J$13:$J$27)) | W18: =IF(OR(G18="",V18=""),"",G18-V18) | Z18: =IF(AND($F18<>"",$V18<>"",Z$2>=$F18,Z$2<=$V18,WEEKDAY(Z$2,2)<6,COUNTIF('마스터'!$J$13:$J$27,Z$2)=0),$Q18/$U18,"") | AA18: =IF(AND($F18<>"",$V18<>"",AA$2>=$F18,AA$2<=$V18,WEEKDAY(AA$2,2)<6,COUNTIF('마스터'!$J$13:$J$27,AA$2)=0),$Q18/$U18,"") | AB18: =IF(AND($F18<>"",$V18<>"",AB$2>=$F18,AB$2<=$V18,WEEKDAY(AB$2,2)<6,COUNTIF('마스터'!$J$13:$J$27,AB$2)=0),$Q18/$U18,"") | AC18: =IF(AND($F18<>"",$V18<>"",AC$2>=$F18,AC$2<=$V18,WEEKDAY(AC$2,2)<6,COUNTIF('마스터'!$J$13:$J$27,AC$2)=0),$Q18/$U18,"") | AD18: =IF(AND($F18<>"",$V18<>"",AD$2>=$F18,AD$2<=$V18,WEEKDAY(AD$2,2)<6,COUNTIF('마스터'!$J$13:$J$27,AD$2)=0),$Q18/$U18,"") | AE18: =IF(AND($F18<>"",$V18<>"",AE$2>=$F18,AE$2<=$V18,WEEKDAY(AE$2,2)<6,COUNTIF('마스터'!$J$13:$J$27,AE$2)=0),$Q18/$U18,"") | AF18: =IF(AND($F18<>"",$V18<>"",AF$2>=$F18,AF$2<=$V18,WEEKDAY(AF$2,2)<6,COUNTIF('마스터'!$J$13:$J$27,AF$2)=0),$Q18/$U18,"") | AG18: =IF(AND($F18<>"",$V18<>"",AG$2>=$F18,AG$2<=$V18,WEEKDAY(AG$2,2)<6,COUNTIF('마스터'!$J$13:$J$27,AG$2)=0),$Q18/$U18,"") | ... BD18: =IF(AND($F18<>"",$V18<>"",BD$2>=$F18,BD$2<=$V18,WEEKDAY(BD$2,2)<6,COUNTIF('마스터'!$J$13:$J$27,BD$2)=0),$Q18/$U18,"")
A19: =IF(E19="","",COUNTA($E$9:E19)) | C19: 마케팅1팀 | Q19: =IF(SUM(L19,N19,P19)=0,"",SUM(L19,N19,P19)) | R19: =IF(L19>0,"영 ","")&IF(N19>0,"이 ","")&IF(P19>0,"기 ","") | S19: =IF(F19="","","W"&ROUNDUP(DAY(F19)/7,0)) | U19: =IF(Q19="",0,ROUNDUP(MAX(L19,N19,P19)/'마스터'!$J$5,0)) | V19: =IF(OR(F19="",U19=0),"",WORKDAY(F19,U19-1,'마스터'!$J$13:$J$27)) | W19: =IF(OR(G19="",V19=""),"",G19-V19) | Z19: =IF(AND($F19<>"",$V19<>"",Z$2>=$F19,Z$2<=$V19,WEEKDAY(Z$2,2)<6,COUNTIF('마스터'!$J$13:$J$27,Z$2)=0),$Q19/$U19,"") | AA19: =IF(AND($F19<>"",$V19<>"",AA$2>=$F19,AA$2<=$V19,WEEKDAY(AA$2,2)<6,COUNTIF('마스터'!$J$13:$J$27,AA$2)=0),$Q19/$U19,"") | AB19: =IF(AND($F19<>"",$V19<>"",AB$2>=$F19,AB$2<=$V19,WEEKDAY(AB$2,2)<6,COUNTIF('마스터'!$J$13:$J$27,AB$2)=0),$Q19/$U19,"") | AC19: =IF(AND($F19<>"",$V19<>"",AC$2>=$F19,AC$2<=$V19,WEEKDAY(AC$2,2)<6,COUNTIF('마스터'!$J$13:$J$27,AC$2)=0),$Q19/$U19,"") | AD19: =IF(AND($F19<>"",$V19<>"",AD$2>=$F19,AD$2<=$V19,WEEKDAY(AD$2,2)<6,COUNTIF('마스터'!$J$13:$J$27,AD$2)=0),$Q19/$U19,"") | AE19: =IF(AND($F19<>"",$V19<>"",AE$2>=$F19,AE$2<=$V19,WEEKDAY(AE$2,2)<6,COUNTIF('마스터'!$J$13:$J$27,AE$2)=0),$Q19/$U19,"") | AF19: =IF(AND($F19<>"",$V19<>"",AF$2>=$F19,AF$2<=$V19,WEEKDAY(AF$2,2)<6,COUNTIF('마스터'!$J$13:$J$27,AF$2)=0),$Q19/$U19,"") | AG19: =IF(AND($F19<>"",$V19<>"",AG$2>=$F19,AG$2<=$V19,WEEKDAY(AG$2,2)<6,COUNTIF('마스터'!$J$13:$J$27,AG$2)=0),$Q19/$U19,"") | ... BD19: =IF(AND($F19<>"",$V19<>"",BD$2>=$F19,BD$2<=$V19,WEEKDAY(BD$2,2)<6,COUNTIF('마스터'!$J$13:$J$27,BD$2)=0),$Q19/$U19,"")
A20: =IF(E20="","",COUNTA($E$9:E20)) | C20: 마케팅1팀 | Q20: =IF(SUM(L20,N20,P20)=0,"",SUM(L20,N20,P20)) | R20: =IF(L20>0,"영 ","")&IF(N20>0,"이 ","")&IF(P20>0,"기 ","") | S20: =IF(F20="","","W"&ROUNDUP(DAY(F20)/7,0)) | U20: =IF(Q20="",0,ROUNDUP(MAX(L20,N20,P20)/'마스터'!$J$5,0)) | V20: =IF(OR(F20="",U20=0),"",WORKDAY(F20,U20-1,'마스터'!$J$13:$J$27)) | W20: =IF(OR(G20="",V20=""),"",G20-V20) | Z20: =IF(AND($F20<>"",$V20<>"",Z$2>=$F20,Z$2<=$V20,WEEKDAY(Z$2,2)<6,COUNTIF('마스터'!$J$13:$J$27,Z$2)=0),$Q20/$U20,"") | AA20: =IF(AND($F20<>"",$V20<>"",AA$2>=$F20,AA$2<=$V20,WEEKDAY(AA$2,2)<6,COUNTIF('마스터'!$J$13:$J$27,AA$2)=0),$Q20/$U20,"") | AB20: =IF(AND($F20<>"",$V20<>"",AB$2>=$F20,AB$2<=$V20,WEEKDAY(AB$2,2)<6,COUNTIF('마스터'!$J$13:$J$27,AB$2)=0),$Q20/$U20,"") | AC20: =IF(AND($F20<>"",$V20<>"",AC$2>=$F20,AC$2<=$V20,WEEKDAY(AC$2,2)<6,COUNTIF('마스터'!$J$13:$J$27,AC$2)=0),$Q20/$U20,"") | AD20: =IF(AND($F20<>"",$V20<>"",AD$2>=$F20,AD$2<=$V20,WEEKDAY(AD$2,2)<6,COUNTIF('마스터'!$J$13:$J$27,AD$2)=0),$Q20/$U20,"") | AE20: =IF(AND($F20<>"",$V20<>"",AE$2>=$F20,AE$2<=$V20,WEEKDAY(AE$2,2)<6,COUNTIF('마스터'!$J$13:$J$27,AE$2)=0),$Q20/$U20,"") | AF20: =IF(AND($F20<>"",$V20<>"",AF$2>=$F20,AF$2<=$V20,WEEKDAY(AF$2,2)<6,COUNTIF('마스터'!$J$13:$J$27,AF$2)=0),$Q20/$U20,"") | AG20: =IF(AND($F20<>"",$V20<>"",AG$2>=$F20,AG$2<=$V20,WEEKDAY(AG$2,2)<6,COUNTIF('마스터'!$J$13:$J$27,AG$2)=0),$Q20/$U20,"") | ... BD20: =IF(AND($F20<>"",$V20<>"",BD$2>=$F20,BD$2<=$V20,WEEKDAY(BD$2,2)<6,COUNTIF('마스터'!$J$13:$J$27,BD$2)=0),$Q20/$U20,"")
... A38: =IF(E38="","",COUNTA($E$9:E38)) | C38: 마케팅1팀 | Q38: =IF(SUM(L38,N38,P38)=0,"",SUM(L38,N38,P38)) | R38: =IF(L38>0,"영 ","")&IF(N38>0,"이 ","")&IF(P38>0,"기 ","") | S38: =IF(F38="","","W"&ROUNDUP(DAY(F38)/7,0)) | U38: =IF(Q38="",0,ROUNDUP(MAX(L38,N38,P38)/'마스터'!$J$5,0)) | V38: =IF(OR(F38="",U38=0),"",WORKDAY(F38,U38-1,'마스터'!$J$13:$J$27)) | W38: =IF(OR(G38="",V38=""),"",G38-V38) | Z38: =IF(AND($F38<>"",$V38<>"",Z$2>=$F38,Z$2<=$V38,WEEKDAY(Z$2,2)<6,COUNTIF('마스터'!$J$13:$J$27,Z$2)=0),$Q38/$U38,"") | AA38: =IF(AND($F38<>"",$V38<>"",AA$2>=$F38,AA$2<=$V38,WEEKDAY(AA$2,2)<6,COUNTIF('마스터'!$J$13:$J$27,AA$2)=0),$Q38/$U38,"") | AB38: =IF(AND($F38<>"",$V38<>"",AB$2>=$F38,AB$2<=$V38,WEEKDAY(AB$2,2)<6,COUNTIF('마스터'!$J$13:$J$27,AB$2)=0),$Q38/$U38,"") | AC38: =IF(AND($F38<>"",$V38<>"",AC$2>=$F38,AC$2<=$V38,WEEKDAY(AC$2,2)<6,COUNTIF('마스터'!$J$13:$J$27,AC$2)=0),$Q38/$U38,"") | AD38: =IF(AND($F38<>"",$V38<>"",AD$2>=$F38,AD$2<=$V38,WEEKDAY(AD$2,2)<6,COUNTIF('마스터'!$J$13:$J$27,AD$2)=0),$Q38/$U38,"") | AE38: =IF(AND($F38<>"",$V38<>"",AE$2>=$F38,AE$2<=$V38,WEEKDAY(AE$2,2)<6,COUNTIF('마스터'!$J$13:$J$27,AE$2)=0),$Q38/$U38,"") | AF38: =IF(AND($F38<>"",$V38<>"",AF$2>=$F38,AF$2<=$V38,WEEKDAY(AF$2,2)<6,COUNTIF('마스터'!$J$13:$J$27,AF$2)=0),$Q38/$U38,"") | AG38: =IF(AND($F38<>"",$V38<>"",AG$2>=$F38,AG$2<=$V38,WEEKDAY(AG$2,2)<6,COUNTIF('마스터'!$J$13:$J$27,AG$2)=0),$Q38/$U38,"") | ... BD38: =IF(AND($F38<>"",$V38<>"",BD$2>=$F38,BD$2<=$V38,WEEKDAY(BD$2,2)<6,COUNTIF('마스터'!$J$13:$J$27,BD$2)=0),$Q38/$U38,"")
A39: 마케팅2팀 (40~69행)
A40: =IF(E40="","",COUNTA($E$40:E40)) | C40: 마케팅2팀 | Q40: =IF(SUM(L40,N40,P40)=0,"",SUM(L40,N40,P40)) | R40: =IF(L40>0,"영 ","")&IF(N40>0,"이 ","")&IF(P40>0,"기 ","") | S40: =IF(F40="","","W"&ROUNDUP(DAY(F40)/7,0)) | U40: =IF(Q40="",0,ROUNDUP(MAX(L40,N40,P40)/'마스터'!$J$5,0)) | V40: =IF(OR(F40="",U40=0),"",WORKDAY(F40,U40-1,'마스터'!$J$13:$J$27)) | W40: =IF(OR(G40="",V40=""),"",G40-V40) | Z40: =IF(AND($F40<>"",$V40<>"",Z$2>=$F40,Z$2<=$V40,WEEKDAY(Z$2,2)<6,COUNTIF('마스터'!$J$13:$J$27,Z$2)=0),$Q40/$U40,"") | AA40: =IF(AND($F40<>"",$V40<>"",AA$2>=$F40,AA$2<=$V40,WEEKDAY(AA$2,2)<6,COUNTIF('마스터'!$J$13:$J$27,AA$2)=0),$Q40/$U40,"") | AB40: =IF(AND($F40<>"",$V40<>"",AB$2>=$F40,AB$2<=$V40,WEEKDAY(AB$2,2)<6,COUNTIF('마스터'!$J$13:$J$27,AB$2)=0),$Q40/$U40,"") | AC40: =IF(AND($F40<>"",$V40<>"",AC$2>=$F40,AC$2<=$V40,WEEKDAY(AC$2,2)<6,COUNTIF('마스터'!$J$13:$J$27,AC$2)=0),$Q40/$U40,"") | AD40: =IF(AND($F40<>"",$V40<>"",AD$2>=$F40,AD$2<=$V40,WEEKDAY(AD$2,2)<6,COUNTIF('마스터'!$J$13:$J$27,AD$2)=0),$Q40/$U40,"") | AE40: =IF(AND($F40<>"",$V40<>"",AE$2>=$F40,AE$2<=$V40,WEEKDAY(AE$2,2)<6,COUNTIF('마스터'!$J$13:$J$27,AE$2)=0),$Q40/$U40,"") | AF40: =IF(AND($F40<>"",$V40<>"",AF$2>=$F40,AF$2<=$V40,WEEKDAY(AF$2,2)<6,COUNTIF('마스터'!$J$13:$J$27,AF$2)=0),$Q40/$U40,"") | AG40: =IF(AND($F40<>"",$V40<>"",AG$2>=$F40,AG$2<=$V40,WEEKDAY(AG$2,2)<6,COUNTIF('마스터'!$J$13:$J$27,AG$2)=0),$Q40/$U40,"") | ... BD40: =IF(AND($F40<>"",$V40<>"",BD$2>=$F40,BD$2<=$V40,WEEKDAY(BD$2,2)<6,COUNTIF('마스터'!$J$13:$J$27,BD$2)=0),$Q40/$U40,"")
A41: =IF(E41="","",COUNTA($E$40:E41)) | C41: 마케팅2팀 | Q41: =IF(SUM(L41,N41,P41)=0,"",SUM(L41,N41,P41)) | R41: =IF(L41>0,"영 ","")&IF(N41>0,"이 ","")&IF(P41>0,"기 ","") | S41: =IF(F41="","","W"&ROUNDUP(DAY(F41)/7,0)) | U41: =IF(Q41="",0,ROUNDUP(MAX(L41,N41,P41)/'마스터'!$J$5,0)) | V41: =IF(OR(F41="",U41=0),"",WORKDAY(F41,U41-1,'마스터'!$J$13:$J$27)) | W41: =IF(OR(G41="",V41=""),"",G41-V41) | Z41: =IF(AND($F41<>"",$V41<>"",Z$2>=$F41,Z$2<=$V41,WEEKDAY(Z$2,2)<6,COUNTIF('마스터'!$J$13:$J$27,Z$2)=0),$Q41/$U41,"") | AA41: =IF(AND($F41<>"",$V41<>"",AA$2>=$F41,AA$2<=$V41,WEEKDAY(AA$2,2)<6,COUNTIF('마스터'!$J$13:$J$27,AA$2)=0),$Q41/$U41,"") | AB41: =IF(AND($F41<>"",$V41<>"",AB$2>=$F41,AB$2<=$V41,WEEKDAY(AB$2,2)<6,COUNTIF('마스터'!$J$13:$J$27,AB$2)=0),$Q41/$U41,"") | AC41: =IF(AND($F41<>"",$V41<>"",AC$2>=$F41,AC$2<=$V41,WEEKDAY(AC$2,2)<6,COUNTIF('마스터'!$J$13:$J$27,AC$2)=0),$Q41/$U41,"") | AD41: =IF(AND($F41<>"",$V41<>"",AD$2>=$F41,AD$2<=$V41,WEEKDAY(AD$2,2)<6,COUNTIF('마스터'!$J$13:$J$27,AD$2)=0),$Q41/$U41,"") | AE41: =IF(AND($F41<>"",$V41<>"",AE$2>=$F41,AE$2<=$V41,WEEKDAY(AE$2,2)<6,COUNTIF('마스터'!$J$13:$J$27,AE$2)=0),$Q41/$U41,"") | AF41: =IF(AND($F41<>"",$V41<>"",AF$2>=$F41,AF$2<=$V41,WEEKDAY(AF$2,2)<6,COUNTIF('마스터'!$J$13:$J$27,AF$2)=0),$Q41/$U41,"") | AG41: =IF(AND($F41<>"",$V41<>"",AG$2>=$F41,AG$2<=$V41,WEEKDAY(AG$2,2)<6,COUNTIF('마스터'!$J$13:$J$27,AG$2)=0),$Q41/$U41,"") | ... BD41: =IF(AND($F41<>"",$V41<>"",BD$2>=$F41,BD$2<=$V41,WEEKDAY(BD$2,2)<6,COUNTIF('마스터'!$J$13:$J$27,BD$2)=0),$Q41/$U41,"")
A42: =IF(E42="","",COUNTA($E$40:E42)) | C42: 마케팅2팀 | Q42: =IF(SUM(L42,N42,P42)=0,"",SUM(L42,N42,P42)) | R42: =IF(L42>0,"영 ","")&IF(N42>0,"이 ","")&IF(P42>0,"기 ","") | S42: =IF(F42="","","W"&ROUNDUP(DAY(F42)/7,0)) | U42: =IF(Q42="",0,ROUNDUP(MAX(L42,N42,P42)/'마스터'!$J$5,0)) | V42: =IF(OR(F42="",U42=0),"",WORKDAY(F42,U42-1,'마스터'!$J$13:$J$27)) | W42: =IF(OR(G42="",V42=""),"",G42-V42) | Z42: =IF(AND($F42<>"",$V42<>"",Z$2>=$F42,Z$2<=$V42,WEEKDAY(Z$2,2)<6,COUNTIF('마스터'!$J$13:$J$27,Z$2)=0),$Q42/$U42,"") | AA42: =IF(AND($F42<>"",$V42<>"",AA$2>=$F42,AA$2<=$V42,WEEKDAY(AA$2,2)<6,COUNTIF('마스터'!$J$13:$J$27,AA$2)=0),$Q42/$U42,"") | AB42: =IF(AND($F42<>"",$V42<>"",AB$2>=$F42,AB$2<=$V42,WEEKDAY(AB$2,2)<6,COUNTIF('마스터'!$J$13:$J$27,AB$2)=0),$Q42/$U42,"") | AC42: =IF(AND($F42<>"",$V42<>"",AC$2>=$F42,AC$2<=$V42,WEEKDAY(AC$2,2)<6,COUNTIF('마스터'!$J$13:$J$27,AC$2)=0),$Q42/$U42,"") | AD42: =IF(AND($F42<>"",$V42<>"",AD$2>=$F42,AD$2<=$V42,WEEKDAY(AD$2,2)<6,COUNTIF('마스터'!$J$13:$J$27,AD$2)=0),$Q42/$U42,"") | AE42: =IF(AND($F42<>"",$V42<>"",AE$2>=$F42,AE$2<=$V42,WEEKDAY(AE$2,2)<6,COUNTIF('마스터'!$J$13:$J$27,AE$2)=0),$Q42/$U42,"") | AF42: =IF(AND($F42<>"",$V42<>"",AF$2>=$F42,AF$2<=$V42,WEEKDAY(AF$2,2)<6,COUNTIF('마스터'!$J$13:$J$27,AF$2)=0),$Q42/$U42,"") | AG42: =IF(AND($F42<>"",$V42<>"",AG$2>=$F42,AG$2<=$V42,WEEKDAY(AG$2,2)<6,COUNTIF('마스터'!$J$13:$J$27,AG$2)=0),$Q42/$U42,"") | ... BD42: =IF(AND($F42<>"",$V42<>"",BD$2>=$F42,BD$2<=$V42,WEEKDAY(BD$2,2)<6,COUNTIF('마스터'!$J$13:$J$27,BD$2)=0),$Q42/$U42,"")
A43: =IF(E43="","",COUNTA($E$40:E43)) | C43: 마케팅2팀 | Q43: =IF(SUM(L43,N43,P43)=0,"",SUM(L43,N43,P43)) | R43: =IF(L43>0,"영 ","")&IF(N43>0,"이 ","")&IF(P43>0,"기 ","") | S43: =IF(F43="","","W"&ROUNDUP(DAY(F43)/7,0)) | U43: =IF(Q43="",0,ROUNDUP(MAX(L43,N43,P43)/'마스터'!$J$5,0)) | V43: =IF(OR(F43="",U43=0),"",WORKDAY(F43,U43-1,'마스터'!$J$13:$J$27)) | W43: =IF(OR(G43="",V43=""),"",G43-V43) | Z43: =IF(AND($F43<>"",$V43<>"",Z$2>=$F43,Z$2<=$V43,WEEKDAY(Z$2,2)<6,COUNTIF('마스터'!$J$13:$J$27,Z$2)=0),$Q43/$U43,"") | AA43: =IF(AND($F43<>"",$V43<>"",AA$2>=$F43,AA$2<=$V43,WEEKDAY(AA$2,2)<6,COUNTIF('마스터'!$J$13:$J$27,AA$2)=0),$Q43/$U43,"") | AB43: =IF(AND($F43<>"",$V43<>"",AB$2>=$F43,AB$2<=$V43,WEEKDAY(AB$2,2)<6,COUNTIF('마스터'!$J$13:$J$27,AB$2)=0),$Q43/$U43,"") | AC43: =IF(AND($F43<>"",$V43<>"",AC$2>=$F43,AC$2<=$V43,WEEKDAY(AC$2,2)<6,COUNTIF('마스터'!$J$13:$J$27,AC$2)=0),$Q43/$U43,"") | AD43: =IF(AND($F43<>"",$V43<>"",AD$2>=$F43,AD$2<=$V43,WEEKDAY(AD$2,2)<6,COUNTIF('마스터'!$J$13:$J$27,AD$2)=0),$Q43/$U43,"") | AE43: =IF(AND($F43<>"",$V43<>"",AE$2>=$F43,AE$2<=$V43,WEEKDAY(AE$2,2)<6,COUNTIF('마스터'!$J$13:$J$27,AE$2)=0),$Q43/$U43,"") | AF43: =IF(AND($F43<>"",$V43<>"",AF$2>=$F43,AF$2<=$V43,WEEKDAY(AF$2,2)<6,COUNTIF('마스터'!$J$13:$J$27,AF$2)=0),$Q43/$U43,"") | AG43: =IF(AND($F43<>"",$V43<>"",AG$2>=$F43,AG$2<=$V43,WEEKDAY(AG$2,2)<6,COUNTIF('마스터'!$J$13:$J$27,AG$2)=0),$Q43/$U43,"") | ... BD43: =IF(AND($F43<>"",$V43<>"",BD$2>=$F43,BD$2<=$V43,WEEKDAY(BD$2,2)<6,COUNTIF('마스터'!$J$13:$J$27,BD$2)=0),$Q43/$U43,"")
