Workbook

Sheet 사용법
B2: AI 파이프라인 통합 리소스/스케줄 관리 시트 v7 (월별 탭 + 연간요약)
B3: 1월~12월 각각 별도 탭. 입력은 해당 월 탭에서. 연간요약이 12개 탭을 자동 집계.
B5: 색 표시
B6: 파랑 | C6: 해당 직군 정원(TO)의 80~100% 채워진 상태
B7: 보라 | C7: 정원(TO) 초과 - 조율 필요
B9: 1. 월별 탭
B10: 탭 구조 | C10: 1월~12월 탭이 각각 독립된 통합관리. 그 달 업무만 그 탭에 입력 - 리스트가 길어져도 달마다 분리되어 관리가 쉬움.
B11: 행 = 한 업무명 | C11: 영상 파이프라인 기준. 영상/이미지/기획(SB)이 각각 담당+MD 칸으로 붙음. 붙는 직군만 기입, 나머지 비움.
B12: 요청일 위치 | C12: 소재명 바로 오른쪽. 소재명+요청일은 스크롤해도 고정.
B13: 수량 | C13: 영상 수 / 사이즈베리 수 / 다국어베리 수 3개 분리.
B15: 2. 각 월 탭 - 일별 직군 TO 과부하
B16: 상단 4줄 | C16: 날짜 위 전체/영상/이미지/기획 TO 줄. 각 날짜 셀 = 그날 그 직군 총 MD. 정원 대비 파랑(참)/보라(오버).
B17: 간트 | C17: 각 소재 셀에 합계MD를 요청~예상완료 영업일에 균등 분산(숫자). 주말 음영.
B19: 3. 연간요약
B20: 월별/누적 | C20: 12개 월 탭에서 직접 집계. 매월 누적(1월부터 running), 상반기(1-6)/하반기(7-12)/연간 합계, 월별 가동률.
B21: 팀/타이틀 | C21: 고객팀x유형 연간 건수, 게임타이틀별 연간 MD - 12개 탭 합산.
B22: 새 연도 시작 | C22: 마스터의 연도만 바꾸면 전체 탭의 날짜가 그 연도 기준으로 재계산.

Sheet 마스터
A1: 마스터 / 기준정보
A2: 게임 타이틀 (25) | C2: 고객팀 | E2: 유형 | G2: 상태 | I2: 운영 파라미터
A3: 뱀피르 | C3: 마케팅1팀 | E3: 영상 | G3: 대기 | I3: 연도 | J3: 2026
A4: RF 글로벌 | C4: 마케팅2팀 | E4: 영상+이미지 | G4: 진행 | I4: 월 가동일수 | J4: 20
A5: SOL 인챈트 | C5: 마케팅3팀 | E5: 이미지 | G5: 검수 | I5: 1일=MD | J5: 1
A6: 스톤에이지펫월드 | C6: 마케팅4팀 | E6: 베리 | G6: 완료
A7: 칠대죄오리진 | C7: 기타 | E7: 기획 | I7: 직군 일 TO 정원
A8: 세나리버스 | E8: 기타 | I8: 영상 | J8: 6
A9: 몬길 | I9: 이미지 | J9: 8
A10: 왕겜(GOT) | I10: 기획 | J10: 3
A11: 몬스터길들이기
A12: 라이즈오브
A30: 비나(VINA) 운영 시나리오 (참고)
A31: 방안 1 | C31: 기획+내부디자인+비나영상 - 비나 영상공수는 영상실 매출 귀속
A32: 방안 2 | C32: 비나=사이즈베리만 - 영상 베리는 디자인 흡수
A33: 방안 3 | C33: 비나 이미지TO 추가발주+추가비용
A34: 방안 4 | C34: 본사 프로세스 통합(이미지TO 추가X)

Sheet 연간요약
B2: 연간요약 - 월별 / 상하반기 / 매월 누적
B3: 각 월 탭에서 직접 집계. 입력은 해당 월 탭에서.
B5: 월 | C5: 영상MD | D5: 이미지MD | E5: 기획MD | F5: 합계MD | G5: 누적MD | H5: 영상수 | I5: 사이즈베리 | J5: 다국어베리 | K5: 가동률
B6: 1월 | C6: =SUM('1월'!L8:L57) | D6: =SUM('1월'!N8:N57) | E6: =SUM('1월'!P8:P57) | F6: =SUM(C6:E6) | G6: =SUM($F$6:F6) | H6: =SUM('1월'!H8:H57) | I6: =SUM('1월'!I8:I57) | J6: =SUM('1월'!J8:J57) | K6: =IFERROR(F6/(SUM('마스터'!$J$8:$J$10)*'마스터'!$J$4),0)
B7: 2월 | C7: =SUM('2월'!L8:L57) | D7: =SUM('2월'!N8:N57) | E7: =SUM('2월'!P8:P57) | F7: =SUM(C7:E7) | G7: =SUM($F$6:F7) | H7: =SUM('2월'!H8:H57) | I7: =SUM('2월'!I8:I57) | J7: =SUM('2월'!J8:J57) | K7: =IFERROR(F7/(SUM('마스터'!$J$8:$J$10)*'마스터'!$J$4),0)
B8: 3월 | C8: =SUM('3월'!L8:L57) | D8: =SUM('3월'!N8:N57) | E8: =SUM('3월'!P8:P57) | F8: =SUM(C8:E8) | G8: =SUM($F$6:F8) | H8: =SUM('3월'!H8:H57) | I8: =SUM('3월'!I8:I57) | J8: =SUM('3월'!J8:J57) | K8: =IFERROR(F8/(SUM('마스터'!$J$8:$J$10)*'마스터'!$J$4),0)
B9: 4월 | C9: =SUM('4월'!L8:L57) | D9: =SUM('4월'!N8:N57) | E9: =SUM('4월'!P8:P57) | F9: =SUM(C9:E9) | G9: =SUM($F$6:F9) | H9: =SUM('4월'!H8:H57) | I9: =SUM('4월'!I8:I57) | J9: =SUM('4월'!J8:J57) | K9: =IFERROR(F9/(SUM('마스터'!$J$8:$J$10)*'마스터'!$J$4),0)
B10: 5월 | C10: =SUM('5월'!L8:L57) | D10: =SUM('5월'!N8:N57) | E10: =SUM('5월'!P8:P57) | F10: =SUM(C10:E10) | G10: =SUM($F$6:F10) | H10: =SUM('5월'!H8:H57) | I10: =SUM('5월'!I8:I57) | J10: =SUM('5월'!J8:J57) | K10: =IFERROR(F10/(SUM('마스터'!$J$8:$J$10)*'마스터'!$J$4),0)
B11: 6월 | C11: =SUM('6월'!L8:L57) | D11: =SUM('6월'!N8:N57) | E11: =SUM('6월'!P8:P57) | F11: =SUM(C11:E11) | G11: =SUM($F$6:F11) | H11: =SUM('6월'!H8:H57) | I11: =SUM('6월'!I8:I57) | J11: =SUM('6월'!J8:J57) | K11: =IFERROR(F11/(SUM('마스터'!$J$8:$J$10)*'마스터'!$J$4),0)
B12: 7월 | C12: =SUM('7월'!L8:L57) | D12: =SUM('7월'!N8:N57) | E12: =SUM('7월'!P8:P57) | F12: =SUM(C12:E12) | G12: =SUM($F$6:F12) | H12: =SUM('7월'!H8:H57) | I12: =SUM('7월'!I8:I57) | J12: =SUM('7월'!J8:J57) | K12: =IFERROR(F12/(SUM('마스터'!$J$8:$J$10)*'마스터'!$J$4),0)
B13: 8월 | C13: =SUM('8월'!L8:L57) | D13: =SUM('8월'!N8:N57) | E13: =SUM('8월'!P8:P57) | F13: =SUM(C13:E13) | G13: =SUM($F$6:F13) | H13: =SUM('8월'!H8:H57) | I13: =SUM('8월'!I8:I57) | J13: =SUM('8월'!J8:J57) | K13: =IFERROR(F13/(SUM('마스터'!$J$8:$J$10)*'마스터'!$J$4),0)
B14: 9월 | C14: =SUM('9월'!L8:L57) | D14: =SUM('9월'!N8:N57) | E14: =SUM('9월'!P8:P57) | F14: =SUM(C14:E14) | G14: =SUM($F$6:F14) | H14: =SUM('9월'!H8:H57) | I14: =SUM('9월'!I8:I57) | J14: =SUM('9월'!J8:J57) | K14: =IFERROR(F14/(SUM('마스터'!$J$8:$J$10)*'마스터'!$J$4),0)
B15: 10월 | C15: =SUM('10월'!L8:L57) | D15: =SUM('10월'!N8:N57) | E15: =SUM('10월'!P8:P57) | F15: =SUM(C15:E15) | G15: =SUM($F$6:F15) | H15: =SUM('10월'!H8:H57) | I15: =SUM('10월'!I8:I57) | J15: =SUM('10월'!J8:J57) | K15: =IFERROR(F15/(SUM('마스터'!$J$8:$J$10)*'마스터'!$J$4),0)
B16: 11월 | C16: =SUM('11월'!L8:L57) | D16: =SUM('11월'!N8:N57) | E16: =SUM('11월'!P8:P57) | F16: =SUM(C16:E16) | G16: =SUM($F$6:F16) | H16: =SUM('11월'!H8:H57) | I16: =SUM('11월'!I8:I57) | J16: =SUM('11월'!J8:J57) | K16: =IFERROR(F16/(SUM('마스터'!$J$8:$J$10)*'마스터'!$J$4),0)
B17: 12월 | C17: =SUM('12월'!L8:L57) | D17: =SUM('12월'!N8:N57) | E17: =SUM('12월'!P8:P57) | F17: =SUM(C17:E17) | G17: =SUM($F$6:F17) | H17: =SUM('12월'!H8:H57) | I17: =SUM('12월'!I8:I57) | J17: =SUM('12월'!J8:J57) | K17: =IFERROR(F17/(SUM('마스터'!$J$8:$J$10)*'마스터'!$J$4),0)
B18: 상반기(1-6) | C18: =SUM(C6:C11) | D18: =SUM(D6:D11) | E18: =SUM(E6:E11) | F18: =SUM(F6:F11) | H18: =SUM(H6:H11) | I18: =SUM(I6:I11) | J18: =SUM(J6:J11) | K18: =IFERROR(F18/(SUM('마스터'!$J$8:$J$10)*'마스터'!$J$4*(11-6+1)),0)
B19: 하반기(7-12) | C19: =SUM(C12:C17) | D19: =SUM(D12:D17) | E19: =SUM(E12:E17) | F19: =SUM(F12:F17) | H19: =SUM(H12:H17) | I19: =SUM(I12:I17) | J19: =SUM(J12:J17) | K19: =IFERROR(F19/(SUM('마스터'!$J$8:$J$10)*'마스터'!$J$4*(17-12+1)),0)
B20: 연간 합계 | C20: =SUM(C6:C17) | D20: =SUM(D6:D17) | E20: =SUM(E6:E17) | F20: =SUM(F6:F17) | H20: =SUM(H6:H17) | I20: =SUM(I6:I17) | J20: =SUM(J6:J17) | K20: =IFERROR(F20/(SUM('마스터'!$J$8:$J$10)*'마스터'!$J$4*(17-6+1)),0)
B23: 고객팀 x 유형 (연간 건수) | H23: 게임타이틀별 (연간)
B24: 팀\유형 | C24: 영상 | D24: 이미지 | E24: 기획 | H24: 타이틀 | I24: 건수 | J24: MD
B25: 마케팅1팀 | C25: =COUNTIFS('1월'!$C$8:$C$57,$B25,'1월'!$D$8:$D$57,C$24)+COUNTIFS('2월'!$C$8:$C$57,$B25,'2월'!$D$8:$D$57,C$24)+COUNTIFS('3월'!$C$8:$C$57,$B25,'3월'!$D$8:$D$57,C$24)+COUNTIFS('4월'!$C$8:$C$57,$B25,'4월'!$D$8:$D$57,C$24)+COUNTIFS('5월'!$C$8:$C$57,$B25,'5월'!$D$8:$D$57,C$24)+COUNTIFS('6월'!$C$8:$C$57,$B25,'6월'!$D$8:$D$57,C$24)+COUNTIFS('7월'!$C$8:$C$57,$B25,'7월'!$D$8:$D$57,C$24)+COUNTIFS('8월'!$C$8:$C$57,$B25,'8월'!$D$8:$D$57,C$24)+COUNTIFS('9월'!$C$8:$C$57,$B25,'9월'!$D$8:$D$57,C$24)+COUNTIFS('10월'!$C$8:$C$57,$B25,'10월'!$D$8:$D$57,C$24)+COUNTIFS('11월'!$C$8:$C$57,$B25,'11월'!$D$8:$D$57,C$24)+COUNTIFS('12월'!$C$8:$C$57,$B25,'12월'!$D$8:$D$57,C$24) | D25: =COUNTIFS('1월'!$C$8:$C$57,$B25,'1월'!$D$8:$D$57,D$24)+COUNTIFS('2월'!$C$8:$C$57,$B25,'2월'!$D$8:$D$57,D$24)+COUNTIFS('3월'!$C$8:$C$57,$B25,'3월'!$D$8:$D$57,D$24)+COUNTIFS('4월'!$C$8:$C$57,$B25,'4월'!$D$8:$D$57,D$24)+COUNTIFS('5월'!$C$8:$C$57,$B25,'5월'!$D$8:$D$57,D$24)+COUNTIFS('6월'!$C$8:$C$57,$B25,'6월'!$D$8:$D$57,D$24)+COUNTIFS('7월'!$C$8:$C$57,$B25,'7월'!$D$8:$D$57,D$24)+COUNTIFS('8월'!$C$8:$C$57,$B25,'8월'!$D$8:$D$57,D$24)+COUNTIFS('9월'!$C$8:$C$57,$B25,'9월'!$D$8:$D$57,D$24)+COUNTIFS('10월'!$C$8:$C$57,$B25,'10월'!$D$8:$D$57,D$24)+COUNTIFS('11월'!$C$8:$C$57,$B25,'11월'!$D$8:$D$57,D$24)+COUNTIFS('12월'!$C$8:$C$57,$B25,'12월'!$D$8:$D$57,D$24) | E25: =COUNTIFS('1월'!$C$8:$C$57,$B25,'1월'!$D$8:$D$57,E$24)+COUNTIFS('2월'!$C$8:$C$57,$B25,'2월'!$D$8:$D$57,E$24)+COUNTIFS('3월'!$C$8:$C$57,$B25,'3월'!$D$8:$D$57,E$24)+COUNTIFS('4월'!$C$8:$C$57,$B25,'4월'!$D$8:$D$57,E$24)+COUNTIFS('5월'!$C$8:$C$57,$B25,'5월'!$D$8:$D$57,E$24)+COUNTIFS('6월'!$C$8:$C$57,$B25,'6월'!$D$8:$D$57,E$24)+COUNTIFS('7월'!$C$8:$C$57,$B25,'7월'!$D$8:$D$57,E$24)+COUNTIFS('8월'!$C$8:$C$57,$B25,'8월'!$D$8:$D$57,E$24)+COUNTIFS('9월'!$C$8:$C$57,$B25,'9월'!$D$8:$D$57,E$24)+COUNTIFS('10월'!$C$8:$C$57,$B25,'10월'!$D$8:$D$57,E$24)+COUNTIFS('11월'!$C$8:$C$57,$B25,'11월'!$D$8:$D$57,E$24)+COUNTIFS('12월'!$C$8:$C$57,$B25,'12월'!$D$8:$D$57,E$24) | H25: 뱀피르 | I25: =COUNTIF('1월'!$B$8:$B$57,$H25)+COUNTIF('2월'!$B$8:$B$57,$H25)+COUNTIF('3월'!$B$8:$B$57,$H25)+COUNTIF('4월'!$B$8:$B$57,$H25)+COUNTIF('5월'!$B$8:$B$57,$H25)+COUNTIF('6월'!$B$8:$B$57,$H25)+COUNTIF('7월'!$B$8:$B$57,$H25)+COUNTIF('8월'!$B$8:$B$57,$H25)+COUNTIF('9월'!$B$8:$B$57,$H25)+COUNTIF('10월'!$B$8:$B$57,$H25)+COUNTIF('11월'!$B$8:$B$57,$H25)+COUNTIF('12월'!$B$8:$B$57,$H25) | J25: =SUMIF('1월'!$B$8:$B$57,$H25,'1월'!$Q$8:$Q$57)+SUMIF('2월'!$B$8:$B$57,$H25,'2월'!$Q$8:$Q$57)+SUMIF('3월'!$B$8:$B$57,$H25,'3월'!$Q$8:$Q$57)+SUMIF('4월'!$B$8:$B$57,$H25,'4월'!$Q$8:$Q$57)+SUMIF('5월'!$B$8:$B$57,$H25,'5월'!$Q$8:$Q$57)+SUMIF('6월'!$B$8:$B$57,$H25,'6월'!$Q$8:$Q$57)+SUMIF('7월'!$B$8:$B$57,$H25,'7월'!$Q$8:$Q$57)+SUMIF('8월'!$B$8:$B$57,$H25,'8월'!$Q$8:$Q$57)+SUMIF('9월'!$B$8:$B$57,$H25,'9월'!$Q$8:$Q$57)+SUMIF('10월'!$B$8:$B$57,$H25,'10월'!$Q$8:$Q$57)+SUMIF('11월'!$B$8:$B$57,$H25,'11월'!$Q$8:$Q$57)+SUMIF('12월'!$B$8:$B$57,$H25,'12월'!$Q$8:$Q$57)
B26: 마케팅2팀 | C26: =COUNTIFS('1월'!$C$8:$C$57,$B26,'1월'!$D$8:$D$57,C$24)+COUNTIFS('2월'!$C$8:$C$57,$B26,'2월'!$D$8:$D$57,C$24)+COUNTIFS('3월'!$C$8:$C$57,$B26,'3월'!$D$8:$D$57,C$24)+COUNTIFS('4월'!$C$8:$C$57,$B26,'4월'!$D$8:$D$57,C$24)+COUNTIFS('5월'!$C$8:$C$57,$B26,'5월'!$D$8:$D$57,C$24)+COUNTIFS('6월'!$C$8:$C$57,$B26,'6월'!$D$8:$D$57,C$24)+COUNTIFS('7월'!$C$8:$C$57,$B26,'7월'!$D$8:$D$57,C$24)+COUNTIFS('8월'!$C$8:$C$57,$B26,'8월'!$D$8:$D$57,C$24)+COUNTIFS('9월'!$C$8:$C$57,$B26,'9월'!$D$8:$D$57,C$24)+COUNTIFS('10월'!$C$8:$C$57,$B26,'10월'!$D$8:$D$57,C$24)+COUNTIFS('11월'!$C$8:$C$57,$B26,'11월'!$D$8:$D$57,C$24)+COUNTIFS('12월'!$C$8:$C$57,$B26,'12월'!$D$8:$D$57,C$24) | D26: =COUNTIFS('1월'!$C$8:$C$57,$B26,'1월'!$D$8:$D$57,D$24)+COUNTIFS('2월'!$C$8:$C$57,$B26,'2월'!$D$8:$D$57,D$24)+COUNTIFS('3월'!$C$8:$C$57,$B26,'3월'!$D$8:$D$57,D$24)+COUNTIFS('4월'!$C$8:$C$57,$B26,'4월'!$D$8:$D$57,D$24)+COUNTIFS('5월'!$C$8:$C$57,$B26,'5월'!$D$8:$D$57,D$24)+COUNTIFS('6월'!$C$8:$C$57,$B26,'6월'!$D$8:$D$57,D$24)+COUNTIFS('7월'!$C$8:$C$57,$B26,'7월'!$D$8:$D$57,D$24)+COUNTIFS('8월'!$C$8:$C$57,$B26,'8월'!$D$8:$D$57,D$24)+COUNTIFS('9월'!$C$8:$C$57,$B26,'9월'!$D$8:$D$57,D$24)+COUNTIFS('10월'!$C$8:$C$57,$B26,'10월'!$D$8:$D$57,D$24)+COUNTIFS('11월'!$C$8:$C$57,$B26,'11월'!$D$8:$D$57,D$24)+COUNTIFS('12월'!$C$8:$C$57,$B26,'12월'!$D$8:$D$57,D$24) | E26: =COUNTIFS('1월'!$C$8:$C$57,$B26,'1월'!$D$8:$D$57,E$24)+COUNTIFS('2월'!$C$8:$C$57,$B26,'2월'!$D$8:$D$57,E$24)+COUNTIFS('3월'!$C$8:$C$57,$B26,'3월'!$D$8:$D$57,E$24)+COUNTIFS('4월'!$C$8:$C$57,$B26,'4월'!$D$8:$D$57,E$24)+COUNTIFS('5월'!$C$8:$C$57,$B26,'5월'!$D$8:$D$57,E$24)+COUNTIFS('6월'!$C$8:$C$57,$B26,'6월'!$D$8:$D$57,E$24)+COUNTIFS('7월'!$C$8:$C$57,$B26,'7월'!$D$8:$D$57,E$24)+COUNTIFS('8월'!$C$8:$C$57,$B26,'8월'!$D$8:$D$57,E$24)+COUNTIFS('9월'!$C$8:$C$57,$B26,'9월'!$D$8:$D$57,E$24)+COUNTIFS('10월'!$C$8:$C$57,$B26,'10월'!$D$8:$D$57,E$24)+COUNTIFS('11월'!$C$8:$C$57,$B26,'11월'!$D$8:$D$57,E$24)+COUNTIFS('12월'!$C$8:$C$57,$B26,'12월'!$D$8:$D$57,E$24) | H26: RF 글로벌 | I26: =COUNTIF('1월'!$B$8:$B$57,$H26)+COUNTIF('2월'!$B$8:$B$57,$H26)+COUNTIF('3월'!$B$8:$B$57,$H26)+COUNTIF('4월'!$B$8:$B$57,$H26)+COUNTIF('5월'!$B$8:$B$57,$H26)+COUNTIF('6월'!$B$8:$B$57,$H26)+COUNTIF('7월'!$B$8:$B$57,$H26)+COUNTIF('8월'!$B$8:$B$57,$H26)+COUNTIF('9월'!$B$8:$B$57,$H26)+COUNTIF('10월'!$B$8:$B$57,$H26)+COUNTIF('11월'!$B$8:$B$57,$H26)+COUNTIF('12월'!$B$8:$B$57,$H26) | J26: =SUMIF('1월'!$B$8:$B$57,$H26,'1월'!$Q$8:$Q$57)+SUMIF('2월'!$B$8:$B$57,$H26,'2월'!$Q$8:$Q$57)+SUMIF('3월'!$B$8:$B$57,$H26,'3월'!$Q$8:$Q$57)+SUMIF('4월'!$B$8:$B$57,$H26,'4월'!$Q$8:$Q$57)+SUMIF('5월'!$B$8:$B$57,$H26,'5월'!$Q$8:$Q$57)+SUMIF('6월'!$B$8:$B$57,$H26,'6월'!$Q$8:$Q$57)+SUMIF('7월'!$B$8:$B$57,$H26,'7월'!$Q$8:$Q$57)+SUMIF('8월'!$B$8:$B$57,$H26,'8월'!$Q$8:$Q$57)+SUMIF('9월'!$B$8:$B$57,$H26,'9월'!$Q$8:$Q$57)+SUMIF('10월'!$B$8:$B$57,$H26,'10월'!$Q$8:$Q$57)+SUMIF('11월'!$B$8:$B$57,$H26,'11월'!$Q$8:$Q$57)+SUMIF('12월'!$B$8:$B$57,$H26,'12월'!$Q$8:$Q$57)
B27: 마케팅3팀 | C27: =COUNTIFS('1월'!$C$8:$C$57,$B27,'1월'!$D$8:$D$57,C$24)+COUNTIFS('2월'!$C$8:$C$57,$B27,'2월'!$D$8:$D$57,C$24)+COUNTIFS('3월'!$C$8:$C$57,$B27,'3월'!$D$8:$D$57,C$24)+COUNTIFS('4월'!$C$8:$C$57,$B27,'4월'!$D$8:$D$57,C$24)+COUNTIFS('5월'!$C$8:$C$57,$B27,'5월'!$D$8:$D$57,C$24)+COUNTIFS('6월'!$C$8:$C$57,$B27,'6월'!$D$8:$D$57,C$24)+COUNTIFS('7월'!$C$8:$C$57,$B27,'7월'!$D$8:$D$57,C$24)+COUNTIFS('8월'!$C$8:$C$57,$B27,'8월'!$D$8:$D$57,C$24)+COUNTIFS('9월'!$C$8:$C$57,$B27,'9월'!$D$8:$D$57,C$24)+COUNTIFS('10월'!$C$8:$C$57,$B27,'10월'!$D$8:$D$57,C$24)+COUNTIFS('11월'!$C$8:$C$57,$B27,'11월'!$D$8:$D$57,C$24)+COUNTIFS('12월'!$C$8:$C$57,$B27,'12월'!$D$8:$D$57,C$24) | D27: =COUNTIFS('1월'!$C$8:$C$57,$B27,'1월'!$D$8:$D$57,D$24)+COUNTIFS('2월'!$C$8:$C$57,$B27,'2월'!$D$8:$D$57,D$24)+COUNTIFS('3월'!$C$8:$C$57,$B27,'3월'!$D$8:$D$57,D$24)+COUNTIFS('4월'!$C$8:$C$57,$B27,'4월'!$D$8:$D$57,D$24)+COUNTIFS('5월'!$C$8:$C$57,$B27,'5월'!$D$8:$D$57,D$24)+COUNTIFS('6월'!$C$8:$C$57,$B27,'6월'!$D$8:$D$57,D$24)+COUNTIFS('7월'!$C$8:$C$57,$B27,'7월'!$D$8:$D$57,D$24)+COUNTIFS('8월'!$C$8:$C$57,$B27,'8월'!$D$8:$D$57,D$24)+COUNTIFS('9월'!$C$8:$C$57,$B27,'9월'!$D$8:$D$57,D$24)+COUNTIFS('10월'!$C$8:$C$57,$B27,'10월'!$D$8:$D$57,D$24)+COUNTIFS('11월'!$C$8:$C$57,$B27,'11월'!$D$8:$D$57,D$24)+COUNTIFS('12월'!$C$8:$C$57,$B27,'12월'!$D$8:$D$57,D$24) | E27: =COUNTIFS('1월'!$C$8:$C$57,$B27,'1월'!$D$8:$D$57,E$24)+COUNTIFS('2월'!$C$8:$C$57,$B27,'2월'!$D$8:$D$57,E$24)+COUNTIFS('3월'!$C$8:$C$57,$B27,'3월'!$D$8:$D$57,E$24)+COUNTIFS('4월'!$C$8:$C$57,$B27,'4월'!$D$8:$D$57,E$24)+COUNTIFS('5월'!$C$8:$C$57,$B27,'5월'!$D$8:$D$57,E$24)+COUNTIFS('6월'!$C$8:$C$57,$B27,'6월'!$D$8:$D$57,E$24)+COUNTIFS('7월'!$C$8:$C$57,$B27,'7월'!$D$8:$D$57,E$24)+COUNTIFS('8월'!$C$8:$C$57,$B27,'8월'!$D$8:$D$57,E$24)+COUNTIFS('9월'!$C$8:$C$57,$B27,'9월'!$D$8:$D$57,E$24)+COUNTIFS('10월'!$C$8:$C$57,$B27,'10월'!$D$8:$D$57,E$24)+COUNTIFS('11월'!$C$8:$C$57,$B27,'11월'!$D$8:$D$57,E$24)+COUNTIFS('12월'!$C$8:$C$57,$B27,'12월'!$D$8:$D$57,E$24) | H27: SOL 인챈트 | I27: =COUNTIF('1월'!$B$8:$B$57,$H27)+COUNTIF('2월'!$B$8:$B$57,$H27)+COUNTIF('3월'!$B$8:$B$57,$H27)+COUNTIF('4월'!$B$8:$B$57,$H27)+COUNTIF('5월'!$B$8:$B$57,$H27)+COUNTIF('6월'!$B$8:$B$57,$H27)+COUNTIF('7월'!$B$8:$B$57,$H27)+COUNTIF('8월'!$B$8:$B$57,$H27)+COUNTIF('9월'!$B$8:$B$57,$H27)+COUNTIF('10월'!$B$8:$B$57,$H27)+COUNTIF('11월'!$B$8:$B$57,$H27)+COUNTIF('12월'!$B$8:$B$57,$H27) | J27: =SUMIF('1월'!$B$8:$B$57,$H27,'1월'!$Q$8:$Q$57)+SUMIF('2월'!$B$8:$B$57,$H27,'2월'!$Q$8:$Q$57)+SUMIF('3월'!$B$8:$B$57,$H27,'3월'!$Q$8:$Q$57)+SUMIF('4월'!$B$8:$B$57,$H27,'4월'!$Q$8:$Q$57)+SUMIF('5월'!$B$8:$B$57,$H27,'5월'!$Q$8:$Q$57)+SUMIF('6월'!$B$8:$B$57,$H27,'6월'!$Q$8:$Q$57)+SUMIF('7월'!$B$8:$B$57,$H27,'7월'!$Q$8:$Q$57)+SUMIF('8월'!$B$8:$B$57,$H27,'8월'!$Q$8:$Q$57)+SUMIF('9월'!$B$8:$B$57,$H27,'9월'!$Q$8:$Q$57)+SUMIF('10월'!$B$8:$B$57,$H27,'10월'!$Q$8:$Q$57)+SUMIF('11월'!$B$8:$B$57,$H27,'11월'!$Q$8:$Q$57)+SUMIF('12월'!$B$8:$B$57,$H27,'12월'!$Q$8:$Q$57)
B28: 마케팅4팀 | C28: =COUNTIFS('1월'!$C$8:$C$57,$B28,'1월'!$D$8:$D$57,C$24)+COUNTIFS('2월'!$C$8:$C$57,$B28,'2월'!$D$8:$D$57,C$24)+COUNTIFS('3월'!$C$8:$C$57,$B28,'3월'!$D$8:$D$57,C$24)+COUNTIFS('4월'!$C$8:$C$57,$B28,'4월'!$D$8:$D$57,C$24)+COUNTIFS('5월'!$C$8:$C$57,$B28,'5월'!$D$8:$D$57,C$24)+COUNTIFS('6월'!$C$8:$C$57,$B28,'6월'!$D$8:$D$57,C$24)+COUNTIFS('7월'!$C$8:$C$57,$B28,'7월'!$D$8:$D$57,C$24)+COUNTIFS('8월'!$C$8:$C$57,$B28,'8월'!$D$8:$D$57,C$24)+COUNTIFS('9월'!$C$8:$C$57,$B28,'9월'!$D$8:$D$57,C$24)+COUNTIFS('10월'!$C$8:$C$57,$B28,'10월'!$D$8:$D$57,C$24)+COUNTIFS('11월'!$C$8:$C$57,$B28,'11월'!$D$8:$D$57,C$24)+COUNTIFS('12월'!$C$8:$C$57,$B28,'12월'!$D$8:$D$57,C$24) | D28: =COUNTIFS('1월'!$C$8:$C$57,$B28,'1월'!$D$8:$D$57,D$24)+COUNTIFS('2월'!$C$8:$C$57,$B28,'2월'!$D$8:$D$57,D$24)+COUNTIFS('3월'!$C$8:$C$57,$B28,'3월'!$D$8:$D$57,D$24)+COUNTIFS('4월'!$C$8:$C$57,$B28,'4월'!$D$8:$D$57,D$24)+COUNTIFS('5월'!$C$8:$C$57,$B28,'5월'!$D$8:$D$57,D$24)+COUNTIFS('6월'!$C$8:$C$57,$B28,'6월'!$D$8:$D$57,D$24)+COUNTIFS('7월'!$C$8:$C$57,$B28,'7월'!$D$8:$D$57,D$24)+COUNTIFS('8월'!$C$8:$C$57,$B28,'8월'!$D$8:$D$57,D$24)+COUNTIFS('9월'!$C$8:$C$57,$B28,'9월'!$D$8:$D$57,D$24)+COUNTIFS('10월'!$C$8:$C$57,$B28,'10월'!$D$8:$D$57,D$24)+COUNTIFS('11월'!$C$8:$C$57,$B28,'11월'!$D$8:$D$57,D$24)+COUNTIFS('12월'!$C$8:$C$57,$B28,'12월'!$D$8:$D$57,D$24) | E28: =COUNTIFS('1월'!$C$8:$C$57,$B28,'1월'!$D$8:$D$57,E$24)+COUNTIFS('2월'!$C$8:$C$57,$B28,'2월'!$D$8:$D$57,E$24)+COUNTIFS('3월'!$C$8:$C$57,$B28,'3월'!$D$8:$D$57,E$24)+COUNTIFS('4월'!$C$8:$C$57,$B28,'4월'!$D$8:$D$57,E$24)+COUNTIFS('5월'!$C$8:$C$57,$B28,'5월'!$D$8:$D$57,E$24)+COUNTIFS('6월'!$C$8:$C$57,$B28,'6월'!$D$8:$D$57,E$24)+COUNTIFS('7월'!$C$8:$C$57,$B28,'7월'!$D$8:$D$57,E$24)+COUNTIFS('8월'!$C$8:$C$57,$B28,'8월'!$D$8:$D$57,E$24)+COUNTIFS('9월'!$C$8:$C$57,$B28,'9월'!$D$8:$D$57,E$24)+COUNTIFS('10월'!$C$8:$C$57,$B28,'10월'!$D$8:$D$57,E$24)+COUNTIFS('11월'!$C$8:$C$57,$B28,'11월'!$D$8:$D$57,E$24)+COUNTIFS('12월'!$C$8:$C$57,$B28,'12월'!$D$8:$D$57,E$24) | H28: 스톤에이지펫월드 | I28: =COUNTIF('1월'!$B$8:$B$57,$H28)+COUNTIF('2월'!$B$8:$B$57,$H28)+COUNTIF('3월'!$B$8:$B$57,$H28)+COUNTIF('4월'!$B$8:$B$57,$H28)+COUNTIF('5월'!$B$8:$B$57,$H28)+COUNTIF('6월'!$B$8:$B$57,$H28)+COUNTIF('7월'!$B$8:$B$57,$H28)+COUNTIF('8월'!$B$8:$B$57,$H28)+COUNTIF('9월'!$B$8:$B$57,$H28)+COUNTIF('10월'!$B$8:$B$57,$H28)+COUNTIF('11월'!$B$8:$B$57,$H28)+COUNTIF('12월'!$B$8:$B$57,$H28) | J28: =SUMIF('1월'!$B$8:$B$57,$H28,'1월'!$Q$8:$Q$57)+SUMIF('2월'!$B$8:$B$57,$H28,'2월'!$Q$8:$Q$57)+SUMIF('3월'!$B$8:$B$57,$H28,'3월'!$Q$8:$Q$57)+SUMIF('4월'!$B$8:$B$57,$H28,'4월'!$Q$8:$Q$57)+SUMIF('5월'!$B$8:$B$57,$H28,'5월'!$Q$8:$Q$57)+SUMIF('6월'!$B$8:$B$57,$H28,'6월'!$Q$8:$Q$57)+SUMIF('7월'!$B$8:$B$57,$H28,'7월'!$Q$8:$Q$57)+SUMIF('8월'!$B$8:$B$57,$H28,'8월'!$Q$8:$Q$57)+SUMIF('9월'!$B$8:$B$57,$H28,'9월'!$Q$8:$Q$57)+SUMIF('10월'!$B$8:$B$57,$H28,'10월'!$Q$8:$Q$57)+SUMIF('11월'!$B$8:$B$57,$H28,'11월'!$Q$8:$Q$57)+SUMIF('12월'!$B$8:$B$57,$H28,'12월'!$Q$8:$Q$57)
B29: 기타 | C29: =COUNTIFS('1월'!$C$8:$C$57,$B29,'1월'!$D$8:$D$57,C$24)+COUNTIFS('2월'!$C$8:$C$57,$B29,'2월'!$D$8:$D$57,C$24)+COUNTIFS('3월'!$C$8:$C$57,$B29,'3월'!$D$8:$D$57,C$24)+COUNTIFS('4월'!$C$8:$C$57,$B29,'4월'!$D$8:$D$57,C$24)+COUNTIFS('5월'!$C$8:$C$57,$B29,'5월'!$D$8:$D$57,C$24)+COUNTIFS('6월'!$C$8:$C$57,$B29,'6월'!$D$8:$D$57,C$24)+COUNTIFS('7월'!$C$8:$C$57,$B29,'7월'!$D$8:$D$57,C$24)+COUNTIFS('8월'!$C$8:$C$57,$B29,'8월'!$D$8:$D$57,C$24)+COUNTIFS('9월'!$C$8:$C$57,$B29,'9월'!$D$8:$D$57,C$24)+COUNTIFS('10월'!$C$8:$C$57,$B29,'10월'!$D$8:$D$57,C$24)+COUNTIFS('11월'!$C$8:$C$57,$B29,'11월'!$D$8:$D$57,C$24)+COUNTIFS('12월'!$C$8:$C$57,$B29,'12월'!$D$8:$D$57,C$24) | D29: =COUNTIFS('1월'!$C$8:$C$57,$B29,'1월'!$D$8:$D$57,D$24)+COUNTIFS('2월'!$C$8:$C$57,$B29,'2월'!$D$8:$D$57,D$24)+COUNTIFS('3월'!$C$8:$C$57,$B29,'3월'!$D$8:$D$57,D$24)+COUNTIFS('4월'!$C$8:$C$57,$B29,'4월'!$D$8:$D$57,D$24)+COUNTIFS('5월'!$C$8:$C$57,$B29,'5월'!$D$8:$D$57,D$24)+COUNTIFS('6월'!$C$8:$C$57,$B29,'6월'!$D$8:$D$57,D$24)+COUNTIFS('7월'!$C$8:$C$57,$B29,'7월'!$D$8:$D$57,D$24)+COUNTIFS('8월'!$C$8:$C$57,$B29,'8월'!$D$8:$D$57,D$24)+COUNTIFS('9월'!$C$8:$C$57,$B29,'9월'!$D$8:$D$57,D$24)+COUNTIFS('10월'!$C$8:$C$57,$B29,'10월'!$D$8:$D$57,D$24)+COUNTIFS('11월'!$C$8:$C$57,$B29,'11월'!$D$8:$D$57,D$24)+COUNTIFS('12월'!$C$8:$C$57,$B29,'12월'!$D$8:$D$57,D$24) | E29: =COUNTIFS('1월'!$C$8:$C$57,$B29,'1월'!$D$8:$D$57,E$24)+COUNTIFS('2월'!$C$8:$C$57,$B29,'2월'!$D$8:$D$57,E$24)+COUNTIFS('3월'!$C$8:$C$57,$B29,'3월'!$D$8:$D$57,E$24)+COUNTIFS('4월'!$C$8:$C$57,$B29,'4월'!$D$8:$D$57,E$24)+COUNTIFS('5월'!$C$8:$C$57,$B29,'5월'!$D$8:$D$57,E$24)+COUNTIFS('6월'!$C$8:$C$57,$B29,'6월'!$D$8:$D$57,E$24)+COUNTIFS('7월'!$C$8:$C$57,$B29,'7월'!$D$8:$D$57,E$24)+COUNTIFS('8월'!$C$8:$C$57,$B29,'8월'!$D$8:$D$57,E$24)+COUNTIFS('9월'!$C$8:$C$57,$B29,'9월'!$D$8:$D$57,E$24)+COUNTIFS('10월'!$C$8:$C$57,$B29,'10월'!$D$8:$D$57,E$24)+COUNTIFS('11월'!$C$8:$C$57,$B29,'11월'!$D$8:$D$57,E$24)+COUNTIFS('12월'!$C$8:$C$57,$B29,'12월'!$D$8:$D$57,E$24) | H29: 칠대죄오리진 | I29: =COUNTIF('1월'!$B$8:$B$57,$H29)+COUNTIF('2월'!$B$8:$B$57,$H29)+COUNTIF('3월'!$B$8:$B$57,$H29)+COUNTIF('4월'!$B$8:$B$57,$H29)+COUNTIF('5월'!$B$8:$B$57,$H29)+COUNTIF('6월'!$B$8:$B$57,$H29)+COUNTIF('7월'!$B$8:$B$57,$H29)+COUNTIF('8월'!$B$8:$B$57,$H29)+COUNTIF('9월'!$B$8:$B$57,$H29)+COUNTIF('10월'!$B$8:$B$57,$H29)+COUNTIF('11월'!$B$8:$B$57,$H29)+COUNTIF('12월'!$B$8:$B$57,$H29) | J29: =SUMIF('1월'!$B$8:$B$57,$H29,'1월'!$Q$8:$Q$57)+SUMIF('2월'!$B$8:$B$57,$H29,'2월'!$Q$8:$Q$57)+SUMIF('3월'!$B$8:$B$57,$H29,'3월'!$Q$8:$Q$57)+SUMIF('4월'!$B$8:$B$57,$H29,'4월'!$Q$8:$Q$57)+SUMIF('5월'!$B$8:$B$57,$H29,'5월'!$Q$8:$Q$57)+SUMIF('6월'!$B$8:$B$57,$H29,'6월'!$Q$8:$Q$57)+SUMIF('7월'!$B$8:$B$57,$H29,'7월'!$Q$8:$Q$57)+SUMIF('8월'!$B$8:$B$57,$H29,'8월'!$Q$8:$Q$57)+SUMIF('9월'!$B$8:$B$57,$H29,'9월'!$Q$8:$Q$57)+SUMIF('10월'!$B$8:$B$57,$H29,'10월'!$Q$8:$Q$57)+SUMIF('11월'!$B$8:$B$57,$H29,'11월'!$Q$8:$Q$57)+SUMIF('12월'!$B$8:$B$57,$H29,'12월'!$Q$8:$Q$57)
H30: 세나리버스 | I30: =COUNTIF('1월'!$B$8:$B$57,$H30)+COUNTIF('2월'!$B$8:$B$57,$H30)+COUNTIF('3월'!$B$8:$B$57,$H30)+COUNTIF('4월'!$B$8:$B$57,$H30)+COUNTIF('5월'!$B$8:$B$57,$H30)+COUNTIF('6월'!$B$8:$B$57,$H30)+COUNTIF('7월'!$B$8:$B$57,$H30)+COUNTIF('8월'!$B$8:$B$57,$H30)+COUNTIF('9월'!$B$8:$B$57,$H30)+COUNTIF('10월'!$B$8:$B$57,$H30)+COUNTIF('11월'!$B$8:$B$57,$H30)+COUNTIF('12월'!$B$8:$B$57,$H30) | J30: =SUMIF('1월'!$B$8:$B$57,$H30,'1월'!$Q$8:$Q$57)+SUMIF('2월'!$B$8:$B$57,$H30,'2월'!$Q$8:$Q$57)+SUMIF('3월'!$B$8:$B$57,$H30,'3월'!$Q$8:$Q$57)+SUMIF('4월'!$B$8:$B$57,$H30,'4월'!$Q$8:$Q$57)+SUMIF('5월'!$B$8:$B$57,$H30,'5월'!$Q$8:$Q$57)+SUMIF('6월'!$B$8:$B$57,$H30,'6월'!$Q$8:$Q$57)+SUMIF('7월'!$B$8:$B$57,$H30,'7월'!$Q$8:$Q$57)+SUMIF('8월'!$B$8:$B$57,$H30,'8월'!$Q$8:$Q$57)+SUMIF('9월'!$B$8:$B$57,$H30,'9월'!$Q$8:$Q$57)+SUMIF('10월'!$B$8:$B$57,$H30,'10월'!$Q$8:$Q$57)+SUMIF('11월'!$B$8:$B$57,$H30,'11월'!$Q$8:$Q$57)+SUMIF('12월'!$B$8:$B$57,$H30,'12월'!$Q$8:$Q$57)
H31: 몬길 | I31: =COUNTIF('1월'!$B$8:$B$57,$H31)+COUNTIF('2월'!$B$8:$B$57,$H31)+COUNTIF('3월'!$B$8:$B$57,$H31)+COUNTIF('4월'!$B$8:$B$57,$H31)+COUNTIF('5월'!$B$8:$B$57,$H31)+COUNTIF('6월'!$B$8:$B$57,$H31)+COUNTIF('7월'!$B$8:$B$57,$H31)+COUNTIF('8월'!$B$8:$B$57,$H31)+COUNTIF('9월'!$B$8:$B$57,$H31)+COUNTIF('10월'!$B$8:$B$57,$H31)+COUNTIF('11월'!$B$8:$B$57,$H31)+COUNTIF('12월'!$B$8:$B$57,$H31) | J31: =SUMIF('1월'!$B$8:$B$57,$H31,'1월'!$Q$8:$Q$57)+SUMIF('2월'!$B$8:$B$57,$H31,'2월'!$Q$8:$Q$57)+SUMIF('3월'!$B$8:$B$57,$H31,'3월'!$Q$8:$Q$57)+SUMIF('4월'!$B$8:$B$57,$H31,'4월'!$Q$8:$Q$57)+SUMIF('5월'!$B$8:$B$57,$H31,'5월'!$Q$8:$Q$57)+SUMIF('6월'!$B$8:$B$57,$H31,'6월'!$Q$8:$Q$57)+SUMIF('7월'!$B$8:$B$57,$H31,'7월'!$Q$8:$Q$57)+SUMIF('8월'!$B$8:$B$57,$H31,'8월'!$Q$8:$Q$57)+SUMIF('9월'!$B$8:$B$57,$H31,'9월'!$Q$8:$Q$57)+SUMIF('10월'!$B$8:$B$57,$H31,'10월'!$Q$8:$Q$57)+SUMIF('11월'!$B$8:$B$57,$H31,'11월'!$Q$8:$Q$57)+SUMIF('12월'!$B$8:$B$57,$H31,'12월'!$Q$8:$Q$57)
H32: 왕겜(GOT) | I32: =COUNTIF('1월'!$B$8:$B$57,$H32)+COUNTIF('2월'!$B$8:$B$57,$H32)+COUNTIF('3월'!$B$8:$B$57,$H32)+COUNTIF('4월'!$B$8:$B$57,$H32)+COUNTIF('5월'!$B$8:$B$57,$H32)+COUNTIF('6월'!$B$8:$B$57,$H32)+COUNTIF('7월'!$B$8:$B$57,$H32)+COUNTIF('8월'!$B$8:$B$57,$H32)+COUNTIF('9월'!$B$8:$B$57,$H32)+COUNTIF('10월'!$B$8:$B$57,$H32)+COUNTIF('11월'!$B$8:$B$57,$H32)+COUNTIF('12월'!$B$8:$B$57,$H32) | J32: =SUMIF('1월'!$B$8:$B$57,$H32,'1월'!$Q$8:$Q$57)+SUMIF('2월'!$B$8:$B$57,$H32,'2월'!$Q$8:$Q$57)+SUMIF('3월'!$B$8:$B$57,$H32,'3월'!$Q$8:$Q$57)+SUMIF('4월'!$B$8:$B$57,$H32,'4월'!$Q$8:$Q$57)+SUMIF('5월'!$B$8:$B$57,$H32,'5월'!$Q$8:$Q$57)+SUMIF('6월'!$B$8:$B$57,$H32,'6월'!$Q$8:$Q$57)+SUMIF('7월'!$B$8:$B$57,$H32,'7월'!$Q$8:$Q$57)+SUMIF('8월'!$B$8:$B$57,$H32,'8월'!$Q$8:$Q$57)+SUMIF('9월'!$B$8:$B$57,$H32,'9월'!$Q$8:$Q$57)+SUMIF('10월'!$B$8:$B$57,$H32,'10월'!$Q$8:$Q$57)+SUMIF('11월'!$B$8:$B$57,$H32,'11월'!$Q$8:$Q$57)+SUMIF('12월'!$B$8:$B$57,$H32,'12월'!$Q$8:$Q$57)
H33: 몬스터길들이기 | I33: =COUNTIF('1월'!$B$8:$B$57,$H33)+COUNTIF('2월'!$B$8:$B$57,$H33)+COUNTIF('3월'!$B$8:$B$57,$H33)+COUNTIF('4월'!$B$8:$B$57,$H33)+COUNTIF('5월'!$B$8:$B$57,$H33)+COUNTIF('6월'!$B$8:$B$57,$H33)+COUNTIF('7월'!$B$8:$B$57,$H33)+COUNTIF('8월'!$B$8:$B$57,$H33)+COUNTIF('9월'!$B$8:$B$57,$H33)+COUNTIF('10월'!$B$8:$B$57,$H33)+COUNTIF('11월'!$B$8:$B$57,$H33)+COUNTIF('12월'!$B$8:$B$57,$H33) | J33: =SUMIF('1월'!$B$8:$B$57,$H33,'1월'!$Q$8:$Q$57)+SUMIF('2월'!$B$8:$B$57,$H33,'2월'!$Q$8:$Q$57)+SUMIF('3월'!$B$8:$B$57,$H33,'3월'!$Q$8:$Q$57)+SUMIF('4월'!$B$8:$B$57,$H33,'4월'!$Q$8:$Q$57)+SUMIF('5월'!$B$8:$B$57,$H33,'5월'!$Q$8:$Q$57)+SUMIF('6월'!$B$8:$B$57,$H33,'6월'!$Q$8:$Q$57)+SUMIF('7월'!$B$8:$B$57,$H33,'7월'!$Q$8:$Q$57)+SUMIF('8월'!$B$8:$B$57,$H33,'8월'!$Q$8:$Q$57)+SUMIF('9월'!$B$8:$B$57,$H33,'9월'!$Q$8:$Q$57)+SUMIF('10월'!$B$8:$B$57,$H33,'10월'!$Q$8:$Q$57)+SUMIF('11월'!$B$8:$B$57,$H33,'11월'!$Q$8:$Q$57)+SUMIF('12월'!$B$8:$B$57,$H33,'12월'!$Q$8:$Q$57)
H34: 라이즈오브 | I34: =COUNTIF('1월'!$B$8:$B$57,$H34)+COUNTIF('2월'!$B$8:$B$57,$H34)+COUNTIF('3월'!$B$8:$B$57,$H34)+COUNTIF('4월'!$B$8:$B$57,$H34)+COUNTIF('5월'!$B$8:$B$57,$H34)+COUNTIF('6월'!$B$8:$B$57,$H34)+COUNTIF('7월'!$B$8:$B$57,$H34)+COUNTIF('8월'!$B$8:$B$57,$H34)+COUNTIF('9월'!$B$8:$B$57,$H34)+COUNTIF('10월'!$B$8:$B$57,$H34)+COUNTIF('11월'!$B$8:$B$57,$H34)+COUNTIF('12월'!$B$8:$B$57,$H34) | J34: =SUMIF('1월'!$B$8:$B$57,$H34,'1월'!$Q$8:$Q$57)+SUMIF('2월'!$B$8:$B$57,$H34,'2월'!$Q$8:$Q$57)+SUMIF('3월'!$B$8:$B$57,$H34,'3월'!$Q$8:$Q$57)+SUMIF('4월'!$B$8:$B$57,$H34,'4월'!$Q$8:$Q$57)+SUMIF('5월'!$B$8:$B$57,$H34,'5월'!$Q$8:$Q$57)+SUMIF('6월'!$B$8:$B$57,$H34,'6월'!$Q$8:$Q$57)+SUMIF('7월'!$B$8:$B$57,$H34,'7월'!$Q$8:$Q$57)+SUMIF('8월'!$B$8:$B$57,$H34,'8월'!$Q$8:$Q$57)+SUMIF('9월'!$B$8:$B$57,$H34,'9월'!$Q$8:$Q$57)+SUMIF('10월'!$B$8:$B$57,$H34,'10월'!$Q$8:$Q$57)+SUMIF('11월'!$B$8:$B$57,$H34,'11월'!$Q$8:$Q$57)+SUMIF('12월'!$B$8:$B$57,$H34,'12월'!$Q$8:$Q$57)

Sheet 1월
A1: 1월 업무 정보 (소재명 / 요청일) | H1: 수량 | K1: 영상 (본체) | M1: 이미지 | O1: 기획(SB) | Q1: 집계 / 일정 / 자동 | Z1: 1월 간트 (MD 숫자 분산 / 주말 음영) 상단 4줄=일자별 직군 TO 상태
A2: No | B2: 게임 타이틀명 | C2: 고객팀 | D2: 유형 | E2: 소재명(업무명) | F2: 요청일 | G2: 완료일 | H2: 영상 수 | I2: 사이즈 베리 | J2: 다국어 베리 | K2: 영상 담당 | L2: 영상 MD | M2: 이미지 담당 | N2: 이미지 MD | O2: 기획 담당 | P2: 기획 MD | Q2: 합계 MD | R2: 투입 직군 | S2: 주차 | T2: 상태 | U2: 소요일 | V2: 예상완료 | W2: 여유 | X2: 비고 | Z2: =DATE('마스터'!$J$3,1,1) | AA2: =Z2+1 | AB2: =AA2+1 | AC2: =AB2+1 | AD2: =AC2+1 | AE2: =AD2+1 | AF2: =AE2+1 | AG2: =AF2+1 | AH2: =AG2+1 | ... BD2: =BC2+1
A3: 전체 TO (일자별 부하) | G3: 정원 | H3: =SUM('마스터'!$J$8:$J$10) | Z3: =SUMPRODUCT(($F$8:$F$57<>"")*($F$8:$F$57<=Z$2)*($V$8:$V$57>=Z$2)*(WEEKDAY(Z$2,2)<6)*($L$8:$L$57+$N$8:$N$57+$P$8:$P$57)/($U$8:$U$57+($U$8:$U$57=0))) | AA3: =SUMPRODUCT(($F$8:$F$57<>"")*($F$8:$F$57<=AA$2)*($V$8:$V$57>=AA$2)*(WEEKDAY(AA$2,2)<6)*($L$8:$L$57+$N$8:$N$57+$P$8:$P$57)/($U$8:$U$57+($U$8:$U$57=0))) | AB3: =SUMPRODUCT(($F$8:$F$57<>"")*($F$8:$F$57<=AB$2)*($V$8:$V$57>=AB$2)*(WEEKDAY(AB$2,2)<6)*($L$8:$L$57+$N$8:$N$57+$P$8:$P$57)/($U$8:$U$57+($U$8:$U$57=0))) | AC3: =SUMPRODUCT(($F$8:$F$57<>"")*($F$8:$F$57<=AC$2)*($V$8:$V$57>=AC$2)*(WEEKDAY(AC$2,2)<6)*($L$8:$L$57+$N$8:$N$57+$P$8:$P$57)/($U$8:$U$57+($U$8:$U$57=0))) | AD3: =SUMPRODUCT(($F$8:$F$57<>"")*($F$8:$F$57<=AD$2)*($V$8:$V$57>=AD$2)*(WEEKDAY(AD$2,2)<6)*($L$8:$L$57+$N$8:$N$57+$P$8:$P$57)/($U$8:$U$57+($U$8:$U$57=0))) | AE3: =SUMPRODUCT(($F$8:$F$57<>"")*($F$8:$F$57<=AE$2)*($V$8:$V$57>=AE$2)*(WEEKDAY(AE$2,2)<6)*($L$8:$L$57+$N$8:$N$57+$P$8:$P$57)/($U$8:$U$57+($U$8:$U$57=0))) | AF3: =SUMPRODUCT(($F$8:$F$57<>"")*($F$8:$F$57<=AF$2)*($V$8:$V$57>=AF$2)*(WEEKDAY(AF$2,2)<6)*($L$8:$L$57+$N$8:$N$57+$P$8:$P$57)/($U$8:$U$57+($U$8:$U$57=0))) | AG3: =SUMPRODUCT(($F$8:$F$57<>"")*($F$8:$F$57<=AG$2)*($V$8:$V$57>=AG$2)*(WEEKDAY(AG$2,2)<6)*($L$8:$L$57+$N$8:$N$57+$P$8:$P$57)/($U$8:$U$57+($U$8:$U$57=0))) | ... BD3: =SUMPRODUCT(($F$8:$F$57<>"")*($F$8:$F$57<=BD$2)*($V$8:$V$57>=BD$2)*(WEEKDAY(BD$2,2)<6)*($L$8:$L$57+$N$8:$N$57+$P$8:$P$57)/($U$8:$U$57+($U$8:$U$57=0)))
A4: 영상 TO | G4: 정원 | H4: ='마스터'!$J$8 | Z4: =SUMPRODUCT(($F$8:$F$57<>"")*($F$8:$F$57<=Z$2)*($V$8:$V$57>=Z$2)*(WEEKDAY(Z$2,2)<6)*($L$8:$L$57)/($U$8:$U$57+($U$8:$U$57=0))) | AA4: =SUMPRODUCT(($F$8:$F$57<>"")*($F$8:$F$57<=AA$2)*($V$8:$V$57>=AA$2)*(WEEKDAY(AA$2,2)<6)*($L$8:$L$57)/($U$8:$U$57+($U$8:$U$57=0))) | AB4: =SUMPRODUCT(($F$8:$F$57<>"")*($F$8:$F$57<=AB$2)*($V$8:$V$57>=AB$2)*(WEEKDAY(AB$2,2)<6)*($L$8:$L$57)/($U$8:$U$57+($U$8:$U$57=0))) | AC4: =SUMPRODUCT(($F$8:$F$57<>"")*($F$8:$F$57<=AC$2)*($V$8:$V$57>=AC$2)*(WEEKDAY(AC$2,2)<6)*($L$8:$L$57)/($U$8:$U$57+($U$8:$U$57=0))) | AD4: =SUMPRODUCT(($F$8:$F$57<>"")*($F$8:$F$57<=AD$2)*($V$8:$V$57>=AD$2)*(WEEKDAY(AD$2,2)<6)*($L$8:$L$57)/($U$8:$U$57+($U$8:$U$57=0))) | AE4: =SUMPRODUCT(($F$8:$F$57<>"")*($F$8:$F$57<=AE$2)*($V$8:$V$57>=AE$2)*(WEEKDAY(AE$2,2)<6)*($L$8:$L$57)/($U$8:$U$57+($U$8:$U$57=0))) | AF4: =SUMPRODUCT(($F$8:$F$57<>"")*($F$8:$F$57<=AF$2)*($V$8:$V$57>=AF$2)*(WEEKDAY(AF$2,2)<6)*($L$8:$L$57)/($U$8:$U$57+($U$8:$U$57=0))) | AG4: =SUMPRODUCT(($F$8:$F$57<>"")*($F$8:$F$57<=AG$2)*($V$8:$V$57>=AG$2)*(WEEKDAY(AG$2,2)<6)*($L$8:$L$57)/($U$8:$U$57+($U$8:$U$57=0))) | ... BD4: =SUMPRODUCT(($F$8:$F$57<>"")*($F$8:$F$57<=BD$2)*($V$8:$V$57>=BD$2)*(WEEKDAY(BD$2,2)<6)*($L$8:$L$57)/($U$8:$U$57+($U$8:$U$57=0)))
A5: 이미지 TO | G5: 정원 | H5: ='마스터'!$J$9 | Z5: =SUMPRODUCT(($F$8:$F$57<>"")*($F$8:$F$57<=Z$2)*($V$8:$V$57>=Z$2)*(WEEKDAY(Z$2,2)<6)*($N$8:$N$57)/($U$8:$U$57+($U$8:$U$57=0))) | AA5: =SUMPRODUCT(($F$8:$F$57<>"")*($F$8:$F$57<=AA$2)*($V$8:$V$57>=AA$2)*(WEEKDAY(AA$2,2)<6)*($N$8:$N$57)/($U$8:$U$57+($U$8:$U$57=0))) | AB5: =SUMPRODUCT(($F$8:$F$57<>"")*($F$8:$F$57<=AB$2)*($V$8:$V$57>=AB$2)*(WEEKDAY(AB$2,2)<6)*($N$8:$N$57)/($U$8:$U$57+($U$8:$U$57=0))) | AC5: =SUMPRODUCT(($F$8:$F$57<>"")*($F$8:$F$57<=AC$2)*($V$8:$V$57>=AC$2)*(WEEKDAY(AC$2,2)<6)*($N$8:$N$57)/($U$8:$U$57+($U$8:$U$57=0))) | AD5: =SUMPRODUCT(($F$8:$F$57<>"")*($F$8:$F$57<=AD$2)*($V$8:$V$57>=AD$2)*(WEEKDAY(AD$2,2)<6)*($N$8:$N$57)/($U$8:$U$57+($U$8:$U$57=0))) | AE5: =SUMPRODUCT(($F$8:$F$57<>"")*($F$8:$F$57<=AE$2)*($V$8:$V$57>=AE$2)*(WEEKDAY(AE$2,2)<6)*($N$8:$N$57)/($U$8:$U$57+($U$8:$U$57=0))) | AF5: =SUMPRODUCT(($F$8:$F$57<>"")*($F$8:$F$57<=AF$2)*($V$8:$V$57>=AF$2)*(WEEKDAY(AF$2,2)<6)*($N$8:$N$57)/($U$8:$U$57+($U$8:$U$57=0))) | AG5: =SUMPRODUCT(($F$8:$F$57<>"")*($F$8:$F$57<=AG$2)*($V$8:$V$57>=AG$2)*(WEEKDAY(AG$2,2)<6)*($N$8:$N$57)/($U$8:$U$57+($U$8:$U$57=0))) | ... BD5: =SUMPRODUCT(($F$8:$F$57<>"")*($F$8:$F$57<=BD$2)*($V$8:$V$57>=BD$2)*(WEEKDAY(BD$2,2)<6)*($N$8:$N$57)/($U$8:$U$57+($U$8:$U$57=0)))
A6: 기획 TO | G6: 정원 | H6: ='마스터'!$J$10 | Z6: =SUMPRODUCT(($F$8:$F$57<>"")*($F$8:$F$57<=Z$2)*($V$8:$V$57>=Z$2)*(WEEKDAY(Z$2,2)<6)*($P$8:$P$57)/($U$8:$U$57+($U$8:$U$57=0))) | AA6: =SUMPRODUCT(($F$8:$F$57<>"")*($F$8:$F$57<=AA$2)*($V$8:$V$57>=AA$2)*(WEEKDAY(AA$2,2)<6)*($P$8:$P$57)/($U$8:$U$57+($U$8:$U$57=0))) | AB6: =SUMPRODUCT(($F$8:$F$57<>"")*($F$8:$F$57<=AB$2)*($V$8:$V$57>=AB$2)*(WEEKDAY(AB$2,2)<6)*($P$8:$P$57)/($U$8:$U$57+($U$8:$U$57=0))) | AC6: =SUMPRODUCT(($F$8:$F$57<>"")*($F$8:$F$57<=AC$2)*($V$8:$V$57>=AC$2)*(WEEKDAY(AC$2,2)<6)*($P$8:$P$57)/($U$8:$U$57+($U$8:$U$57=0))) | AD6: =SUMPRODUCT(($F$8:$F$57<>"")*($F$8:$F$57<=AD$2)*($V$8:$V$57>=AD$2)*(WEEKDAY(AD$2,2)<6)*($P$8:$P$57)/($U$8:$U$57+($U$8:$U$57=0))) | AE6: =SUMPRODUCT(($F$8:$F$57<>"")*($F$8:$F$57<=AE$2)*($V$8:$V$57>=AE$2)*(WEEKDAY(AE$2,2)<6)*($P$8:$P$57)/($U$8:$U$57+($U$8:$U$57=0))) | AF6: =SUMPRODUCT(($F$8:$F$57<>"")*($F$8:$F$57<=AF$2)*($V$8:$V$57>=AF$2)*(WEEKDAY(AF$2,2)<6)*($P$8:$P$57)/($U$8:$U$57+($U$8:$U$57=0))) | AG6: =SUMPRODUCT(($F$8:$F$57<>"")*($F$8:$F$57<=AG$2)*($V$8:$V$57>=AG$2)*(WEEKDAY(AG$2,2)<6)*($P$8:$P$57)/($U$8:$U$57+($U$8:$U$57=0))) | ... BD6: =SUMPRODUCT(($F$8:$F$57<>"")*($F$8:$F$57<=BD$2)*($V$8:$V$57>=BD$2)*(WEEKDAY(BD$2,2)<6)*($P$8:$P$57)/($U$8:$U$57+($U$8:$U$57=0)))
A8: =IF(E8="","",COUNTA($E$8:E8)) | Q8: =IF(SUM(L8,N8,P8)=0,"",SUM(L8,N8,P8)) | R8: =IF(L8>0,"영 ","")&IF(N8>0,"이 ","")&IF(P8>0,"기 ","") | S8: =IF(F8="","","W"&ROUNDUP(DAY(F8)/7,0)) | U8: =IF(Q8="",0,ROUNDUP(MAX(L8,N8,P8)/'마스터'!$J$5,0)) | V8: =IF(OR(F8="",U8=0),"",WORKDAY(F8,U8-1)) | W8: =IF(OR(G8="",V8=""),"",G8-V8) | Z8: =IF(AND($F8<>"",$V8<>"",Z$2>=$F8,Z$2<=$V8,WEEKDAY(Z$2,2)<6),$Q8/$U8,"") | AA8: =IF(AND($F8<>"",$V8<>"",AA$2>=$F8,AA$2<=$V8,WEEKDAY(AA$2,2)<6),$Q8/$U8,"") | AB8: =IF(AND($F8<>"",$V8<>"",AB$2>=$F8,AB$2<=$V8,WEEKDAY(AB$2,2)<6),$Q8/$U8,"") | AC8: =IF(AND($F8<>"",$V8<>"",AC$2>=$F8,AC$2<=$V8,WEEKDAY(AC$2,2)<6),$Q8/$U8,"") | AD8: =IF(AND($F8<>"",$V8<>"",AD$2>=$F8,AD$2<=$V8,WEEKDAY(AD$2,2)<6),$Q8/$U8,"") | AE8: =IF(AND($F8<>"",$V8<>"",AE$2>=$F8,AE$2<=$V8,WEEKDAY(AE$2,2)<6),$Q8/$U8,"") | AF8: =IF(AND($F8<>"",$V8<>"",AF$2>=$F8,AF$2<=$V8,WEEKDAY(AF$2,2)<6),$Q8/$U8,"") | AG8: =IF(AND($F8<>"",$V8<>"",AG$2>=$F8,AG$2<=$V8,WEEKDAY(AG$2,2)<6),$Q8/$U8,"") | ... BD8: =IF(AND($F8<>"",$V8<>"",BD$2>=$F8,BD$2<=$V8,WEEKDAY(BD$2,2)<6),$Q8/$U8,"")
A9: =IF(E9="","",COUNTA($E$8:E9)) | Q9: =IF(SUM(L9,N9,P9)=0,"",SUM(L9,N9,P9)) | R9: =IF(L9>0,"영 ","")&IF(N9>0,"이 ","")&IF(P9>0,"기 ","") | S9: =IF(F9="","","W"&ROUNDUP(DAY(F9)/7,0)) | U9: =IF(Q9="",0,ROUNDUP(MAX(L9,N9,P9)/'마스터'!$J$5,0)) | V9: =IF(OR(F9="",U9=0),"",WORKDAY(F9,U9-1)) | W9: =IF(OR(G9="",V9=""),"",G9-V9) | Z9: =IF(AND($F9<>"",$V9<>"",Z$2>=$F9,Z$2<=$V9,WEEKDAY(Z$2,2)<6),$Q9/$U9,"") | AA9: =IF(AND($F9<>"",$V9<>"",AA$2>=$F9,AA$2<=$V9,WEEKDAY(AA$2,2)<6),$Q9/$U9,"") | AB9: =IF(AND($F9<>"",$V9<>"",AB$2>=$F9,AB$2<=$V9,WEEKDAY(AB$2,2)<6),$Q9/$U9,"") | AC9: =IF(AND($F9<>"",$V9<>"",AC$2>=$F9,AC$2<=$V9,WEEKDAY(AC$2,2)<6),$Q9/$U9,"") | AD9: =IF(AND($F9<>"",$V9<>"",AD$2>=$F9,AD$2<=$V9,WEEKDAY(AD$2,2)<6),$Q9/$U9,"") | AE9: =IF(AND($F9<>"",$V9<>"",AE$2>=$F9,AE$2<=$V9,WEEKDAY(AE$2,2)<6),$Q9/$U9,"") | AF9: =IF(AND($F9<>"",$V9<>"",AF$2>=$F9,AF$2<=$V9,WEEKDAY(AF$2,2)<6),$Q9/$U9,"") | AG9: =IF(AND($F9<>"",$V9<>"",AG$2>=$F9,AG$2<=$V9,WEEKDAY(AG$2,2)<6),$Q9/$U9,"") | ... BD9: =IF(AND($F9<>"",$V9<>"",BD$2>=$F9,BD$2<=$V9,WEEKDAY(BD$2,2)<6),$Q9/$U9,"")
A10: =IF(E10="","",COUNTA($E$8:E10)) | Q10: =IF(SUM(L10,N10,P10)=0,"",SUM(L10,N10,P10)) | R10: =IF(L10>0,"영 ","")&IF(N10>0,"이 ","")&IF(P10>0,"기 ","") | S10: =IF(F10="","","W"&ROUNDUP(DAY(F10)/7,0)) | U10: =IF(Q10="",0,ROUNDUP(MAX(L10,N10,P10)/'마스터'!$J$5,0)) | V10: =IF(OR(F10="",U10=0),"",WORKDAY(F10,U10-1)) | W10: =IF(OR(G10="",V10=""),"",G10-V10) | Z10: =IF(AND($F10<>"",$V10<>"",Z$2>=$F10,Z$2<=$V10,WEEKDAY(Z$2,2)<6),$Q10/$U10,"") | AA10: =IF(AND($F10<>"",$V10<>"",AA$2>=$F10,AA$2<=$V10,WEEKDAY(AA$2,2)<6),$Q10/$U10,"") | AB10: =IF(AND($F10<>"",$V10<>"",AB$2>=$F10,AB$2<=$V10,WEEKDAY(AB$2,2)<6),$Q10/$U10,"") | AC10: =IF(AND($F10<>"",$V10<>"",AC$2>=$F10,AC$2<=$V10,WEEKDAY(AC$2,2)<6),$Q10/$U10,"") | AD10: =IF(AND($F10<>"",$V10<>"",AD$2>=$F10,AD$2<=$V10,WEEKDAY(AD$2,2)<6),$Q10/$U10,"") | AE10: =IF(AND($F10<>"",$V10<>"",AE$2>=$F10,AE$2<=$V10,WEEKDAY(AE$2,2)<6),$Q10/$U10,"") | AF10: =IF(AND($F10<>"",$V10<>"",AF$2>=$F10,AF$2<=$V10,WEEKDAY(AF$2,2)<6),$Q10/$U10,"") | AG10: =IF(AND($F10<>"",$V10<>"",AG$2>=$F10,AG$2<=$V10,WEEKDAY(AG$2,2)<6),$Q10/$U10,"") | ... BD10: =IF(AND($F10<>"",$V10<>"",BD$2>=$F10,BD$2<=$V10,WEEKDAY(BD$2,2)<6),$Q10/$U10,"")
A11: =IF(E11="","",COUNTA($E$8:E11)) | Q11: =IF(SUM(L11,N11,P11)=0,"",SUM(L11,N11,P11)) | R11: =IF(L11>0,"영 ","")&IF(N11>0,"이 ","")&IF(P11>0,"기 ","") | S11: =IF(F11="","","W"&ROUNDUP(DAY(F11)/7,0)) | U11: =IF(Q11="",0,ROUNDUP(MAX(L11,N11,P11)/'마스터'!$J$5,0)) | V11: =IF(OR(F11="",U11=0),"",WORKDAY(F11,U11-1)) | W11: =IF(OR(G11="",V11=""),"",G11-V11) | Z11: =IF(AND($F11<>"",$V11<>"",Z$2>=$F11,Z$2<=$V11,WEEKDAY(Z$2,2)<6),$Q11/$U11,"") | AA11: =IF(AND($F11<>"",$V11<>"",AA$2>=$F11,AA$2<=$V11,WEEKDAY(AA$2,2)<6),$Q11/$U11,"") | AB11: =IF(AND($F11<>"",$V11<>"",AB$2>=$F11,AB$2<=$V11,WEEKDAY(AB$2,2)<6),$Q11/$U11,"") | AC11: =IF(AND($F11<>"",$V11<>"",AC$2>=$F11,AC$2<=$V11,WEEKDAY(AC$2,2)<6),$Q11/$U11,"") | AD11: =IF(AND($F11<>"",$V11<>"",AD$2>=$F11,AD$2<=$V11,WEEKDAY(AD$2,2)<6),$Q11/$U11,"") | AE11: =IF(AND($F11<>"",$V11<>"",AE$2>=$F11,AE$2<=$V11,WEEKDAY(AE$2,2)<6),$Q11/$U11,"") | AF11: =IF(AND($F11<>"",$V11<>"",AF$2>=$F11,AF$2<=$V11,WEEKDAY(AF$2,2)<6),$Q11/$U11,"") | AG11: =IF(AND($F11<>"",$V11<>"",AG$2>=$F11,AG$2<=$V11,WEEKDAY(AG$2,2)<6),$Q11/$U11,"") | ... BD11: =IF(AND($F11<>"",$V11<>"",BD$2>=$F11,BD$2<=$V11,WEEKDAY(BD$2,2)<6),$Q11/$U11,"")
A12: =IF(E12="","",COUNTA($E$8:E12)) | Q12: =IF(SUM(L12,N12,P12)=0,"",SUM(L12,N12,P12)) | R12: =IF(L12>0,"영 ","")&IF(N12>0,"이 ","")&IF(P12>0,"기 ","") | S12: =IF(F12="","","W"&ROUNDUP(DAY(F12)/7,0)) | U12: =IF(Q12="",0,ROUNDUP(MAX(L12,N12,P12)/'마스터'!$J$5,0)) | V12: =IF(OR(F12="",U12=0),"",WORKDAY(F12,U12-1)) | W12: =IF(OR(G12="",V12=""),"",G12-V12) | Z12: =IF(AND($F12<>"",$V12<>"",Z$2>=$F12,Z$2<=$V12,WEEKDAY(Z$2,2)<6),$Q12/$U12,"") | AA12: =IF(AND($F12<>"",$V12<>"",AA$2>=$F12,AA$2<=$V12,WEEKDAY(AA$2,2)<6),$Q12/$U12,"") | AB12: =IF(AND($F12<>"",$V12<>"",AB$2>=$F12,AB$2<=$V12,WEEKDAY(AB$2,2)<6),$Q12/$U12,"") | AC12: =IF(AND($F12<>"",$V12<>"",AC$2>=$F12,AC$2<=$V12,WEEKDAY(AC$2,2)<6),$Q12/$U12,"") | AD12: =IF(AND($F12<>"",$V12<>"",AD$2>=$F12,AD$2<=$V12,WEEKDAY(AD$2,2)<6),$Q12/$U12,"") | AE12: =IF(AND($F12<>"",$V12<>"",AE$2>=$F12,AE$2<=$V12,WEEKDAY(AE$2,2)<6),$Q12/$U12,"") | AF12: =IF(AND($F12<>"",$V12<>"",AF$2>=$F12,AF$2<=$V12,WEEKDAY(AF$2,2)<6),$Q12/$U12,"") | AG12: =IF(AND($F12<>"",$V12<>"",AG$2>=$F12,AG$2<=$V12,WEEKDAY(AG$2,2)<6),$Q12/$U12,"") | ... BD12: =IF(AND($F12<>"",$V12<>"",BD$2>=$F12,BD$2<=$V12,WEEKDAY(BD$2,2)<6),$Q12/$U12,"")
A13: =IF(E13="","",COUNTA($E$8:E13)) | Q13: =IF(SUM(L13,N13,P13)=0,"",SUM(L13,N13,P13)) | R13: =IF(L13>0,"영 ","")&IF(N13>0,"이 ","")&IF(P13>0,"기 ","") | S13: =IF(F13="","","W"&ROUNDUP(DAY(F13)/7,0)) | U13: =IF(Q13="",0,ROUNDUP(MAX(L13,N13,P13)/'마스터'!$J$5,0)) | V13: =IF(OR(F13="",U13=0),"",WORKDAY(F13,U13-1)) | W13: =IF(OR(G13="",V13=""),"",G13-V13) | Z13: =IF(AND($F13<>"",$V13<>"",Z$2>=$F13,Z$2<=$V13,WEEKDAY(Z$2,2)<6),$Q13/$U13,"") | AA13: =IF(AND($F13<>"",$V13<>"",AA$2>=$F13,AA$2<=$V13,WEEKDAY(AA$2,2)<6),$Q13/$U13,"") | AB13: =IF(AND($F13<>"",$V13<>"",AB$2>=$F13,AB$2<=$V13,WEEKDAY(AB$2,2)<6),$Q13/$U13,"") | AC13: =IF(AND($F13<>"",$V13<>"",AC$2>=$F13,AC$2<=$V13,WEEKDAY(AC$2,2)<6),$Q13/$U13,"") | AD13: =IF(AND($F13<>"",$V13<>"",AD$2>=$F13,AD$2<=$V13,WEEKDAY(AD$2,2)<6),$Q13/$U13,"") | AE13: =IF(AND($F13<>"",$V13<>"",AE$2>=$F13,AE$2<=$V13,WEEKDAY(AE$2,2)<6),$Q13/$U13,"") | AF13: =IF(AND($F13<>"",$V13<>"",AF$2>=$F13,AF$2<=$V13,WEEKDAY(AF$2,2)<6),$Q13/$U13,"") | AG13: =IF(AND($F13<>"",$V13<>"",AG$2>=$F13,AG$2<=$V13,WEEKDAY(AG$2,2)<6),$Q13/$U13,"") | ... BD13: =IF(AND($F13<>"",$V13<>"",BD$2>=$F13,BD$2<=$V13,WEEKDAY(BD$2,2)<6),$Q13/$U13,"")
A14: =IF(E14="","",COUNTA($E$8:E14)) | Q14: =IF(SUM(L14,N14,P14)=0,"",SUM(L14,N14,P14)) | R14: =IF(L14>0,"영 ","")&IF(N14>0,"이 ","")&IF(P14>0,"기 ","") | S14: =IF(F14="","","W"&ROUNDUP(DAY(F14)/7,0)) | U14: =IF(Q14="",0,ROUNDUP(MAX(L14,N14,P14)/'마스터'!$J$5,0)) | V14: =IF(OR(F14="",U14=0),"",WORKDAY(F14,U14-1)) | W14: =IF(OR(G14="",V14=""),"",G14-V14) | Z14: =IF(AND($F14<>"",$V14<>"",Z$2>=$F14,Z$2<=$V14,WEEKDAY(Z$2,2)<6),$Q14/$U14,"") | AA14: =IF(AND($F14<>"",$V14<>"",AA$2>=$F14,AA$2<=$V14,WEEKDAY(AA$2,2)<6),$Q14/$U14,"") | AB14: =IF(AND($F14<>"",$V14<>"",AB$2>=$F14,AB$2<=$V14,WEEKDAY(AB$2,2)<6),$Q14/$U14,"") | AC14: =IF(AND($F14<>"",$V14<>"",AC$2>=$F14,AC$2<=$V14,WEEKDAY(AC$2,2)<6),$Q14/$U14,"") | AD14: =IF(AND($F14<>"",$V14<>"",AD$2>=$F14,AD$2<=$V14,WEEKDAY(AD$2,2)<6),$Q14/$U14,"") | AE14: =IF(AND($F14<>"",$V14<>"",AE$2>=$F14,AE$2<=$V14,WEEKDAY(AE$2,2)<6),$Q14/$U14,"") | AF14: =IF(AND($F14<>"",$V14<>"",AF$2>=$F14,AF$2<=$V14,WEEKDAY(AF$2,2)<6),$Q14/$U14,"") | AG14: =IF(AND($F14<>"",$V14<>"",AG$2>=$F14,AG$2<=$V14,WEEKDAY(AG$2,2)<6),$Q14/$U14,"") | ... BD14: =IF(AND($F14<>"",$V14<>"",BD$2>=$F14,BD$2<=$V14,WEEKDAY(BD$2,2)<6),$Q14/$U14,"")
A15: =IF(E15="","",COUNTA($E$8:E15)) | Q15: =IF(SUM(L15,N15,P15)=0,"",SUM(L15,N15,P15)) | R15: =IF(L15>0,"영 ","")&IF(N15>0,"이 ","")&IF(P15>0,"기 ","") | S15: =IF(F15="","","W"&ROUNDUP(DAY(F15)/7,0)) | U15: =IF(Q15="",0,ROUNDUP(MAX(L15,N15,P15)/'마스터'!$J$5,0)) | V15: =IF(OR(F15="",U15=0),"",WORKDAY(F15,U15-1)) | W15: =IF(OR(G15="",V15=""),"",G15-V15) | Z15: =IF(AND($F15<>"",$V15<>"",Z$2>=$F15,Z$2<=$V15,WEEKDAY(Z$2,2)<6),$Q15/$U15,"") | AA15: =IF(AND($F15<>"",$V15<>"",AA$2>=$F15,AA$2<=$V15,WEEKDAY(AA$2,2)<6),$Q15/$U15,"") | AB15: =IF(AND($F15<>"",$V15<>"",AB$2>=$F15,AB$2<=$V15,WEEKDAY(AB$2,2)<6),$Q15/$U15,"") | AC15: =IF(AND($F15<>"",$V15<>"",AC$2>=$F15,AC$2<=$V15,WEEKDAY(AC$2,2)<6),$Q15/$U15,"") | AD15: =IF(AND($F15<>"",$V15<>"",AD$2>=$F15,AD$2<=$V15,WEEKDAY(AD$2,2)<6),$Q15/$U15,"") | AE15: =IF(AND($F15<>"",$V15<>"",AE$2>=$F15,AE$2<=$V15,WEEKDAY(AE$2,2)<6),$Q15/$U15,"") | AF15: =IF(AND($F15<>"",$V15<>"",AF$2>=$F15,AF$2<=$V15,WEEKDAY(AF$2,2)<6),$Q15/$U15,"") | AG15: =IF(AND($F15<>"",$V15<>"",AG$2>=$F15,AG$2<=$V15,WEEKDAY(AG$2,2)<6),$Q15/$U15,"") | ... BD15: =IF(AND($F15<>"",$V15<>"",BD$2>=$F15,BD$2<=$V15,WEEKDAY(BD$2,2)<6),$Q15/$U15,"")
A16: =IF(E16="","",COUNTA($E$8:E16)) | Q16: =IF(SUM(L16,N16,P16)=0,"",SUM(L16,N16,P16)) | R16: =IF(L16>0,"영 ","")&IF(N16>0,"이 ","")&IF(P16>0,"기 ","") | S16: =IF(F16="","","W"&ROUNDUP(DAY(F16)/7,0)) | U16: =IF(Q16="",0,ROUNDUP(MAX(L16,N16,P16)/'마스터'!$J$5,0)) | V16: =IF(OR(F16="",U16=0),"",WORKDAY(F16,U16-1)) | W16: =IF(OR(G16="",V16=""),"",G16-V16) | Z16: =IF(AND($F16<>"",$V16<>"",Z$2>=$F16,Z$2<=$V16,WEEKDAY(Z$2,2)<6),$Q16/$U16,"") | AA16: =IF(AND($F16<>"",$V16<>"",AA$2>=$F16,AA$2<=$V16,WEEKDAY(AA$2,2)<6),$Q16/$U16,"") | AB16: =IF(AND($F16<>"",$V16<>"",AB$2>=$F16,AB$2<=$V16,WEEKDAY(AB$2,2)<6),$Q16/$U16,"") | AC16: =IF(AND($F16<>"",$V16<>"",AC$2>=$F16,AC$2<=$V16,WEEKDAY(AC$2,2)<6),$Q16/$U16,"") | AD16: =IF(AND($F16<>"",$V16<>"",AD$2>=$F16,AD$2<=$V16,WEEKDAY(AD$2,2)<6),$Q16/$U16,"") | AE16: =IF(AND($F16<>"",$V16<>"",AE$2>=$F16,AE$2<=$V16,WEEKDAY(AE$2,2)<6),$Q16/$U16,"") | AF16: =IF(AND($F16<>"",$V16<>"",AF$2>=$F16,AF$2<=$V16,WEEKDAY(AF$2,2)<6),$Q16/$U16,"") | AG16: =IF(AND($F16<>"",$V16<>"",AG$2>=$F16,AG$2<=$V16,WEEKDAY(AG$2,2)<6),$Q16/$U16,"") | ... BD16: =IF(AND($F16<>"",$V16<>"",BD$2>=$F16,BD$2<=$V16,WEEKDAY(BD$2,2)<6),$Q16/$U16,"")
A17: =IF(E17="","",COUNTA($E$8:E17)) | Q17: =IF(SUM(L17,N17,P17)=0,"",SUM(L17,N17,P17)) | R17: =IF(L17>0,"영 ","")&IF(N17>0,"이 ","")&IF(P17>0,"기 ","") | S17: =IF(F17="","","W"&ROUNDUP(DAY(F17)/7,0)) | U17: =IF(Q17="",0,ROUNDUP(MAX(L17,N17,P17)/'마스터'!$J$5,0)) | V17: =IF(OR(F17="",U17=0),"",WORKDAY(F17,U17-1)) | W17: =IF(OR(G17="",V17=""),"",G17-V17) | Z17: =IF(AND($F17<>"",$V17<>"",Z$2>=$F17,Z$2<=$V17,WEEKDAY(Z$2,2)<6),$Q17/$U17,"") | AA17: =IF(AND($F17<>"",$V17<>"",AA$2>=$F17,AA$2<=$V17,WEEKDAY(AA$2,2)<6),$Q17/$U17,"") | AB17: =IF(AND($F17<>"",$V17<>"",AB$2>=$F17,AB$2<=$V17,WEEKDAY(AB$2,2)<6),$Q17/$U17,"") | AC17: =IF(AND($F17<>"",$V17<>"",AC$2>=$F17,AC$2<=$V17,WEEKDAY(AC$2,2)<6),$Q17/$U17,"") | AD17: =IF(AND($F17<>"",$V17<>"",AD$2>=$F17,AD$2<=$V17,WEEKDAY(AD$2,2)<6),$Q17/$U17,"") | AE17: =IF(AND($F17<>"",$V17<>"",AE$2>=$F17,AE$2<=$V17,WEEKDAY(AE$2,2)<6),$Q17/$U17,"") | AF17: =IF(AND($F17<>"",$V17<>"",AF$2>=$F17,AF$2<=$V17,WEEKDAY(AF$2,2)<6),$Q17/$U17,"") | AG17: =IF(AND($F17<>"",$V17<>"",AG$2>=$F17,AG$2<=$V17,WEEKDAY(AG$2,2)<6),$Q17/$U17,"") | ... BD17: =IF(AND($F17<>"",$V17<>"",BD$2>=$F17,BD$2<=$V17,WEEKDAY(BD$2,2)<6),$Q17/$U17,"")
A18: =IF(E18="","",COUNTA($E$8:E18)) | Q18: =IF(SUM(L18,N18,P18)=0,"",SUM(L18,N18,P18)) | R18: =IF(L18>0,"영 ","")&IF(N18>0,"이 ","")&IF(P18>0,"기 ","") | S18: =IF(F18="","","W"&ROUNDUP(DAY(F18)/7,0)) | U18: =IF(Q18="",0,ROUNDUP(MAX(L18,N18,P18)/'마스터'!$J$5,0)) | V18: =IF(OR(F18="",U18=0),"",WORKDAY(F18,U18-1)) | W18: =IF(OR(G18="",V18=""),"",G18-V18) | Z18: =IF(AND($F18<>"",$V18<>"",Z$2>=$F18,Z$2<=$V18,WEEKDAY(Z$2,2)<6),$Q18/$U18,"") | AA18: =IF(AND($F18<>"",$V18<>"",AA$2>=$F18,AA$2<=$V18,WEEKDAY(AA$2,2)<6),$Q18/$U18,"") | AB18: =IF(AND($F18<>"",$V18<>"",AB$2>=$F18,AB$2<=$V18,WEEKDAY(AB$2,2)<6),$Q18/$U18,"") | AC18: =IF(AND($F18<>"",$V18<>"",AC$2>=$F18,AC$2<=$V18,WEEKDAY(AC$2,2)<6),$Q18/$U18,"") | AD18: =IF(AND($F18<>"",$V18<>"",AD$2>=$F18,AD$2<=$V18,WEEKDAY(AD$2,2)<6),$Q18/$U18,"") | AE18: =IF(AND($F18<>"",$V18<>"",AE$2>=$F18,AE$2<=$V18,WEEKDAY(AE$2,2)<6),$Q18/$U18,"") | AF18: =IF(AND($F18<>"",$V18<>"",AF$2>=$F18,AF$2<=$V18,WEEKDAY(AF$2,2)<6),$Q18/$U18,"") | AG18: =IF(AND($F18<>"",$V18<>"",AG$2>=$F18,AG$2<=$V18,WEEKDAY(AG$2,2)<6),$Q18/$U18,"") | ... BD18: =IF(AND($F18<>"",$V18<>"",BD$2>=$F18,BD$2<=$V18,WEEKDAY(BD$2,2)<6),$Q18/$U18,"")
A19: =IF(E19="","",COUNTA($E$8:E19)) | Q19: =IF(SUM(L19,N19,P19)=0,"",SUM(L19,N19,P19)) | R19: =IF(L19>0,"영 ","")&IF(N19>0,"이 ","")&IF(P19>0,"기 ","") | S19: =IF(F19="","","W"&ROUNDUP(DAY(F19)/7,0)) | U19: =IF(Q19="",0,ROUNDUP(MAX(L19,N19,P19)/'마스터'!$J$5,0)) | V19: =IF(OR(F19="",U19=0),"",WORKDAY(F19,U19-1)) | W19: =IF(OR(G19="",V19=""),"",G19-V19) | Z19: =IF(AND($F19<>"",$V19<>"",Z$2>=$F19,Z$2<=$V19,WEEKDAY(Z$2,2)<6),$Q19/$U19,"") | AA19: =IF(AND($F19<>"",$V19<>"",AA$2>=$F19,AA$2<=$V19,WEEKDAY(AA$2,2)<6),$Q19/$U19,"") | AB19: =IF(AND($F19<>"",$V19<>"",AB$2>=$F19,AB$2<=$V19,WEEKDAY(AB$2,2)<6),$Q19/$U19,"") | AC19: =IF(AND($F19<>"",$V19<>"",AC$2>=$F19,AC$2<=$V19,WEEKDAY(AC$2,2)<6),$Q19/$U19,"") | AD19: =IF(AND($F19<>"",$V19<>"",AD$2>=$F19,AD$2<=$V19,WEEKDAY(AD$2,2)<6),$Q19/$U19,"") | AE19: =IF(AND($F19<>"",$V19<>"",AE$2>=$F19,AE$2<=$V19,WEEKDAY(AE$2,2)<6),$Q19/$U19,"") | AF19: =IF(AND($F19<>"",$V19<>"",AF$2>=$F19,AF$2<=$V19,WEEKDAY(AF$2,2)<6),$Q19/$U19,"") | AG19: =IF(AND($F19<>"",$V19<>"",AG$2>=$F19,AG$2<=$V19,WEEKDAY(AG$2,2)<6),$Q19/$U19,"") | ... BD19: =IF(AND($F19<>"",$V19<>"",BD$2>=$F19,BD$2<=$V19,WEEKDAY(BD$2,2)<6),$Q19/$U19,"")
... A57: =IF(E57="","",COUNTA($E$8:E57)) | Q57: =IF(SUM(L57,N57,P57)=0,"",SUM(L57,N57,P57)) | R57: =IF(L57>0,"영 ","")&IF(N57>0,"이 ","")&IF(P57>0,"기 ","") | S57: =IF(F57="","","W"&ROUNDUP(DAY(F57)/7,0)) | U57: =IF(Q57="",0,ROUNDUP(MAX(L57,N57,P57)/'마스터'!$J$5,0)) | V57: =IF(OR(F57="",U57=0),"",WORKDAY(F57,U57-1)) | W57: =IF(OR(G57="",V57=""),"",G57-V57) | Z57: =IF(AND($F57<>"",$V57<>"",Z$2>=$F57,Z$2<=$V57,WEEKDAY(Z$2,2)<6),$Q57/$U57,"") | AA57: =IF(AND($F57<>"",$V57<>"",AA$2>=$F57,AA$2<=$V57,WEEKDAY(AA$2,2)<6),$Q57/$U57,"") | AB57: =IF(AND($F57<>"",$V57<>"",AB$2>=$F57,AB$2<=$V57,WEEKDAY(AB$2,2)<6),$Q57/$U57,"") | AC57: =IF(AND($F57<>"",$V57<>"",AC$2>=$F57,AC$2<=$V57,WEEKDAY(AC$2,2)<6),$Q57/$U57,"") | AD57: =IF(AND($F57<>"",$V57<>"",AD$2>=$F57,AD$2<=$V57,WEEKDAY(AD$2,2)<6),$Q57/$U57,"") | AE57: =IF(AND($F57<>"",$V57<>"",AE$2>=$F57,AE$2<=$V57,WEEKDAY(AE$2,2)<6),$Q57/$U57,"") | AF57: =IF(AND($F57<>"",$V57<>"",AF$2>=$F57,AF$2<=$V57,WEEKDAY(AF$2,2)<6),$Q57/$U57,"") | AG57: =IF(AND($F57<>"",$V57<>"",AG$2>=$F57,AG$2<=$V57,WEEKDAY(AG$2,2)<6),$Q57/$U57,"") | ... BD57: =IF(AND($F57<>"",$V57<>"",BD$2>=$F57,BD$2<=$V57,WEEKDAY(BD$2,2)<6),$Q57/$U57,"")

Sheet 2월
A1: 2월 업무 정보 (소재명 / 요청일) | H1: 수량 | K1: 영상 (본체) | M1: 이미지 | O1: 기획(SB) | Q1: 집계 / 일정 / 자동 | Z1: 2월 간트 (MD 숫자 분산 / 주말 음영) 상단 4줄=일자별 직군 TO 상태
A2: No | B2: 게임 타이틀명 | C2: 고객팀 | D2: 유형 | E2: 소재명(업무명) | F2: 요청일 | G2: 완료일 | H2: 영상 수 | I2: 사이즈 베리 | J2: 다국어 베리 | K2: 영상 담당 | L2: 영상 MD | M2: 이미지 담당 | N2: 이미지 MD | O2: 기획 담당 | P2: 기획 MD | Q2: 합계 MD | R2: 투입 직군 | S2: 주차 | T2: 상태 | U2: 소요일 | V2: 예상완료 | W2: 여유 | X2: 비고 | Z2: =DATE('마스터'!$J$3,2,1) | AA2: =Z2+1 | AB2: =AA2+1 | AC2: =AB2+1 | AD2: =AC2+1 | AE2: =AD2+1 | AF2: =AE2+1 | AG2: =AF2+1 | AH2: =AG2+1 | ... BD2: =BC2+1
A3: 전체 TO (일자별 부하) | G3: 정원 | H3: =SUM('마스터'!$J$8:$J$10) | Z3: =SUMPRODUCT(($F$8:$F$57<>"")*($F$8:$F$57<=Z$2)*($V$8:$V$57>=Z$2)*(WEEKDAY(Z$2,2)<6)*($L$8:$L$57+$N$8:$N$57+$P$8:$P$57)/($U$8:$U$57+($U$8:$U$57=0))) | AA3: =SUMPRODUCT(($F$8:$F$57<>"")*($F$8:$F$57<=AA$2)*($V$8:$V$57>=AA$2)*(WEEKDAY(AA$2,2)<6)*($L$8:$L$57+$N$8:$N$57+$P$8:$P$57)/($U$8:$U$57+($U$8:$U$57=0))) | AB3: =SUMPRODUCT(($F$8:$F$57<>"")*($F$8:$F$57<=AB$2)*($V$8:$V$57>=AB$2)*(WEEKDAY(AB$2,2)<6)*($L$8:$L$57+$N$8:$N$57+$P$8:$P$57)/($U$8:$U$57+($U$8:$U$57=0))) | AC3: =SUMPRODUCT(($F$8:$F$57<>"")*($F$8:$F$57<=AC$2)*($V$8:$V$57>=AC$2)*(WEEKDAY(AC$2,2)<6)*($L$8:$L$57+$N$8:$N$57+$P$8:$P$57)/($U$8:$U$57+($U$8:$U$57=0))) | AD3: =SUMPRODUCT(($F$8:$F$57<>"")*($F$8:$F$57<=AD$2)*($V$8:$V$57>=AD$2)*(WEEKDAY(AD$2,2)<6)*($L$8:$L$57+$N$8:$N$57+$P$8:$P$57)/($U$8:$U$57+($U$8:$U$57=0))) | AE3: =SUMPRODUCT(($F$8:$F$57<>"")*($F$8:$F$57<=AE$2)*($V$8:$V$57>=AE$2)*(WEEKDAY(AE$2,2)<6)*($L$8:$L$57+$N$8:$N$57+$P$8:$P$57)/($U$8:$U$57+($U$8:$U$57=0))) | AF3: =SUMPRODUCT(($F$8:$F$57<>"")*($F$8:$F$57<=AF$2)*($V$8:$V$57>=AF$2)*(WEEKDAY(AF$2,2)<6)*($L$8:$L$57+$N$8:$N$57+$P$8:$P$57)/($U$8:$U$57+($U$8:$U$57=0))) | AG3: =SUMPRODUCT(($F$8:$F$57<>"")*($F$8:$F$57<=AG$2)*($V$8:$V$57>=AG$2)*(WEEKDAY(AG$2,2)<6)*($L$8:$L$57+$N$8:$N$57+$P$8:$P$57)/($U$8:$U$57+($U$8:$U$57=0))) | ... BD3: =SUMPRODUCT(($F$8:$F$57<>"")*($F$8:$F$57<=BD$2)*($V$8:$V$57>=BD$2)*(WEEKDAY(BD$2,2)<6)*($L$8:$L$57+$N$8:$N$57+$P$8:$P$57)/($U$8:$U$57+($U$8:$U$57=0)))
A4: 영상 TO | G4: 정원 | H4: ='마스터'!$J$8 | Z4: =SUMPRODUCT(($F$8:$F$57<>"")*($F$8:$F$57<=Z$2)*($V$8:$V$57>=Z$2)*(WEEKDAY(Z$2,2)<6)*($L$8:$L$57)/($U$8:$U$57+($U$8:$U$57=0))) | AA4: =SUMPRODUCT(($F$8:$F$57<>"")*($F$8:$F$57<=AA$2)*($V$8:$V$57>=AA$2)*(WEEKDAY(AA$2,2)<6)*($L$8:$L$57)/($U$8:$U$57+($U$8:$U$57=0))) | AB4: =SUMPRODUCT(($F$8:$F$57<>"")*($F$8:$F$57<=AB$2)*($V$8:$V$57>=AB$2)*(WEEKDAY(AB$2,2)<6)*($L$8:$L$57)/($U$8:$U$57+($U$8:$U$57=0))) | AC4: =SUMPRODUCT(($F$8:$F$57<>"")*($F$8:$F$57<=AC$2)*($V$8:$V$57>=AC$2)*(WEEKDAY(AC$2,2)<6)*($L$8:$L$57)/($U$8:$U$57+($U$8:$U$57=0))) | AD4: =SUMPRODUCT(($F$8:$F$57<>"")*($F$8:$F$57<=AD$2)*($V$8:$V$57>=AD$2)*(WEEKDAY(AD$2,2)<6)*($L$8:$L$57)/($U$8:$U$57+($U$8:$U$57=0))) | AE4: =SUMPRODUCT(($F$8:$F$57<>"")*($F$8:$F$57<=AE$2)*($V$8:$V$57>=AE$2)*(WEEKDAY(AE$2,2)<6)*($L$8:$L$57)/($U$8:$U$57+($U$8:$U$57=0))) | AF4: =SUMPRODUCT(($F$8:$F$57<>"")*($F$8:$F$57<=AF$2)*($V$8:$V$57>=AF$2)*(WEEKDAY(AF$2,2)<6)*($L$8:$L$57)/($U$8:$U$57+($U$8:$U$57=0))) | AG4: =SUMPRODUCT(($F$8:$F$57<>"")*($F$8:$F$57<=AG$2)*($V$8:$V$57>=AG$2)*(WEEKDAY(AG$2,2)<6)*($L$8:$L$57)/($U$8:$U$57+($U$8:$U$57=0))) | ... BD4: =SUMPRODUCT(($F$8:$F$57<>"")*($F$8:$F$57<=BD$2)*($V$8:$V$57>=BD$2)*(WEEKDAY(BD$2,2)<6)*($L$8:$L$57)/($U$8:$U$57+($U$8:$U$57=0)))
A5: 이미지 TO | G5: 정원 | H5: ='마스터'!$J$9 | Z5: =SUMPRODUCT(($F$8:$F$57<>"")*($F$8:$F$57<=Z$2)*($V$8:$V$57>=Z$2)*(WEEKDAY(Z$2,2)<6)*($N$8:$N$57)/($U$8:$U$57+($U$8:$U$57=0))) | AA5: =SUMPRODUCT(($F$8:$F$57<>"")*($F$8:$F$57<=AA$2)*($V$8:$V$57>=AA$2)*(WEEKDAY(AA$2,2)<6)*($N$8:$N$57)/($U$8:$U$57+($U$8:$U$57=0))) | AB5: =SUMPRODUCT(($F$8:$F$57<>"")*($F$8:$F$57<=AB$2)*($V$8:$V$57>=AB$2)*(WEEKDAY(AB$2,2)<6)*($N$8:$N$57)/($U$8:$U$57+($U$8:$U$57=0))) | AC5: =SUMPRODUCT(($F$8:$F$57<>"")*($F$8:$F$57<=AC$2)*($V$8:$V$57>=AC$2)*(WEEKDAY(AC$2,2)<6)*($N$8:$N$57)/($U$8:$U$57+($U$8:$U$57=0))) | AD5: =SUMPRODUCT(($F$8:$F$57<>"")*($F$8:$F$57<=AD$2)*($V$8:$V$57>=AD$2)*(WEEKDAY(AD$2,2)<6)*($N$8:$N$57)/($U$8:$U$57+($U$8:$U$57=0))) | AE5: =SUMPRODUCT(($F$8:$F$57<>"")*($F$8:$F$57<=AE$2)*($V$8:$V$57>=AE$2)*(WEEKDAY(AE$2,2)<6)*($N$8:$N$57)/($U$8:$U$57+($U$8:$U$57=0))) | AF5: =SUMPRODUCT(($F$8:$F$57<>"")*($F$8:$F$57<=AF$2)*($V$8:$V$57>=AF$2)*(WEEKDAY(AF$2,2)<6)*($N$8:$N$57)/($U$8:$U$57+($U$8:$U$57=0))) | AG5: =SUMPRODUCT(($F$8:$F$57<>"")*($F$8:$F$57<=AG$2)*($V$8:$V$57>=AG$2)*(WEEKDAY(AG$2,2)<6)*($N$8:$N$57)/($U$8:$U$57+($U$8:$U$57=0))) | ... BD5: =SUMPRODUCT(($F$8:$F$57<>"")*($F$8:$F$57<=BD$2)*($V$8:$V$57>=BD$2)*(WEEKDAY(BD$2,2)<6)*($N$8:$N$57)/($U$8:$U$57+($U$8:$U$57=0)))
A6: 기획 TO | G6: 정원 | H6: ='마스터'!$J$10 | Z6: =SUMPRODUCT(($F$8:$F$57<>"")*($F$8:$F$57<=Z$2)*($V$8:$V$57>=Z$2)*(WEEKDAY(Z$2,2)<6)*($P$8:$P$57)/($U$8:$U$57+($U$8:$U$57=0))) | AA6: =SUMPRODUCT(($F$8:$F$57<>"")*($F$8:$F$57<=AA$2)*($V$8:$V$57>=AA$2)*(WEEKDAY(AA$2,2)<6)*($P$8:$P$57)/($U$8:$U$57+($U$8:$U$57=0))) | AB6: =SUMPRODUCT(($F$8:$F$57<>"")*($F$8:$F$57<=AB$2)*($V$8:$V$57>=AB$2)*(WEEKDAY(AB$2,2)<6)*($P$8:$P$57)/($U$8:$U$57+($U$8:$U$57=0))) | AC6: =SUMPRODUCT(($F$8:$F$57<>"")*($F$8:$F$57<=AC$2)*($V$8:$V$57>=AC$2)*(WEEKDAY(AC$2,2)<6)*($P$8:$P$57)/($U$8:$U$57+($U$8:$U$57=0))) | AD6: =SUMPRODUCT(($F$8:$F$57<>"")*($F$8:$F$57<=AD$2)*($V$8:$V$57>=AD$2)*(WEEKDAY(AD$2,2)<6)*($P$8:$P$57)/($U$8:$U$57+($U$8:$U$57=0))) | AE6: =SUMPRODUCT(($F$8:$F$57<>"")*($F$8:$F$57<=AE$2)*($V$8:$V$57>=AE$2)*(WEEKDAY(AE$2,2)<6)*($P$8:$P$57)/($U$8:$U$57+($U$8:$U$57=0))) | AF6: =SUMPRODUCT(($F$8:$F$57<>"")*($F$8:$F$57<=AF$2)*($V$8:$V$57>=AF$2)*(WEEKDAY(AF$2,2)<6)*($P$8:$P$57)/($U$8:$U$57+($U$8:$U$57=0))) | AG6: =SUMPRODUCT(($F$8:$F$57<>"")*($F$8:$F$57<=AG$2)*($V$8:$V$57>=AG$2)*(WEEKDAY(AG$2,2)<6)*($P$8:$P$57)/($U$8:$U$57+($U$8:$U$57=0))) | ... BD6: =SUMPRODUCT(($F$8:$F$57<>"")*($F$8:$F$57<=BD$2)*($V$8:$V$57>=BD$2)*(WEEKDAY(BD$2,2)<6)*($P$8:$P$57)/($U$8:$U$57+($U$8:$U$57=0)))
A8: =IF(E8="","",COUNTA($E$8:E8)) | Q8: =IF(SUM(L8,N8,P8)=0,"",SUM(L8,N8,P8)) | R8: =IF(L8>0,"영 ","")&IF(N8>0,"이 ","")&IF(P8>0,"기 ","") | S8: =IF(F8="","","W"&ROUNDUP(DAY(F8)/7,0)) | U8: =IF(Q8="",0,ROUNDUP(MAX(L8,N8,P8)/'마스터'!$J$5,0)) | V8: =IF(OR(F8="",U8=0),"",WORKDAY(F8,U8-1)) | W8: =IF(OR(G8="",V8=""),"",G8-V8) | Z8: =IF(AND($F8<>"",$V8<>"",Z$2>=$F8,Z$2<=$V8,WEEKDAY(Z$2,2)<6),$Q8/$U8,"") | AA8: =IF(AND($F8<>"",$V8<>"",AA$2>=$F8,AA$2<=$V8,WEEKDAY(AA$2,2)<6),$Q8/$U8,"") | AB8: =IF(AND($F8<>"",$V8<>"",AB$2>=$F8,AB$2<=$V8,WEEKDAY(AB$2,2)<6),$Q8/$U8,"") | AC8: =IF(AND($F8<>"",$V8<>"",AC$2>=$F8,AC$2<=$V8,WEEKDAY(AC$2,2)<6),$Q8/$U8,"") | AD8: =IF(AND($F8<>"",$V8<>"",AD$2>=$F8,AD$2<=$V8,WEEKDAY(AD$2,2)<6),$Q8/$U8,"") | AE8: =IF(AND($F8<>"",$V8<>"",AE$2>=$F8,AE$2<=$V8,WEEKDAY(AE$2,2)<6),$Q8/$U8,"") | AF8: =IF(AND($F8<>"",$V8<>"",AF$2>=$F8,AF$2<=$V8,WEEKDAY(AF$2,2)<6),$Q8/$U8,"") | AG8: =IF(AND($F8<>"",$V8<>"",AG$2>=$F8,AG$2<=$V8,WEEKDAY(AG$2,2)<6),$Q8/$U8,"") | ... BD8: =IF(AND($F8<>"",$V8<>"",BD$2>=$F8,BD$2<=$V8,WEEKDAY(BD$2,2)<6),$Q8/$U8,"")
A9: =IF(E9="","",COUNTA($E$8:E9)) | Q9: =IF(SUM(L9,N9,P9)=0,"",SUM(L9,N9,P9)) | R9: =IF(L9>0,"영 ","")&IF(N9>0,"이 ","")&IF(P9>0,"기 ","") | S9: =IF(F9="","","W"&ROUNDUP(DAY(F9)/7,0)) | U9: =IF(Q9="",0,ROUNDUP(MAX(L9,N9,P9)/'마스터'!$J$5,0)) | V9: =IF(OR(F9="",U9=0),"",WORKDAY(F9,U9-1)) | W9: =IF(OR(G9="",V9=""),"",G9-V9) | Z9: =IF(AND($F9<>"",$V9<>"",Z$2>=$F9,Z$2<=$V9,WEEKDAY(Z$2,2)<6),$Q9/$U9,"") | AA9: =IF(AND($F9<>"",$V9<>"",AA$2>=$F9,AA$2<=$V9,WEEKDAY(AA$2,2)<6),$Q9/$U9,"") | AB9: =IF(AND($F9<>"",$V9<>"",AB$2>=$F9,AB$2<=$V9,WEEKDAY(AB$2,2)<6),$Q9/$U9,"") | AC9: =IF(AND($F9<>"",$V9<>"",AC$2>=$F9,AC$2<=$V9,WEEKDAY(AC$2,2)<6),$Q9/$U9,"") | AD9: =IF(AND($F9<>"",$V9<>"",AD$2>=$F9,AD$2<=$V9,WEEKDAY(AD$2,2)<6),$Q9/$U9,"") | AE9: =IF(AND($F9<>"",$V9<>"",AE$2>=$F9,AE$2<=$V9,WEEKDAY(AE$2,2)<6),$Q9/$U9,"") | AF9: =IF(AND($F9<>"",$V9<>"",AF$2>=$F9,AF$2<=$V9,WEEKDAY(AF$2,2)<6),$Q9/$U9,"") | AG9: =IF(AND($F9<>"",$V9<>"",AG$2>=$F9,AG$2<=$V9,WEEKDAY(AG$2,2)<6),$Q9/$U9,"") | ... BD9: =IF(AND($F9<>"",$V9<>"",BD$2>=$F9,BD$2<=$V9,WEEKDAY(BD$2,2)<6),$Q9/$U9,"")
A10: =IF(E10="","",COUNTA($E$8:E10)) | Q10: =IF(SUM(L10,N10,P10)=0,"",SUM(L10,N10,P10)) | R10: =IF(L10>0,"영 ","")&IF(N10>0,"이 ","")&IF(P10>0,"기 ","") | S10: =IF(F10="","","W"&ROUNDUP(DAY(F10)/7,0)) | U10: =IF(Q10="",0,ROUNDUP(MAX(L10,N10,P10)/'마스터'!$J$5,0)) | V10: =IF(OR(F10="",U10=0),"",WORKDAY(F10,U10-1)) | W10: =IF(OR(G10="",V10=""),"",G10-V10) | Z10: =IF(AND($F10<>"",$V10<>"",Z$2>=$F10,Z$2<=$V10,WEEKDAY(Z$2,2)<6),$Q10/$U10,"") | AA10: =IF(AND($F10<>"",$V10<>"",AA$2>=$F10,AA$2<=$V10,WEEKDAY(AA$2,2)<6),$Q10/$U10,"") | AB10: =IF(AND($F10<>"",$V10<>"",AB$2>=$F10,AB$2<=$V10,WEEKDAY(AB$2,2)<6),$Q10/$U10,"") | AC10: =IF(AND($F10<>"",$V10<>"",AC$2>=$F10,AC$2<=$V10,WEEKDAY(AC$2,2)<6),$Q10/$U10,"") | AD10: =IF(AND($F10<>"",$V10<>"",AD$2>=$F10,AD$2<=$V10,WEEKDAY(AD$2,2)<6),$Q10/$U10,"") | AE10: =IF(AND($F10<>"",$V10<>"",AE$2>=$F10,AE$2<=$V10,WEEKDAY(AE$2,2)<6),$Q10/$U10,"") | AF10: =IF(AND($F10<>"",$V10<>"",AF$2>=$F10,AF$2<=$V10,WEEKDAY(AF$2,2)<6),$Q10/$U10,"") | AG10: =IF(AND($F10<>"",$V10<>"",AG$2>=$F10,AG$2<=$V10,WEEKDAY(AG$2,2)<6),$Q10/$U10,"") | ... BD10: =IF(AND($F10<>"",$V10<>"",BD$2>=$F10,BD$2<=$V10,WEEKDAY(BD$2,2)<6),$Q10/$U10,"")
A11: =IF(E11="","",COUNTA($E$8:E11)) | Q11: =IF(SUM(L11,N11,P11)=0,"",SUM(L11,N11,P11)) | R11: =IF(L11>0,"영 ","")&IF(N11>0,"이 ","")&IF(P11>0,"기 ","") | S11: =IF(F11="","","W"&ROUNDUP(DAY(F11)/7,0)) | U11: =IF(Q11="",0,ROUNDUP(MAX(L11,N11,P11)/'마스터'!$J$5,0)) | V11: =IF(OR(F11="",U11=0),"",WORKDAY(F11,U11-1)) | W11: =IF(OR(G11="",V11=""),"",G11-V11) | Z11: =IF(AND($F11<>"",$V11<>"",Z$2>=$F11,Z$2<=$V11,WEEKDAY(Z$2,2)<6),$Q11/$U11,"") | AA11: =IF(AND($F11<>"",$V11<>"",AA$2>=$F11,AA$2<=$V11,WEEKDAY(AA$2,2)<6),$Q11/$U11,"") | AB11: =IF(AND($F11<>"",$V11<>"",AB$2>=$F11,AB$2<=$V11,WEEKDAY(AB$2,2)<6),$Q11/$U11,"") | AC11: =IF(AND($F11<>"",$V11<>"",AC$2>=$F11,AC$2<=$V11,WEEKDAY(AC$2,2)<6),$Q11/$U11,"") | AD11: =IF(AND($F11<>"",$V11<>"",AD$2>=$F11,AD$2<=$V11,WEEKDAY(AD$2,2)<6),$Q11/$U11,"") | AE11: =IF(AND($F11<>"",$V11<>"",AE$2>=$F11,AE$2<=$V11,WEEKDAY(AE$2,2)<6),$Q11/$U11,"") | AF11: =IF(AND($F11<>"",$V11<>"",AF$2>=$F11,AF$2<=$V11,WEEKDAY(AF$2,2)<6),$Q11/$U11,"") | AG11: =IF(AND($F11<>"",$V11<>"",AG$2>=$F11,AG$2<=$V11,WEEKDAY(AG$2,2)<6),$Q11/$U11,"") | ... BD11: =IF(AND($F11<>"",$V11<>"",BD$2>=$F11,BD$2<=$V11,WEEKDAY(BD$2,2)<6),$Q11/$U11,"")
A12: =IF(E12="","",COUNTA($E$8:E12)) | Q12: =IF(SUM(L12,N12,P12)=0,"",SUM(L12,N12,P12)) | R12: =IF(L12>0,"영 ","")&IF(N12>0,"이 ","")&IF(P12>0,"기 ","") | S12: =IF(F12="","","W"&ROUNDUP(DAY(F12)/7,0)) | U12: =IF(Q12="",0,ROUNDUP(MAX(L12,N12,P12)/'마스터'!$J$5,0)) | V12: =IF(OR(F12="",U12=0),"",WORKDAY(F12,U12-1)) | W12: =IF(OR(G12="",V12=""),"",G12-V12) | Z12: =IF(AND($F12<>"",$V12<>"",Z$2>=$F12,Z$2<=$V12,WEEKDAY(Z$2,2)<6),$Q12/$U12,"") | AA12: =IF(AND($F12<>"",$V12<>"",AA$2>=$F12,AA$2<=$V12,WEEKDAY(AA$2,2)<6),$Q12/$U12,"") | AB12: =IF(AND($F12<>"",$V12<>"",AB$2>=$F12,AB$2<=$V12,WEEKDAY(AB$2,2)<6),$Q12/$U12,"") | AC12: =IF(AND($F12<>"",$V12<>"",AC$2>=$F12,AC$2<=$V12,WEEKDAY(AC$2,2)<6),$Q12/$U12,"") | AD12: =IF(AND($F12<>"",$V12<>"",AD$2>=$F12,AD$2<=$V12,WEEKDAY(AD$2,2)<6),$Q12/$U12,"") | AE12: =IF(AND($F12<>"",$V12<>"",AE$2>=$F12,AE$2<=$V12,WEEKDAY(AE$2,2)<6),$Q12/$U12,"") | AF12: =IF(AND($F12<>"",$V12<>"",AF$2>=$F12,AF$2<=$V12,WEEKDAY(AF$2,2)<6),$Q12/$U12,"") | AG12: =IF(AND($F12<>"",$V12<>"",AG$2>=$F12,AG$2<=$V12,WEEKDAY(AG$2,2)<6),$Q12/$U12,"") | ... BD12: =IF(AND($F12<>"",$V12<>"",BD$2>=$F12,BD$2<=$V12,WEEKDAY(BD$2,2)<6),$Q12/$U12,"")
A13: =IF(E13="","",COUNTA($E$8:E13)) | Q13: =IF(SUM(L13,N13,P13)=0,"",SUM(L13,N13,P13)) | R13: =IF(L13>0,"영 ","")&IF(N13>0,"이 ","")&IF(P13>0,"기 ","") | S13: =IF(F13="","","W"&ROUNDUP(DAY(F13)/7,0)) | U13: =IF(Q13="",0,ROUNDUP(MAX(L13,N13,P13)/'마스터'!$J$5,0)) | V13: =IF(OR(F13="",U13=0),"",WORKDAY(F13,U13-1)) | W13: =IF(OR(G13="",V13=""),"",G13-V13) | Z13: =IF(AND($F13<>"",$V13<>"",Z$2>=$F13,Z$2<=$V13,WEEKDAY(Z$2,2)<6),$Q13/$U13,"") | AA13: =IF(AND($F13<>"",$V13<>"",AA$2>=$F13,AA$2<=$V13,WEEKDAY(AA$2,2)<6),$Q13/$U13,"") | AB13: =IF(AND($F13<>"",$V13<>"",AB$2>=$F13,AB$2<=$V13,WEEKDAY(AB$2,2)<6),$Q13/$U13,"") | AC13: =IF(AND($F13<>"",$V13<>"",AC$2>=$F13,AC$2<=$V13,WEEKDAY(AC$2,2)<6),$Q13/$U13,"") | AD13: =IF(AND($F13<>"",$V13<>"",AD$2>=$F13,AD$2<=$V13,WEEKDAY(AD$2,2)<6),$Q13/$U13,"") | AE13: =IF(AND($F13<>"",$V13<>"",AE$2>=$F13,AE$2<=$V13,WEEKDAY(AE$2,2)<6),$Q13/$U13,"") | AF13: =IF(AND($F13<>"",$V13<>"",AF$2>=$F13,AF$2<=$V13,WEEKDAY(AF$2,2)<6),$Q13/$U13,"") | AG13: =IF(AND($F13<>"",$V13<>"",AG$2>=$F13,AG$2<=$V13,WEEKDAY(AG$2,2)<6),$Q13/$U13,"") | ... BD13: =IF(AND($F13<>"",$V13<>"",BD$2>=$F13,BD$2<=$V13,WEEKDAY(BD$2,2)<6),$Q13/$U13,"")
A14: =IF(E14="","",COUNTA($E$8:E14)) | Q14: =IF(SUM(L14,N14,P14)=0,"",SUM(L14,N14,P14)) | R14: =IF(L14>0,"영 ","")&IF(N14>0,"이 ","")&IF(P14>0,"기 ","") | S14: =IF(F14="","","W"&ROUNDUP(DAY(F14)/7,0)) | U14: =IF(Q14="",0,ROUNDUP(MAX(L14,N14,P14)/'마스터'!$J$5,0)) | V14: =IF(OR(F14="",U14=0),"",WORKDAY(F14,U14-1)) | W14: =IF(OR(G14="",V14=""),"",G14-V14) | Z14: =IF(AND($F14<>"",$V14<>"",Z$2>=$F14,Z$2<=$V14,WEEKDAY(Z$2,2)<6),$Q14/$U14,"") | AA14: =IF(AND($F14<>"",$V14<>"",AA$2>=$F14,AA$2<=$V14,WEEKDAY(AA$2,2)<6),$Q14/$U14,"") | AB14: =IF(AND($F14<>"",$V14<>"",AB$2>=$F14,AB$2<=$V14,WEEKDAY(AB$2,2)<6),$Q14/$U14,"") | AC14: =IF(AND($F14<>"",$V14<>"",AC$2>=$F14,AC$2<=$V14,WEEKDAY(AC$2,2)<6),$Q14/$U14,"") | AD14: =IF(AND($F14<>"",$V14<>"",AD$2>=$F14,AD$2<=$V14,WEEKDAY(AD$2,2)<6),$Q14/$U14,"") | AE14: =IF(AND($F14<>"",$V14<>"",AE$2>=$F14,AE$2<=$V14,WEEKDAY(AE$2,2)<6),$Q14/$U14,"") | AF14: =IF(AND($F14<>"",$V14<>"",AF$2>=$F14,AF$2<=$V14,WEEKDAY(AF$2,2)<6),$Q14/$U14,"") | AG14: =IF(AND($F14<>"",$V14<>"",AG$2>=$F14,AG$2<=$V14,WEEKDAY(AG$2,2)<6),$Q14/$U14,"") | ... BD14: =IF(AND($F14<>"",$V14<>"",BD$2>=$F14,BD$2<=$V14,WEEKDAY(BD$2,2)<6),$Q14/$U14,"")
A15: =IF(E15="","",COUNTA($E$8:E15)) | Q15: =IF(SUM(L15,N15,P15)=0,"",SUM(L15,N15,P15)) | R15: =IF(L15>0,"영 ","")&IF(N15>0,"이 ","")&IF(P15>0,"기 ","") | S15: =IF(F15="","","W"&ROUNDUP(DAY(F15)/7,0)) | U15: =IF(Q15="",0,ROUNDUP(MAX(L15,N15,P15)/'마스터'!$J$5,0)) | V15: =IF(OR(F15="",U15=0),"",WORKDAY(F15,U15-1)) | W15: =IF(OR(G15="",V15=""),"",G15-V15) | Z15: =IF(AND($F15<>"",$V15<>"",Z$2>=$F15,Z$2<=$V15,WEEKDAY(Z$2,2)<6),$Q15/$U15,"") | AA15: =IF(AND($F15<>"",$V15<>"",AA$2>=$F15,AA$2<=$V15,WEEKDAY(AA$2,2)<6),$Q15/$U15,"") | AB15: =IF(AND($F15<>"",$V15<>"",AB$2>=$F15,AB$2<=$V15,WEEKDAY(AB$2,2)<6),$Q15/$U15,"") | AC15: =IF(AND($F15<>"",$V15<>"",AC$2>=$F15,AC$2<=$V15,WEEKDAY(AC$2,2)<6),$Q15/$U15,"") | AD15: =IF(AND($F15<>"",$V15<>"",AD$2>=$F15,AD$2<=$V15,WEEKDAY(AD$2,2)<6),$Q15/$U15,"") | AE15: =IF(AND($F15<>"",$V15<>"",AE$2>=$F15,AE$2<=$V15,WEEKDAY(AE$2,2)<6),$Q15/$U15,"") | AF15: =IF(AND($F15<>"",$V15<>"",AF$2>=$F15,AF$2<=$V15,WEEKDAY(AF$2,2)<6),$Q15/$U15,"") | AG15: =IF(AND($F15<>"",$V15<>"",AG$2>=$F15,AG$2<=$V15,WEEKDAY(AG$2,2)<6),$Q15/$U15,"") | ... BD15: =IF(AND($F15<>"",$V15<>"",BD$2>=$F15,BD$2<=$V15,WEEKDAY(BD$2,2)<6),$Q15/$U15,"")
